Workbook

Sheet Gap Trace
A1: BRACKET-GAP LEDGER TRACE 2019 — every Recon row where Stock > Challan
A2: Each ledger sale behind the Stock figure was traced to its challan (Pivot Data, cancellations applied). No Recon values changed.
B4: VERDICT | C4: Rows | D4: Gap (pcs)
B5: Explained – issued inside SDN assemblies | C5: 31 | D5: -548
B6: Explained – ledger posting not backed by a live challan line | C6: 44 | D6: -593
B7: Recon Challan short – challan lines exist | C7: 59 | D7: -3395
B8: Partly explained | C8: 16 | D8: -857
B9: Ledger postings ≠ Stock total | C9: 3 | D9: -113
B10: Total | C10: =SUM(C5:C9) -> 153 | D10: =SUM(D5:D9) -> -5506
A13: # | B13: Verdict | C13: Recon cell (Gap) | D13: Section | E13: Part | F13: Code | G13: Challan | H13: Stock | I13: Gap | J13: Ledger trace | K13: Action
A14: 1 | B14: Explained – issued inside SDN assemblies | C14: X323 | D14: PART 10 – HOSE & TUBE ASSEMBLIES | E14: SD-1020ACCD-CP | F14: INNOVA DUAL | G14: 0 | H14: 95 | I14: -95 | J14: 95 pcs issued inside assemblies | K14: No change — assembly sold on challan, component issued in ledger.
A15: 2 | B15: Explained – issued inside SDN assemblies | C15: X331 | D15: PART 10 – HOSE & TUBE ASSEMBLIES | E15: SD-228CP/BLR | F15: BOLERO | G15: 0 | H15: 54 | I15: -54 | J15: 54 pcs issued inside assemblies | K15: No change — assembly sold on challan, component issued in ledger.
A16: 3 | B16: Explained – issued inside SDN assemblies | C16: X156 | D16: PART 7 – COILS | E16: LOGAN DSL | F16: SD-145MC/LGN.DSL | G16: 30 | H16: 71 | I16: -41 | J16: 41 pcs issued inside assemblies | K16: No change — assembly sold on challan, component issued in ledger.
A17: 4 | B17: Explained – issued inside SDN assemblies | C17: X354 | D17: PART 10 – HOSE & TUBE ASSEMBLIES | E17: SD240CP/LGN.DSL | F17: LOGAN DSL | G17: 0 | H17: 41 | I17: -41 | J17: 41 pcs issued inside assemblies | K17: No change — assembly sold on challan, component issued in ledger.
A18: 5 | B18: Explained – issued inside SDN assemblies | C18: X336 | D18: PART 10 – HOSE & TUBE ASSEMBLIES | E18: SD-222VP/HT4ZXDSL | F18: HONDA ZX/T4 | G18: 0 | H18: 32 | I18: -32 | J18: 32 pcs issued inside assemblies | K18: No change — assembly sold on challan, component issued in ledger.
A19: 6 | B19: Explained – issued inside SDN assemblies | C19: X165 | D19: PART 7 – COILS | E19: XUV 500 | F19: SD153MC/MX5 | G19: 0 | H19: 30 | I19: -30 | J19: 30 pcs issued inside assemblies | K19: No change — assembly sold on challan, component issued in ledger.
A20: 7 | B20: Explained – issued inside SDN assemblies | C20: X317 | D20: PART 10 – HOSE & TUBE ASSEMBLIES | E20: SD-1008WR-CP | F20: WR INNOVA SINGLE | G20: 0 | H20: 30 | I20: -30 | J20: 30 pcs issued inside assemblies | K20: No change — assembly sold on challan, component issued in ledger.
A21: 8 | B21: Explained – issued inside SDN assemblies | C21: X154 | D21: PART 7 – COILS | E21: FIGO | F21: SD148MC/FIGO | G21: 0 | H21: 28 | I21: -28 | J21: 28 pcs issued inside assemblies | K21: No change — assembly sold on challan, component issued in ledger.
A22: 9 | B22: Explained – issued inside SDN assemblies | C22: X352 | D22: PART 10 – HOSE & TUBE ASSEMBLIES | E22: (no description) | F22: FIGO | G22: 0 | H22: 28 | I22: -28 | J22: 28 pcs issued inside assemblies | K22: No change — assembly sold on challan, component issued in ledger.
A23: 10 | B23: Explained – issued inside SDN assemblies | C23: X164 | D23: PART 7 – COILS | E23: SWIFT NEW 2012 | G23: 0 | H23: 20 | I23: -20 | J23: 20 pcs issued inside assemblies | K23: No change — assembly sold on challan, component issued in ledger.
A24: 11 | B24: Explained – issued inside SDN assemblies | C24: X359 | D24: PART 10 – HOSE & TUBE ASSEMBLIES | E24: (no description) | F24: SWIFT NEW 2012 | G24: 0 | H24: 20 | I24: -20 | J24: 20 pcs issued inside assemblies | K24: No change — assembly sold on challan, component issued in ledger.
A25: 12 | B25: Explained – issued inside SDN assemblies | C25: X112 | D25: PART 7 – COILS | E25: SD-1005ND-MC | F25: MAGNETIC COIL SUBROS ND ESTEEM | G25: 0 | H25: 17 | I25: -17 | J25: 17 pcs issued inside assemblies | K25: No change — assembly sold on challan, component issued in ledger.
A26: 13 | B26: Explained – issued inside SDN assemblies | C26: X108 | D26: PART 7 – COILS | E26: SD-1003-MC QUALIS | F26: MAGNATTE COIL QUALIS | G26: 0 | H26: 10 | I26: -10 | J26: 10 pcs issued inside assemblies | K26: No change — assembly sold on challan, component issued in ledger.
A27: 14 | B27: Explained – issued inside SDN assemblies | C27: X144 | D27: PART 7 – COILS | E27: TEMPO TRAVELLER | F27: SD139MC/TT | G27: 5 | H27: 15 | I27: -10 | J27: 10 pcs issued inside assemblies | K27: No change — assembly sold on challan, component issued in ledger.
A28: 15 | B28: Explained – issued inside SDN assemblies | C28: X157 | D28: PART 7 – COILS | E28: POLO | G28: 0 | H28: 10 | I28: -10 | J28: 10 pcs issued inside assemblies | K28: No change — assembly sold on challan, component issued in ledger.
A29: 16 | B29: Explained – issued inside SDN assemblies | C29: X312 | D29: PART 10 – HOSE & TUBE ASSEMBLIES | E29: SD-1003-CP/QUALIS | F29: SD-1003-MC | G29: 0 | H29: 10 | I29: -10 | J29: 10 pcs issued inside assemblies | K29: No change — assembly sold on challan, component issued in ledger.
A30: 17 | B30: Explained – issued inside SDN assemblies | C30: X332 | D30: PART 10 – HOSE & TUBE ASSEMBLIES | E30: SD-231CP/HT3 | F30: HONDA T3 | G30: 0 | H30: 10 | I30: -10 | J30: 10 pcs issued inside assemblies | K30: No change — assembly sold on challan, component issued in ledger.
A31: 18 | B31: Explained – issued inside SDN assemblies | C31: X345 | D31: PART 10 – HOSE & TUBE ASSEMBLIES | E31: SD234CP/TT | F31: TEMPO TRAVELLER | G31: 0 | H31: 10 | I31: -10 | J31: 10 pcs issued inside assemblies | K31: No change — assembly sold on challan, component issued in ledger.
A32: 19 | B32: Explained – issued inside SDN assemblies | C32: X355 | D32: PART 10 – HOSE & TUBE ASSEMBLIES | E32: (no description) | F32: POLO | G32: 0 | H32: 10 | I32: -10 | J32: 10 pcs issued inside assemblies | K32: No change — assembly sold on challan, component issued in ledger.
A33: 20 | B33: Explained – issued inside SDN assemblies | C33: X168 | D33: PART 7 – COILS | E33: VISTA 5PK | F33: SD-156MC/VS.5PK | G33: 0 | H33: 9 | I33: -9 | J33: 9 pcs issued inside assemblies | K33: No change — assembly sold on challan, component issued in ledger.
A34: 21 | B34: Explained – issued inside SDN assemblies | C34: X113 | D34: PART 7 – COILS | E34: SD-1007SKD-MC | F34: MAGNETIC COIL SKODA | G34: 0 | H34: 8 | I34: -8 | J34: 8 pcs issued inside assemblies | K34: No change — assembly sold on challan, component issued in ledger.
A35: 22 | B35: Explained – issued inside SDN assemblies | C35: X134 | D35: PART 7 – COILS | E35: CIVIC | F35: SD-106/CIVIC | G35: 0 | H35: 6 | I35: -6 | J35: 6 pcs issued inside assemblies | K35: No change — assembly sold on challan, component issued in ledger.
A36: 23 | B36: Explained – issued inside SDN assemblies | C36: X339 | D36: PART 10 – HOSE & TUBE ASSEMBLIES | E36: SD-229CP/CIVIC | F36: HONDA CIVIC | G36: 0 | H36: 4 | I36: -4 | J36: 4 pcs issued inside assemblies | K36: No change — assembly sold on challan, component issued in ledger.
A37: 24 | B37: Explained – issued inside SDN assemblies | C37: X158 | D37: PART 7 – COILS | E37: ZEN ESTILO | G37: 0 | H37: 3 | I37: -3 | J37: 3 pcs issued inside assemblies | K37: No change — assembly sold on challan, component issued in ledger.
A38: 25 | B38: Explained – issued inside SDN assemblies | C38: X116 | D38: PART 7 – COILS | E38: SD-1010LNR-MMC-MC | F38: MAGNETIC COIL LANCER MMC | G38: 0 | H38: 2 | I38: -2 | J38: 2 pcs issued inside assemblies | K38: No change — assembly sold on challan, component issued in ledger.
A39: 26 | B39: Explained – issued inside SDN assemblies | C39: X142 | D39: PART 7 – COILS | E39: ENDEAVOUR | F39: SD-131MC/END | G39: 0 | H39: 2 | I39: -2 | J39: 2 pcs issued inside assemblies | K39: No change — assembly sold on challan, component issued in ledger.
A40: 27 | B40: Explained – issued inside SDN assemblies | C40: X319 | D40: PART 10 – HOSE & TUBE ASSEMBLIES | E40: SD-1010LNR -MMC-CP | F40: SD-1010LNR-MMC-MC | G40: 0 | H40: 2 | I40: -2 | J40: 2 pcs issued inside assemblies | K40: No change — assembly sold on challan, component issued in ledger.
A41: 28 | B41: Explained – issued inside SDN assemblies | C41: X329 | D41: PART 10 – HOSE & TUBE ASSEMBLIES | E41: (no description) | F41: FEISTA DSL | G41: 0 | H41: 2 | I41: -2 | J41: 2 pcs issued inside assemblies | K41: No change — assembly sold on challan, component issued in ledger.
A42: 29 | B42: Explained – issued inside SDN assemblies | C42: X343 | D42: PART 10 – HOSE & TUBE ASSEMBLIES | E42: SD-220CP/END | F42: ENDEAVOUR | G42: 0 | H42: 2 | I42: -2 | J42: 2 pcs issued inside assemblies | K42: No change — assembly sold on challan, component issued in ledger.
A43: 30 | B43: Explained – issued inside SDN assemblies | C43: X152 | D43: PART 7 – COILS | E43: I-20 PTL | G43: 0 | H43: 1 | I43: -1 | J43: 1 pcs issued inside assemblies | K43: No change — assembly sold on challan, component issued in ledger.
...

Sheet Recon
A1: Group | B1: Item | C1: Part Code | D1: Challan | E1: Stock | F1: Gap | G1: Total Available | K1: Group | L1: Item | M1: Part Code | N1: Challan | O1: Stock | P1: Gap | Q1: Total Available | S1: Group | T1: Item | U1: Part Code | V1: Challan | W1: Stock | X1: Gap | Y1: Total Available | Z1: Group | AA1: Item | AB1: Part Code | AC1: Challan | AD1: Stock | AE1: Gap | AF1: Total Available
A2: PART 1 – CONDENSERS | B2: ACCENT CRD-I | C2: PC-86064B | D2: 22 | E2: {=IF($B2="","",IF(TRIM(INDEX('Part 1'!$L$2:$IV$2,1,ROW()-1))=TRIM($B2),INDEX('Part 1'!$L$1250:$IV$1250,1,ROW()-1),"CHECK"))} -> 22 | F2: =IFERROR(D2-E2,"") -> 0 | G2: ='Part 1'!L30 -> 95 | K2: Drier | L2: Ambasdor /Bolero | M2: PC-8120 | N2: 0 | O2: =IF($L2="","",IF(TRIM(INDEX('Part 4'!$E$2:$AY$2,1,ROW()-1))=TRIM($L2),INDEX('Part 4'!$E$778:$AY$778,1,ROW()-1),"CHECK")) -> 0 | P2: =IFERROR(N2-O2,"") -> 0 | Q2: ='Part 4'!E20 -> 280 | T2: PULLEY | X2: =IFERROR(V2-W2,"") -> 0 | Z2: PART 8 – HOSE & TUBE ASSEMBLIES | AA2: MARUTI 800 R12 DISCHARGE HOSE | AB2: PC-101 | AC2: 0 | AD2: =IF($AB2="","",IF(TRIM(INDEX('Part 8'!$F$2:$IV$2,1,ROW()-1))=TRIM($AB2),INDEX('Part 8'!$F$244:$IV$244,1,ROW()-1),"CHECK")) -> 0 | AE2: =IFERROR(AC2-AD2,"") -> 0 | AF2: ='Part 8'!F9 -> 0
B3: ACCENT-PETROL | C3: PC-86248 | D3: 0 | E3: {=IF($B3="","",IF(TRIM(INDEX('Part 1'!$L$2:$IV$2,1,ROW()-1))=TRIM($B3),INDEX('Part 1'!$L$1250:$IV$1250,1,ROW()-1),"CHECK"))} -> 0 | F3: =IFERROR(D3-E3,"") -> 0 | G3: ='Part 1'!M30 -> 120 | L3: Ambasdor /Bolero-corrected | M3: PC-8120 | N3: 50 | O3: =IF($L3="","",IF(TRIM(INDEX('Part 4'!$E$2:$AY$2,1,ROW()-1))=TRIM($L3),INDEX('Part 4'!$E$778:$AY$778,1,ROW()-1),"CHECK")) -> 50 | P3: =IFERROR(N3-O3,"") -> 0 | Q3: ='Part 4'!F20 -> 95 | S3: PART 7 – PULLEYS | T3: QUALIS | U3: SD-1003-MC/SD-304PL/QUALIS | V3: 12 | W3: =IFERROR('Part 7'!EI690+0,0) -> 10 | X3: =IFERROR(V3-W3,"") -> 2 | Y3: ='Part 7'!EI18 -> 312 | AA3: MARUTI 800 SUCTION HOSE R12 | AB3: PC-102 | AC3: 0 | AD3: =IF($AB3="","",IF(TRIM(INDEX('Part 8'!$F$2:$IV$2,1,ROW()-1))=TRIM($AB3),INDEX('Part 8'!$F$244:$IV$244,1,ROW()-1),"CHECK")) -> 0 | AE3: =IFERROR(AC3-AD3,"") -> 0 | AF3: ='Part 8'!G9 -> 0
B4: ALTIS | C4: PC-86032 | D4: 4 | E4: {=IF($B4="","",IF(TRIM(INDEX('Part 1'!$L$2:$IV$2,1,ROW()-1))=TRIM($B4),INDEX('Part 1'!$L$1250:$IV$1250,1,ROW()-1),"CHECK"))} -> 9 | F4: =IFERROR(D4-E4,"") -> -5 | G4: ='Part 1'!N30 -> -6 | L4: Aveo | M4: PC-8797 | N4: 0 | O4: =IF($L4="","",IF(TRIM(INDEX('Part 4'!$E$2:$AY$2,1,ROW()-1))=TRIM($L4),INDEX('Part 4'!$E$778:$AY$778,1,ROW()-1),"CHECK")) -> 0 | P4: =IFERROR(N4-O4,"") -> 0 | Q4: ='Part 4'!G20 -> 348 | T4: SD-1004-MC(OLD) | U4: SD-1004-PL (OLD) | V4: 0 | W4: =IFERROR('Part 7'!EJ690+0,0) -> 0 | X4: =IFERROR(V4-W4,"") -> 0 | Y4: ='Part 7'!EJ18 -> 94 | AA4: MARUTI 800 SUCTION HOSE R12 N/TYPE | AB4: PC-103 | AC4: 0 | AD4: =IF($AB4="","",IF(TRIM(INDEX('Part 8'!$F$2:$IV$2,1,ROW()-1))=TRIM($AB4),INDEX('Part 8'!$F$244:$IV$244,1,ROW()-1),"CHECK")) -> 0 | AE4: =IFERROR(AC4-AD4,"") -> 0 | AF4: ='Part 8'!H9 -> 0
B5: ALTIS-CORRECTED | C5: PC-86083 | D5: 29 | E5: {=IF($B5="","",IF(TRIM(INDEX('Part 1'!$L$2:$IV$2,1,ROW()-1))=TRIM($B5),INDEX('Part 1'!$L$1250:$IV$1250,1,ROW()-1),"CHECK"))} -> 23 | F5: =IFERROR(D5-E5,"") -> 6 | G5: ='Part 1'!O30 -> 57 | L5: Daewoo Cielo | M5: PC-8263 | N5: 0 | O5: =IF($L5="","",IF(TRIM(INDEX('Part 4'!$E$2:$AY$2,1,ROW()-1))=TRIM($L5),INDEX('Part 4'!$E$778:$AY$778,1,ROW()-1),"CHECK")) -> 0 | P5: =IFERROR(N5-O5,"") -> 0 | Q5: ='Part 4'!H20 -> 40 | T5: SD-1004-MC (NEW) | U5: SD-1004-PL (NEW) | V5: 0 | W5: =IFERROR('Part 7'!EK690+0,0) -> 10 | X5: =IFERROR(V5-W5,"") -> -10 | Y5: ='Part 7'!EK18 -> -176 | AA5: MARUTI 800 LIQUID TUBE RD TO COND R12 | AB5: PC-104 | AC5: 0 | AD5: =IF($AB5="","",IF(TRIM(INDEX('Part 8'!$F$2:$IV$2,1,ROW()-1))=TRIM($AB5),INDEX('Part 8'!$F$244:$IV$244,1,ROW()-1),"CHECK")) -> 0 | AE5: =IFERROR(AC5-AD5,"") -> 0 | AF5: ='Part 8'!I9 -> 0
B6: ALTIS-Q5 | C6: PC-86083-Q5 | D6: 39 | E6: {=IF($B6="","",IF(TRIM(INDEX('Part 1'!$L$2:$IV$2,1,ROW()-1))=TRIM($B6),INDEX('Part 1'!$L$1250:$IV$1250,1,ROW()-1),"CHECK"))} -> 17 | F6: =IFERROR(D6-E6,"") -> 22 | G6: ='Part 1'!P30 -> 172 | L6: Desiccant Drier/Filter | M6: PC-20241 | N6: 1040 | O6: =IF($L6="","",IF(TRIM(INDEX('Part 4'!$E$2:$AY$2,1,ROW()-1))=TRIM($L6),INDEX('Part 4'!$E$778:$AY$778,1,ROW()-1),"CHECK")) -> 990 | P6: =IFERROR(N6-O6,"") -> 50 | Q6: ='Part 4'!I20 -> 17032 | T6: SD-1004-MC (DELPHI) | U6: SD-1004-PL (DELPHI) | V6: 0 | W6: =IFERROR('Part 7'!EL690+0,0) -> 0 | X6: =IFERROR(V6-W6,"") -> 0 | Y6: ='Part 7'!EL18 -> 0 | AA6: MARUTI 800 ALU. LIQ TUBE 27" WITHOUT VALVE | AB6: PC-104A | AC6: 0 | AD6: =IF($AB6="","",IF(TRIM(INDEX('Part 8'!$F$2:$IV$2,1,ROW()-1))=TRIM($AB6),INDEX('Part 8'!$F$244:$IV$244,1,ROW()-1),"CHECK")) -> 0 | AE6: =IFERROR(AC6-AD6,"") -> 0 | AF6: ='Part 8'!J9 -> 0
B7: ALTO 800 NEW | C7: PC-86634 | D7: 11 | E7: {=IF($B7="","",IF(TRIM(INDEX('Part 1'!$L$2:$IV$2,1,ROW()-1))=TRIM($B7),INDEX('Part 1'!$L$1250:$IV$1250,1,ROW()-1),"CHECK"))} -> 8 | F7: =IFERROR(D7-E7,"") -> 3 | G7: ='Part 1'!Q30 -> 218 | L7: Esteem-R12 | M7: PC-8005 | N7: 144 | O7: =IF($L7="","",IF(TRIM(INDEX('Part 4'!$E$2:$AY$2,1,ROW()-1))=TRIM($L7),INDEX('Part 4'!$E$778:$AY$778,1,ROW()-1),"CHECK")) -> 115 | P7: =IFERROR(N7-O7,"") -> 29 | Q7: ='Part 4'!J20 -> 201 | T7: XING | U7: SD-1004E | V7: 121 | W7: =IFERROR('Part 7'!EM690+0,0) -> 108 | X7: =IFERROR(V7-W7,"") -> 13 | Y7: ='Part 7'!EM18 -> 654 | AA7: MARUTI 800 LIQUID T'" RD TO COIL R12 | AB7: PC-105 | AC7: 0 | AD7: =IF($AB7="","",IF(TRIM(INDEX('Part 8'!$F$2:$IV$2,1,ROW()-1))=TRIM($AB7),INDEX('Part 8'!$F$244:$IV$244,1,ROW()-1),"CHECK")) -> 5 | AE7: =IFERROR(AC7-AD7,"") -> -5 | AF7: ='Part 8'!K9 -> 0
B8: AMBASDOR | C8: PC-86041 | D8: 7 | E8: {=IF($B8="","",IF(TRIM(INDEX('Part 1'!$L$2:$IV$2,1,ROW()-1))=TRIM($B8),INDEX('Part 1'!$L$1250:$IV$1250,1,ROW()-1),"CHECK"))} -> 7 | F8: =IFERROR(D8-E8,"") -> 0 | G8: ='Part 1'!R30 -> 63 | L8: Esteem-R134A | M8: PC-8006 | N8: 635 | O8: =IF($L8="","",IF(TRIM(INDEX('Part 4'!$E$2:$AY$2,1,ROW()-1))=TRIM($L8),INDEX('Part 4'!$E$778:$AY$778,1,ROW()-1),"CHECK")) -> 400 | P8: =IFERROR(N8-O8,"") -> 235 | Q8: ='Part 4'!K20 -> 844 | T8: SD-1005ND-MC | U8: SD-1005ND-PL | V8: 19 | W8: =IFERROR('Part 7'!EN690+0,0) -> 17 | X8: =IFERROR(V8-W8,"") -> 2 | Y8: ='Part 7'!EN18 -> 740 | AA8: MARUTI 800 R12 COOLING COIL TUBE LIQUID | AB8: PC-106 | AC8: 0 | AD8: =IF($AB8="","",IF(TRIM(INDEX('Part 8'!$F$2:$IV$2,1,ROW()-1))=TRIM($AB8),INDEX('Part 8'!$F$244:$IV$244,1,ROW()-1),"CHECK")) -> 0 | AE8: =IFERROR(AC8-AD8,"") -> 0 | AF8: ='Part 8'!L9 -> 0
B9: A-STAR | C9: PC-86274 | D9: 3 | E9: {=IF($B9="","",IF(TRIM(INDEX('Part 1'!$L$2:$IV$2,1,ROW()-1))=TRIM($B9),INDEX('Part 1'!$L$1250:$IV$1250,1,ROW()-1),"CHECK"))} -> 6 | F9: =IFERROR(D9-E9,"") -> -3 | G9: ='Part 1'!S30 -> 108 | L9: Ford | M9: PC-8321 | N9: 0 | O9: =IF($L9="","",IF(TRIM(INDEX('Part 4'!$E$2:$AY$2,1,ROW()-1))=TRIM($L9),INDEX('Part 4'!$E$778:$AY$778,1,ROW()-1),"CHECK")) -> 0 | P9: =IFERROR(N9-O9,"") -> 0 | Q9: ='Part 4'!L20 -> 51 | T9: SD-1007SKD-MC | U9: SD-1007SKD-PL | V9: 14 | W9: =IFERROR('Part 7'!EO690+0,0) -> 13 | X9: =IFERROR(V9-W9,"") -> 1 | Y9: ='Part 7'!EO18 -> 316 | AA9: MARUTI 800 R12 SUCTION TUBE COOLING COIL | AB9: PC-107 | AC9: 0 | AD9: =IF($AB9="","",IF(TRIM(INDEX('Part 8'!$F$2:$IV$2,1,ROW()-1))=TRIM($AB9),INDEX('Part 8'!$F$244:$IV$244,1,ROW()-1),"CHECK")) -> 0 | AE9: =IFERROR(AC9-AD9,"") -> 0 | AF9: ='Part 8'!M9 -> 0
B10: AUDI A3 | C10: PCP-C86283Q5 | D10: 14 | E10: {=IF($B10="","",IF(TRIM(INDEX('Part 1'!$L$2:$IV$2,1,ROW()-1))=TRIM($B10),INDEX('Part 1'!$L$1250:$IV$1250,1,ROW()-1),"CHECK"))} -> 14 | F10: =IFERROR(D10-E10,"") -> 0 | G10: ='Part 1'!T30 -> 96 | L10: Honda City | M10: PC-8020 | N10: 48 | O10: =IF($L10="","",IF(TRIM(INDEX('Part 4'!$E$2:$AY$2,1,ROW()-1))=TRIM($L10),INDEX('Part 4'!$E$778:$AY$778,1,ROW()-1),"CHECK")) -> 38 | P10: =IFERROR(N10-O10,"") -> 10 | Q10: ='Part 4'!M20 -> 1299 | T10: SD-1008WR-MC | U10: SD-1008WR-PL // SD-303PL/WR | V10: 238 | W10: =IFERROR('Part 7'!EP690+0,0) -> 226 | X10: =IFERROR(V10-W10,"") -> 12 | Y10: ='Part 7'!EP18 -> 404 | AA10: MARUTI 800 R134A DISCHARGE HOSE | AB10: PC-108 | AC10: 0 | AD10: =IF($AB10="","",IF(TRIM(INDEX('Part 8'!$F$2:$IV$2,1,ROW()-1))=TRIM($AB10),INDEX('Part 8'!$F$244:$IV$244,1,ROW()-1),"CHECK")) -> 0 | AE10: =IFERROR(AC10-AD10,"") -> 0 | AF10: ='Part 8'!N9 -> 0
B11: AUDI A4 | C11: PCP-C86001 | D11: 0 | E11: {=IF($B11="","",IF(TRIM(INDEX('Part 1'!$L$2:$IV$2,1,ROW()-1))=TRIM($B11),INDEX('Part 1'!$L$1250:$IV$1250,1,ROW()-1),"CHECK"))} -> 0 | F11: =IFERROR(D11-E11,"") -> 0 | G11: ='Part 1'!U30 -> 37 | L11: Honda Civic | M11: PC-65076 | N11: 10 | O11: =IF($L11="","",IF(TRIM(INDEX('Part 4'!$E$2:$AY$2,1,ROW()-1))=TRIM($L11),INDEX('Part 4'!$E$778:$AY$778,1,ROW()-1),"CHECK")) -> 5 | P11: =IFERROR(N11-O11,"") -> 5 | Q11: ='Part 4'!N20 -> -131 | T11: SD-1009IKN1.8-MC | U11: SD-1009IKN1.8-PL | V11: 0 | W11: =IFERROR('Part 7'!EQ690+0,0) -> 0 | X11: =IFERROR(V11-W11,"") -> 0 | Y11: ='Part 7'!EQ18 -> 180 | AA11: MARUTI 800 DISCHARGE HOSE R134A | AB11: PC-109 | AC11: 0 | AD11: =IF($AB11="","",IF(TRIM(INDEX('Part 8'!$F$2:$IV$2,1,ROW()-1))=TRIM($AB11),INDEX('Part 8'!$F$244:$IV$244,1,ROW()-1),"CHECK")) -> 6 | AE11: =IFERROR(AC11-AD11,"") -> -6 | AF11: ='Part 8'!O9 -> 0
B12: AUDI A6 | C12: PCP-C86082 | D12: 5 | E12: {=IF($B12="","",IF(TRIM(INDEX('Part 1'!$L$2:$IV$2,1,ROW()-1))=TRIM($B12),INDEX('Part 1'!$L$1250:$IV$1250,1,ROW()-1),"CHECK"))} -> 5 | F12: =IFERROR(D12-E12,"") -> 0 | G12: ='Part 1'!V30 -> 39 | L12: Indica Behr | M12: PC-8115 | N12: 0 | O12: =IF($L12="","",IF(TRIM(INDEX('Part 4'!$E$2:$AY$2,1,ROW()-1))=TRIM($L12),INDEX('Part 4'!$E$778:$AY$778,1,ROW()-1),"CHECK")) -> 0 | P12: =IFERROR(N12-O12,"") -> 0 | Q12: ='Part 4'!O20 -> 436 | T12: SD-1010LNR-MMC-MC | U12: SD-1010LNR-MMC-PL | V12: 2 | W12: =IFERROR('Part 7'!ER690+0,0) -> 2 | X12: =IFERROR(V12-W12,"") -> 0 | Y12: ='Part 7'!ER18 -> 22 | AA12: MARUTI 800 R134A SUCTION HOSE | AB12: PC-110 | AC12: 0 | AD12: =IF($AB12="","",IF(TRIM(INDEX('Part 8'!$F$2:$IV$2,1,ROW()-1))=TRIM($AB12),INDEX('Part 8'!$F$244:$IV$244,1,ROW()-1),"CHECK")) -> 0 | AE12: =IFERROR(AC12-AD12,"") -> 0 | AF12: ='Part 8'!P9 -> 0
B13: AUDI Q3 | C13: PCP-C86020 | D13: 28 | E13: {=IF($B13="","",IF(TRIM(INDEX('Part 1'!$L$2:$IV$2,1,ROW()-1))=TRIM($B13),INDEX('Part 1'!$L$1250:$IV$1250,1,ROW()-1),"CHECK"))} -> 20 | F13: =IFERROR(D13-E13,"") -> 8 | G13: ='Part 1'!W30 -> 65 | L13: Lancer | M13: PC-8017 | N13: 1 | O13: =IF($L13="","",IF(TRIM(INDEX('Part 4'!$E$2:$AY$2,1,ROW()-1))=TRIM($L13),INDEX('Part 4'!$E$778:$AY$778,1,ROW()-1),"CHECK")) -> 1 | P13: =IFERROR(N13-O13,"") -> 0 | Q13: ='Part 4'!P20 -> 28 | T13: SD-1011ACRDI-MC | U13: SD-1011ACRDI-PL | V13: 0 | W13: =IFERROR('Part 7'!ES690+0,0) -> 0 | X13: =IFERROR(V13-W13,"") -> 0 | Y13: ='Part 7'!ES18 -> 279 | AA13: MARUTI 800 LIQUID TUBE RD TO COND R134A (PAD & NUT) | AB13: PC-111 | AC13: 0 | AD13: =IF($AB13="","",IF(TRIM(INDEX('Part 8'!$F$2:$IV$2,1,ROW()-1))=TRIM($AB13),INDEX('Part 8'!$F$244:$IV$244,1,ROW()-1),"CHECK")) -> 5 | AE13: =IFERROR(AC13-AD13,"") -> -5 | AF13: ='Part 8'!Q9 -> 0
B14: AUDI Q7 | C14: PCP-C86832 | D14: 3 | E14: {=IF($B14="","",IF(TRIM(INDEX('Part 1'!$L$2:$IV$2,1,ROW()-1))=TRIM($B14),INDEX('Part 1'!$L$1250:$IV$1250,1,ROW()-1),"CHECK"))} -> 3 | F14: =IFERROR(D14-E14,"") -> 0 | G14: ='Part 1'!X30 -> 20 | L14: Logan (DSL) | M14: PC-20233-A | N14: 0 | O14: =IF($L14="","",IF(TRIM(INDEX('Part 4'!$E$2:$AY$2,1,ROW()-1))=TRIM($L14),INDEX('Part 4'!$E$778:$AY$778,1,ROW()-1),"CHECK")) -> 0 | P14: =IFERROR(N14-O14,"") -> 0 | Q14: ='Part 4'!Q20 -> 75 | T14: SD-1012SCR-MC | U14: SD-1012SCR-PL | V14: 0 | W14: =IFERROR('Part 7'!ET690+0,0) -> 0 | X14: =IFERROR(V14-W14,"") -> 0 | Y14: ='Part 7'!ET18 -> 440 | AA14: MARUTI 800 R134A LIQUID TUBE RD (BOTH SIDE PAD) | AB14: PC-112 | AC14: 0 | AD14: =IF($AB14="","",IF(TRIM(INDEX('Part 8'!$F$2:$IV$2,1,ROW()-1))=TRIM($AB14),INDEX('Part 8'!$F$244:$IV$244,1,ROW()-1),"CHECK")) -> 0 | AE14: =IFERROR(AC14-AD14,"") -> 0 | AF14: ='Part 8'!R9 -> 0
B15: AVEO | C15: PC-86177 | D15: 27 | E15: {=IF($B15="","",IF(TRIM(INDEX('Part 1'!$L$2:$IV$2,1,ROW()-1))=TRIM($B15),INDEX('Part 1'!$L$1250:$IV$1250,1,ROW()-1),"CHECK"))} -> 20 | F15: =IFERROR(D15-E15,"") -> 7 | G15: ='Part 1'!Y30 -> 96 | L15: Maruti 'F'Ring | M15: PC-8047 | N15: 0 | O15: =IF($L15="","",IF(TRIM(INDEX('Part 4'!$E$2:$AY$2,1,ROW()-1))=TRIM($L15),INDEX('Part 4'!$E$778:$AY$778,1,ROW()-1),"CHECK")) -> 0 | P15: =IFERROR(N15-O15,"") -> 0 | Q15: ='Part 4'!R20 -> 716 | T15: SD-1018IKN1.3-MC | U15: SD-1018IKN1.3-PL | V15: 0 | W15: =IFERROR('Part 7'!EU690+0,0) -> 0 | X15: =IFERROR(V15-W15,"") -> 0 | Y15: ='Part 7'!EU18 -> -1 | AA15: MARUTI 800 R134A LIQUID TUBE RD TO COIL HP | AB15: PC-113 | AC15: 0 | AD15: =IF($AB15="","",IF(TRIM(INDEX('Part 8'!$F$2:$IV$2,1,ROW()-1))=TRIM($AB15),INDEX('Part 8'!$F$244:$IV$244,1,ROW()-1),"CHECK")) -> 5 | AE15: =IFERROR(AC15-AD15,"") -> -5 | AF15: ='Part 8'!S9 -> 0
B16: BALENO-NEW | C16: PC-86803 | D16: 40 | E16: {=IF($B16="","",IF(TRIM(INDEX('Part 1'!$L$2:$IV$2,1,ROW()-1))=TRIM($B16),INDEX('Part 1'!$L$1250:$IV$1250,1,ROW()-1),"CHECK"))} -> 37 | F16: =IFERROR(D16-E16,"") -> 3 | G16: ='Part 1'!Z30 -> 175 | L16: Maruti 'O'Ring | M16: PC-8051 | N16: 0 | O16: =IF($L16="","",IF(TRIM(INDEX('Part 4'!$E$2:$AY$2,1,ROW()-1))=TRIM($L16),INDEX('Part 4'!$E$778:$AY$778,1,ROW()-1),"CHECK")) -> 0 | P16: =IFERROR(N16-O16,"") -> 0 | Q16: ='Part 4'!S20 -> 1481 | T16: SD-1020ACCD-MC/INNOVA DUAL | U16: SD-1020ACCD-PL | V16: 0 | W16: =IFERROR('Part 7'!EV690+0,0) -> 0 | X16: =IFERROR(V16-W16,"") -> 0 | Y16: ='Part 7'!EV18 -> 139 | AA16: MARUTI 800 R134A LIQUID TUBE COOLING COIL | AB16: PC-114 | AC16: 0 | AD16: =IF($AB16="","",IF(TRIM(INDEX('Part 8'!$F$2:$IV$2,1,ROW()-1))=TRIM($AB16),INDEX('Part 8'!$F$244:$IV$244,1,ROW()-1),"CHECK")) -> 0 | AE16: =IFERROR(AC16-AD16,"") -> 0 | AF16: ='Part 8'!T9 -> 0
B17: BALENO-NEW-Q5 | C17: PC-86803Q5 | D17: 0 | E17: {=IF($B17="","",IF(TRIM(INDEX('Part 1'!$L$2:$IV$2,1,ROW()-1))=TRIM($B17),INDEX('Part 1'!$L$1250:$IV$1250,1,ROW()-1),"CHECK"))} -> 0 | F17: =IFERROR(D17-E17,"") -> 0 | G17: ='Part 1'!AA30 -> 50 | L17: Matiz | M17: PC-8096 | N17: 0 | O17: =IF($L17="","",IF(TRIM(INDEX('Part 4'!$E$2:$AY$2,1,ROW()-1))=TRIM($L17),INDEX('Part 4'!$E$778:$AY$778,1,ROW()-1),"CHECK")) -> 0 | P17: =IFERROR(N17-O17,"") -> 0 | Q17: ='Part 4'!T20 -> 0 | T17: SD-1021CRV-MC | U17: SD-1021CRV-PL | V17: 0 | W17: =IFERROR('Part 7'!EW690+0,0) -> 0 | X17: =IFERROR(V17-W17,"") -> 0 | Y17: ='Part 7'!EW18 -> 260 | AA17: MARUTI 800 R134A SUCTION TUBE COOLING COIL | AB17: PC-115 | AC17: 0 | AD17: =IF($AB17="","",IF(TRIM(INDEX('Part 8'!$F$2:$IV$2,1,ROW()-1))=TRIM($AB17),INDEX('Part 8'!$F$244:$IV$244,1,ROW()-1),"CHECK")) -> 0 | AE17: =IFERROR(AC17-AD17,"") -> 0 | AF17: ='Part 8'!U9 -> 0
B18: BEAT DSL-Q5 | C18: PC-86589Q5 | D18: 25 | E18: {=IF($B18="","",IF(TRIM(INDEX('Part 1'!$L$2:$IV$2,1,ROW()-1))=TRIM($B18),INDEX('Part 1'!$L$1250:$IV$1250,1,ROW()-1),"CHECK"))} -> 5 | F18: =IFERROR(D18-E18,"") -> 20 | G18: ='Part 1'!AB30 -> 145 | L18: Opel | M18: PC-6142 | N18: 0 | O18: =IF($L18="","",IF(TRIM(INDEX('Part 4'!$E$2:$AY$2,1,ROW()-1))=TRIM($L18),INDEX('Part 4'!$E$778:$AY$778,1,ROW()-1),"CHECK")) -> 0 | P18: =IFERROR(N18-O18,"") -> 0 | Q18: ='Part 4'!U20 -> 323 | T18: ZEN DELPHI | U18: SDN-310/PL | V18: 0 | W18: =IFERROR('Part 7'!EX690+0,0) -> 0 | X18: =IFERROR(V18-W18,"") -> 0 | Y18: ='Part 7'!EX18 -> 270 | AA18: MARUTI ZEN ESTILO DISCHARGE HOSE | AB18: PC-116 | AC18: 0 | AD18: =IF($AB18="","",IF(TRIM(INDEX('Part 8'!$F$2:$IV$2,1,ROW()-1))=TRIM($AB18),INDEX('Part 8'!$F$244:$IV$244,1,ROW()-1),"CHECK")) -> 0 | AE18: =IFERROR(AC18-AD18,"") -> 0 | AF18: ='Part 8'!V9 -> 0
B19: BEAT PTL-Q5 | C19: PC-86535Q5 | D19: 20 | E19: {=IF($B19="","",IF(TRIM(INDEX('Part 1'!$L$2:$IV$2,1,ROW()-1))=TRIM($B19),INDEX('Part 1'!$L$1250:$IV$1250,1,ROW()-1),"CHECK"))} -> 15 | F19: =IFERROR(D19-E19,"") -> 5 | G19: ='Part 1'!AC30 -> 299 | L19: Optra | M19: PC-8031 | N19: 0 | O19: =IF($L19="","",IF(TRIM(INDEX('Part 4'!$E$2:$AY$2,1,ROW()-1))=TRIM($L19),INDEX('Part 4'!$E$778:$AY$778,1,ROW()-1),"CHECK")) -> 0 | P19: =IFERROR(N19-O19,"") -> 0 | Q19: ='Part 4'!V20 -> 105 | T19: SDN101/507/7PK | V19: 454 | W19: =IFERROR('Part 7'!EY690+0,0) -> 434 | X19: =IFERROR(V19-W19,"") -> 20 | Y19: ='Part 7'!EY18 -> 1232 | AA19: MARUTI ZEN ESTILO SUCTION HOSE | AB19: PC-117 | AC19: 0 | AD19: =IF($AB19="","",IF(TRIM(INDEX('Part 8'!$F$2:$IV$2,1,ROW()-1))=TRIM($AB19),INDEX('Part 8'!$F$244:$IV$244,1,ROW()-1),"CHECK")) -> 0 | AE19: =IFERROR(AC19-AD19,"") -> 0 | AF19: ='Part 8'!W9 -> 0
B20: BEAT-DSL | C20: PC-86589 | D20: 73 | E20: {=IF($B20="","",IF(TRIM(INDEX('Part 1'!$L$2:$IV$2,1,ROW()-1))=TRIM($B20),INDEX('Part 1'!$L$1250:$IV$1250,1,ROW()-1),"CHECK"))} -> 56 | F20: =IFERROR(D20-E20,"") -> 17 | G20: ='Part 1'!AD30 -> 350 | L20: PIZO (VALVO) | M20: NA | N20: 0 | O20: =IF($L20="","",IF(TRIM(INDEX('Part 4'!$E$2:$AY$2,1,ROW()-1))=TRIM($L20),INDEX('Part 4'!$E$778:$AY$778,1,ROW()-1),"CHECK")) -> 0 | P20: =IFERROR(N20-O20,"") -> 0 | Q20: ='Part 4'!W20 -> 0 | T20: SDN102/508/8PK | V20: 140 | W20: =IFERROR('Part 7'!EZ690+0,0) -> 130 | X20: =IFERROR(V20-W20,"") -> 10 | Y20: ='Part 7'!EZ18 -> 790 | AA20: MARUTI ZEN ESTILO LIQUID TUBE RD TO COIL | AB20: PC-118 | AC20: 0 | AD20: =IF($AB20="","",IF(TRIM(INDEX('Part 8'!$F$2:$IV$2,1,ROW()-1))=TRIM($AB20),INDEX('Part 8'!$F$244:$IV$244,1,ROW()-1),"CHECK")) -> 0 | AE20: =IFERROR(AC20-AD20,"") -> 0 | AF20: ='Part 8'!X9 -> 0
B21: BEAT-PTL | C21: PC-86535 | D21: 128 | E21: {=IF($B21="","",IF(TRIM(INDEX('Part 1'!$L$2:$IV$2,1,ROW()-1))=TRIM($B21),INDEX('Part 1'!$L$1250:$IV$1250,1,ROW()-1),"CHECK"))} -> 115 | F21: =IFERROR(D21-E21,"") -> 13 | G21: ='Part 1'!AE30 -> 652 | L21: Santro / Santro Zing | M21: PC-8026 | N21: 187 | O21: =IF($L21="","",IF(TRIM(INDEX('Part 4'!$E$2:$AY$2,1,ROW()-1))=TRIM($L21),INDEX('Part 4'!$E$778:$AY$778,1,ROW()-1),"CHECK")) -> 185 | P21: =IFERROR(N21-O21,"") -> 2 | Q21: ='Part 4'!X20 -> 322 | T21: I-20 (DSL) | U21: SD-313PL/I-20 DSL | V21: 15 | W21: =IFERROR('Part 7'!FA690+0,0) -> 15 | X21: =IFERROR(V21-W21,"") -> 0 | Y21: ='Part 7'!FA18 -> 387 | AA21: MARUTI SX4 DISCHARGE HOSE | AB21: PC-119 | AC21: 0 | AD21: =IF($AB21="","",IF(TRIM(INDEX('Part 8'!$F$2:$IV$2,1,ROW()-1))=TRIM($AB21),INDEX('Part 8'!$F$244:$IV$244,1,ROW()-1),"CHECK")) -> 0 | AE21: =IFERROR(AC21-AD21,"") -> 0 | AF21: ='Part 8'!Y9 -> 0
B22: BELANO | C22: PC-86242 | D22: 1 | E22: {=IF($B22="","",IF(TRIM(INDEX('Part 1'!$L$2:$IV$2,1,ROW()-1))=TRIM($B22),INDEX('Part 1'!$L$1250:$IV$1250,1,ROW()-1),"CHECK"))} -> 0 | F22: =IFERROR(D22-E22,"") -> 1 | G22: ='Part 1'!AF30 -> 118 | L22: Scorpio 3 holes | M22: PC-650138 | N22: 0 | O22: =IF($L22="","",IF(TRIM(INDEX('Part 4'!$E$2:$AY$2,1,ROW()-1))=TRIM($L22),INDEX('Part 4'!$E$778:$AY$778,1,ROW()-1),"CHECK")) -> 0 | P22: =IFERROR(N22-O22,"") -> 0 | Q22: ='Part 4'!Y20 -> 210 | T22: I-20 (PTL) | U22: SD-319PL/I-20 PTL | V22: 4 | W22: =IFERROR('Part 7'!FB690+0,0) -> 1 | X22: =IFERROR(V22-W22,"") -> 3 | Y22: ='Part 7'!FB18 -> 509 | AA22: MARUTI SX4 SUCTION HOSE | AB22: PC-120 | AC22: 0 | AD22: =IF($AB22="","",IF(TRIM(INDEX('Part 8'!$F$2:$IV$2,1,ROW()-1))=TRIM($AB22),INDEX('Part 8'!$F$244:$IV$244,1,ROW()-1),"CHECK")) -> 30 | AE22: =IFERROR(AC22-AD22,"") -> -30 | AF22: ='Part 8'!Z9 -> 0
E23: {=IF($B23="","",IF(TRIM(INDEX('Part 1'!$L$2:$IV$2,1,ROW()-1))=TRIM($B23),INDEX('Part 1'!$L$1250:$IV$1250,1,ROW()-1),"CHECK"))} | L23: Scorpio 4 holes | M23: PC-650139 | N23: 0 | O23: =IF($L23="","",IF(TRIM(INDEX('Part 4'!$E$2:$AY$2,1,ROW()-1))=TRIM($L23),INDEX('Part 4'!$E$778:$AY$778,1,ROW()-1),"CHECK")) -> 0 | P23: =IFERROR(N23-O23,"") -> 0 | Q23: ='Part 4'!Z20 -> 448 | T23: VISTA BEHR 6PK Q.JET | U23: SD316PL/V.QJET6PK | V23: 73 | W23: =IFERROR('Part 7'!FC690+0,0) -> 71 | X23: =IFERROR(V23-W23,"") -> 2 | Y23: ='Part 7'!FC18 -> 654 | AA23: MARUTI SX4 SUCTION TUBE | AB23: PC-121 | AC23: 0 | AD23: =IF($AB23="","",IF(TRIM(INDEX('Part 8'!$F$2:$IV$2,1,ROW()-1))=TRIM($AB23),INDEX('Part 8'!$F$244:$IV$244,1,ROW()-1),"CHECK")) -> 0 | AE23: =IFERROR(AC23-AD23,"") -> 0 | AF23: ='Part 8'!AA9 -> 0
B24: BMW E90 DSL SMALL | C24: PCP-C86741F | D24: 0 | E24: {=IF($B24="","",IF(TRIM(INDEX('Part 1'!$L$2:$IV$2,1,ROW()-1))=TRIM($B24),INDEX('Part 1'!$L$1250:$IV$1250,1,ROW()-1),"CHECK"))} -> 1 | F24: =IFERROR(D24-E24,"") -> -1 | G24: ='Part 1'!AH30 -> 0 | L24: Skoda | M24: PC-8053 | N24: 72 | O24: =IF($L24="","",IF(TRIM(INDEX('Part 4'!$E$2:$AY$2,1,ROW()-1))=TRIM($L24),INDEX('Part 4'!$E$778:$AY$778,1,ROW()-1),"CHECK")) -> 62 | P24: =IFERROR(N24-O24,"") -> 10 | Q24: ='Part 4'!AA20 -> 242 | T24: SCORPIO SANDEN | V24: 13 | W24: =IFERROR('Part 7'!FD690+0,0) -> 10 | X24: =IFERROR(V24-W24,"") -> 3 | Y24: ='Part 7'!FD18 -> 249 | AA24: MARUTI SX4 SUC HOSE N/M | AB24: PC-121A | AC24: 0 | AD24: =IF($AB24="","",IF(TRIM(INDEX('Part 8'!$F$2:$IV$2,1,ROW()-1))=TRIM($AB24),INDEX('Part 8'!$F$244:$IV$244,1,ROW()-1),"CHECK")) -> 0 | AE24: =IFERROR(AC24-AD24,"") -> 0 | AF24: ='Part 8'!AB9 -> 0
B25: BMW 3 SERIES E60 BIG | C25: PCP-C86749F | D25: 1 | E25: {=IF($B25="","",IF(TRIM(INDEX('Part 1'!$L$2:$IV$2,1,ROW()-1))=TRIM($B25),INDEX('Part 1'!$L$1250:$IV$1250,1,ROW()-1),"CHECK"))} -> 0 | F25: =IFERROR(D25-E25,"") -> 1 | G25: ='Part 1'!AI30 -> 28 | L25: Skoda Laura | M25: PC-8039B | N25: 5 | O25: =IF($L25="","",IF(TRIM(INDEX('Part 4'!$E$2:$AY$2,1,ROW()-1))=TRIM($L25),INDEX('Part 4'!$E$778:$AY$778,1,ROW()-1),"CHECK")) -> 5 | P25: =IFERROR(N25-O25,"") -> 0 | Q25: ='Part 4'!AB20 -> 300 | T25: SCORPIO HCC | V25: 45 | W25: =IFERROR('Part 7'!FE690+0,0) -> 48 | X25: =IFERROR(V25-W25,"") -> -3 | Y25: ='Part 7'!FE18 -> 233 | AA25: MARUTI SX4 SUCTION HOSE NEW | AB25: PC-121B | AC25: 0 | AD25: =IF($AB25="","",IF(TRIM(INDEX('Part 8'!$F$2:$IV$2,1,ROW()-1))=TRIM($AB25),INDEX('Part 8'!$F$244:$IV$244,1,ROW()-1),"CHECK")) -> 0 | AE25: =IFERROR(AC25-AD25,"") -> 0 | AF25: ='Part 8'!AC9 -> 0
B26: BMW 3 SERIES E60 PTL | C26: PCP-C86747F | D26: 0 | E26: {=IF($B26="","",IF(TRIM(INDEX('Part 1'!$L$2:$IV$2,1,ROW()-1))=TRIM($B26),INDEX('Part 1'!$L$1250:$IV$1250,1,ROW()-1),"CHECK"))} -> 0 | F26: =IFERROR(D26-E26,"") -> 0 | G26: ='Part 1'!AJ30 -> 16 | L26: Sonata | M26: PC-6066 | N26: 0 | O26: =IF($L26="","",IF(TRIM(INDEX('Part 4'!$E$2:$AY$2,1,ROW()-1))=TRIM($L26),INDEX('Part 4'!$E$778:$AY$778,1,ROW()-1),"CHECK")) -> 0 | P26: =IFERROR(N26-O26,"") -> 0 | Q26: ='Part 4'!AC20 -> 0 | T26: FEISTA DSL | U26: SD-315PL/FEISTA-DSL | V26: 9 | W26: =IFERROR('Part 7'!FF690+0,0) -> 3 | X26: =IFERROR(V26-W26,"") -> 6 | Y26: ='Part 7'!FF18 -> 325 | AA26: MARUTI SX 4 DISCHARGE HOSE NEW | AB26: PC-121C | AC26: 0 | AD26: =IF($AB26="","",IF(TRIM(INDEX('Part 8'!$F$2:$IV$2,1,ROW()-1))=TRIM($AB26),INDEX('Part 8'!$F$244:$IV$244,1,ROW()-1),"CHECK")) -> 0 | AE26: =IFERROR(AC26-AD26,"") -> 0 | AF26: ='Part 8'!AD9 -> 0
B27: BMW E60 DSL 03-07 | C27: PCP-C86748F | D27: 3 | E27: {=IF($B27="","",IF(TRIM(INDEX('Part 1'!$L$2:$IV$2,1,ROW()-1))=TRIM($B27),INDEX('Part 1'!$L$1250:$IV$1250,1,ROW()-1),"CHECK"))} -> 2 | F27: =IFERROR(D27-E27,"") -> 1 | G27: ='Part 1'!AK30 -> 15 | L27: TEMPO TRAVELLER-ORING 3/8 SIZE 70*270 | M27: PC-60002 | N27: 260 | O27: =IF($L27="","",IF(TRIM(INDEX('Part 4'!$E$2:$AY$2,1,ROW()-1))=TRIM($L27),INDEX('Part 4'!$E$778:$AY$778,1,ROW()-1),"CHECK")) -> 210 | P27: =IFERROR(N27-O27,"") -> 50 | Q27: ='Part 4'!AD20 -> 1047 | T27: SUMO VECTA DELPHI | U27: SD-321PL/SOMU V. DELPHI | V27: 0 | W27: =IFERROR('Part 7'!FG690+0,0) -> 0 | X27: =IFERROR(V27-W27,"") -> 0 | Y27: ='Part 7'!FG18 -> 546 | AA27: MARUTI SWIFT DSL DISCHARGE HOSE | AB27: PC-122 | AC27: 0 | AD27: =IF($AB27="","",IF(TRIM(INDEX('Part 8'!$F$2:$IV$2,1,ROW()-1))=TRIM($AB27),INDEX('Part 8'!$F$244:$IV$244,1,ROW()-1),"CHECK")) -> 0 | AE27: =IFERROR(AC27-AD27,"") -> 0 | AF27: ='Part 8'!AE9 -> 0
B28: BOLERO- R134A | C28: PC-86236 | D28: 42 | E28: {=IF($B28="","",IF(TRIM(INDEX('Part 1'!$L$2:$IV$2,1,ROW()-1))=TRIM($B28),INDEX('Part 1'!$L$1250:$IV$1250,1,ROW()-1),"CHECK"))} -> 42 | F28: =IFERROR(D28-E28,"") -> 0 | G28: ='Part 1'!AL30 -> 50 | L28: TEMPO TRAVELLER-SMALL (DENFOS) | M28: PC-60003 | N28: 55 | O28: =IF($L28="","",IF(TRIM(INDEX('Part 4'!$E$2:$AY$2,1,ROW()-1))=TRIM($L28),INDEX('Part 4'!$E$778:$AY$778,1,ROW()-1),"CHECK")) -> 50 | P28: =IFERROR(N28-O28,"") -> 5 | Q28: ='Part 4'!AE20 -> 115 | T28: A-STAR | U28: SD-323PL/A-STAR | V28: 282 | W28: =IFERROR('Part 7'!FH690+0,0) -> 220 | X28: =IFERROR(V28-W28,"") -> 62 | Y28: ='Part 7'!FH18 -> 1214 | AA28: MARUTI SWIFT DSL. SUCTIONON HOSE | AB28: PC-123 | AC28: 0 | AD28: =IF($AB28="","",IF(TRIM(INDEX('Part 8'!$F$2:$IV$2,1,ROW()-1))=TRIM($AB28),INDEX('Part 8'!$F$244:$IV$244,1,ROW()-1),"CHECK")) -> 0 | AE28: =IFERROR(AC28-AD28,"") -> 0 | AF28: ='Part 8'!AF9 -> 0
B29: BOLERO- R134A (NEW) | C29: PC-86395 | D29: 319 | E29: {=IF($B29="","",IF(TRIM(INDEX('Part 1'!$L$2:$IV$2,1,ROW()-1))=TRIM($B29),INDEX('Part 1'!$L$1250:$IV$1250,1,ROW()-1),"CHECK"))} -> 269 | F29: =IFERROR(D29-E29,"") -> 50 | G29: ='Part 1'!AM30 -> 728 | L29: Toyota Qualis/ SAFARI | M29: PC-8008 | N29: 420 | O29: =IF($L29="","",IF(TRIM(INDEX('Part 4'!$E$2:$AY$2,1,ROW()-1))=TRIM($L29),INDEX('Part 4'!$E$778:$AY$778,1,ROW()-1),"CHECK")) -> 310 | P29: =IFERROR(N29-O29,"") -> 110 | Q29: ='Part 4'!AF20 -> 998 | T29: I-10 KAPPA | U29: SD-317PL/I10 KAPPA | V29: 52 | W29: =IFERROR('Part 7'!FI690+0,0) -> 46 | X29: =IFERROR(V29-W29,"") -> 6 | Y29: ='Part 7'!FI18 -> 608 | AA29: MARUTI SWIFT DSL LIQUID TUBE RD TO COOLING COIL | AB29: PC-124 | AC29: 0 | AD29: =IF($AB29="","",IF(TRIM(INDEX('Part 8'!$F$2:$IV$2,1,ROW()-1))=TRIM($AB29),INDEX('Part 8'!$F$244:$IV$244,1,ROW()-1),"CHECK")) -> 0 | AE29: =IFERROR(AC29-AD29,"") -> 0 | AF29: ='Part 8'!AG9 -> 0
B30: BREEZA-Q5 | C30: PC-86811-Q5 | D30: 22 | E30: {=IF($B30="","",IF(TRIM(INDEX('Part 1'!$L$2:$IV$2,1,ROW()-1))=TRIM($B30),INDEX('Part 1'!$L$1250:$IV$1250,1,ROW()-1),"CHECK"))} -> 11 | F30: =IFERROR(D30-E30,"") -> 11 | G30: ='Part 1'!AN30 -> 127 | L30: Travera | M30: PC-8122 | N30: 10 | O30: =IF($L30="","",IF(TRIM(INDEX('Part 4'!$E$2:$AY$2,1,ROW()-1))=TRIM($L30),INDEX('Part 4'!$E$778:$AY$778,1,ROW()-1),"CHECK")) -> 10 | P30: =IFERROR(N30-O30,"") -> 0 | Q30: ='Part 4'!AG20 -> 2104 | T30: HONDA ZX/T4 | U30: SD-320PL/HT4ZXDSL | V30: 32 | W30: =IFERROR('Part 7'!FJ690+0,0) -> 32 | X30: =IFERROR(V30-W30,"") -> 0 | Y30: ='Part 7'!FJ18 -> 632 | AA30: MARUTI SWIFT DSL DISCHARGE HOSE. | AB30: PC-124A | AC30: 0 | AD30: =IF($AB30="","",IF(TRIM(INDEX('Part 8'!$F$2:$IV$2,1,ROW()-1))=TRIM($AB30),INDEX('Part 8'!$F$244:$IV$244,1,ROW()-1),"CHECK")) -> 0 | AE30: =IFERROR(AC30-AD30,"") -> 0 | AF30: ='Part 8'!AH9 -> 0
B31: BRIO | C31: PC-86581 | D31: 107 | E31: {=IF($B31="","",IF(TRIM(INDEX('Part 1'!$L$2:$IV$2,1,ROW()-1))=TRIM($B31),INDEX('Part 1'!$L$1250:$IV$1250,1,ROW()-1),"CHECK"))} -> 87 | F31: =IFERROR(D31-E31,"") -> 20 | G31: ='Part 1'!AO30 -> 517 | L31: Universal BUS- 3/8F SIZE 76*245 | M31: PC-61020 | N31: 227 | O31: =IF($L31="","",IF(TRIM(INDEX('Part 4'!$E$2:$AY$2,1,ROW()-1))=TRIM($L31),INDEX('Part 4'!$E$778:$AY$778,1,ROW()-1),"CHECK")) -> 185 | P31: =IFERROR(N31-O31,"") -> 42 | Q31: ='Part 4'!AH20 -> 1199 | T31: BOLERO | U31: SD-311PL/BLR | V31: 67 | W31: =IFERROR('Part 7'!FK690+0,0) -> 54 | X31: =IFERROR(V31-W31,"") -> 13 | Y31: ='Part 7'!FK18 -> 721 | AA31: MARUTI SWIFT DSL DISCHARGE HOSE DE'ZIRE | AB31: PC-124B | AC31: 0 | AD31: =IF($AB31="","",IF(TRIM(INDEX('Part 8'!$F$2:$IV$2,1,ROW()-1))=TRIM($AB31),INDEX('Part 8'!$F$244:$IV$244,1,ROW()-1),"CHECK")) -> 0 | AE31: =IFERROR(AC31-AD31,"") -> 0 | AF31: ='Part 8'!AI9 -> 0
B32: BRIO-Q5 | C32: PC-86581-Q5 | D32: 86 | E32: {=IF($B32="","",IF(TRIM(INDEX('Part 1'!$L$2:$IV$2,1,ROW()-1))=TRIM($B32),INDEX('Part 1'!$L$1250:$IV$1250,1,ROW()-1),"CHECK"))} -> 10 | F32: =IFERROR(D32-E32,"") -> 76 | G32: ='Part 1'!AP30 -> 195 | L32: Universal-F | M32: PC-6001 | N32: 75 | O32: =IF($L32="","",IF(TRIM(INDEX('Part 4'!$E$2:$AY$2,1,ROW()-1))=TRIM($L32),INDEX('Part 4'!$E$778:$AY$778,1,ROW()-1),"CHECK")) -> 50 | P32: =IFERROR(N32-O32,"") -> 25 | Q32: ='Part 4'!AI20 -> 1463 | T32: SX4 | U32: SD-322PL/SX4 | V32: 17 | W32: =IFERROR('Part 7'!FL690+0,0) -> 0 | X32: =IFERROR(V32-W32,"") -> 17 | Y32: ='Part 7'!FL18 -> 363 | AA32: MARUTI BALENO SUCTION HOSE | AB32: PC-125 | AC32: 0 | AD32: =IF($AB32="","",IF(TRIM(INDEX('Part 8'!$F$2:$IV$2,1,ROW()-1))=TRIM($AB32),INDEX('Part 8'!$F$244:$IV$244,1,ROW()-1),"CHECK")) -> 0 | AE32: =IFERROR(AC32-AD32,"") -> 0 | AF32: ='Part 8'!AJ9 -> 0
B33: CAIZ-Q5 | C33: PC-86812Q5 | D33: 15 | E33: {=IF($B33="","",IF(TRIM(INDEX('Part 1'!$L$2:$IV$2,1,ROW()-1))=TRIM($B33),INDEX('Part 1'!$L$1250:$IV$1250,1,ROW()-1),"CHECK"))} -> 15 | F33: =IFERROR(D33-E33,"") -> 0 | G33: ='Part 1'!AQ30 -> 100 | L33: Universal-O | M33: PC-6002 | N33: 100 | O33: =IF($L33="","",IF(TRIM(INDEX('Part 4'!$E$2:$AY$2,1,ROW()-1))=TRIM($L33),INDEX('Part 4'!$E$778:$AY$778,1,ROW()-1),"CHECK")) -> 75 | P33: =IFERROR(N33-O33,"") -> 25 | Q33: ='Part 4'!AJ20 -> 2900 | T33: ENDEAVOUR | U33: SD-318PL/END | V33: 2 | W33: =IFERROR('Part 7'!FM690+0,0) -> 2 | X33: =IFERROR(V33-W33,"") -> 0 | Y33: ='Part 7'!FM18 -> 160 | AA33: MARUTI BALENO DISCHARGE HOSE | AB33: PC-126 | AC33: 0 | AD33: =IF($AB33="","",IF(TRIM(INDEX('Part 8'!$F$2:$IV$2,1,ROW()-1))=TRIM($AB33),INDEX('Part 8'!$F$244:$IV$244,1,ROW()-1),"CHECK")) -> 0 | AE33: =IFERROR(AC33-AD33,"") -> 0 | AF33: ='Part 8'!AK9 -> 0
B34: CAMRY - 02-05 | C34: PC-86396 | D34: 0 | E34: {=IF($B34="","",IF(TRIM(INDEX('Part 1'!$L$2:$IV$2,1,ROW()-1))=TRIM($B34),INDEX('Part 1'!$L$1250:$IV$1250,1,ROW()-1),"CHECK"))} -> 0 | F34: =IFERROR(D34-E34,"") -> 0 | G34: ='Part 1'!AR30 -> 58 | L34: ADOPTER ORING 5/16 TO 3/8 FLARE | N34: 0 | O34: =IF($L34="","",IF(TRIM(INDEX('Part 4'!$E$2:$AY$2,1,ROW()-1))=TRIM($L34),INDEX('Part 4'!$E$778:$AY$778,1,ROW()-1),"CHECK")) -> 170 | P34: =IFERROR(N34-O34,"") -> -170 | Q34: ='Part 4'!AK20 -> -1535 | T34: HT3 | U34: SD312PL/HT3 | V34: 23 | W34: =IFERROR('Part 7'!FN690+0,0) -> 10 | X34: =IFERROR(V34-W34,"") -> 13 | Y34: ='Part 7'!FN18 -> 911 | AA34: MARUTI BALENO SUCTION TUBE | AB34: PC-127 | AC34: 0 | AD34: =IF($AB34="","",IF(TRIM(INDEX('Part 8'!$F$2:$IV$2,1,ROW()-1))=TRIM($AB34),INDEX('Part 8'!$F$244:$IV$244,1,ROW()-1),"CHECK")) -> 0 | AE34: =IFERROR(AC34-AD34,"") -> 0 | AF34: ='Part 8'!AL9 -> 0
B35: CAMRY - 07-09 | C35: PC-86397 | D35: 0 | E35: {=IF($B35="","",IF(TRIM(INDEX('Part 1'!$L$2:$IV$2,1,ROW()-1))=TRIM($B35),INDEX('Part 1'!$L$1250:$IV$1250,1,ROW()-1),"CHECK"))} -> 0 | F35: =IFERROR(D35-E35,"") -> 0 | G35: ='Part 1'!AS30 -> 0 | L35: Universal-O | M35: PC-6001B | N35: 0 | O35: =IF($L35="","",IF(TRIM(INDEX('Part 4'!$E$2:$AY$2,1,ROW()-1))=TRIM($L35),INDEX('Part 4'!$E$778:$AY$778,1,ROW()-1),"CHECK")) -> 0 | P35: =IFERROR(N35-O35,"") -> 0 | Q35: ='Part 4'!AL20 -> -284 | T35: SWIFT PTL | U35: SD324PL/SWT-PTL | V35: 33 | W35: =IFERROR('Part 7'!FO690+0,0) -> 33 | X35: =IFERROR(V35-W35,"") -> 0 | Y35: ='Part 7'!FO18 -> 336 | AA35: MARUTI BALENO LIQUID TUBE | AB35: PC-128 | AC35: 0 | AD35: =IF($AB35="","",IF(TRIM(INDEX('Part 8'!$F$2:$IV$2,1,ROW()-1))=TRIM($AB35),INDEX('Part 8'!$F$244:$IV$244,1,ROW()-1),"CHECK")) -> 30 | AE35: =IFERROR(AC35-AD35,"") -> -30 | AF35: ='Part 8'!AM9 -> 0
B36: CAMRY - 07-09 (Q5) | C36: PC-86397-Q5 | D36: 0 | E36: {=IF($B36="","",IF(TRIM(INDEX('Part 1'!$L$2:$IV$2,1,ROW()-1))=TRIM($B36),INDEX('Part 1'!$L$1250:$IV$1250,1,ROW()-1),"CHECK"))} -> 0 | F36: =IFERROR(D36-E36,"") -> 0 | G36: ='Part 1'!AT30 -> 35 | L36: Universal-F WITH BOLT | M36: PC-6003 | N36: 0 | O36: =IF($L36="","",IF(TRIM(INDEX('Part 4'!$E$2:$AY$2,1,ROW()-1))=TRIM($L36),INDEX('Part 4'!$E$778:$AY$778,1,ROW()-1),"CHECK")) -> 0 | P36: =IFERROR(N36-O36,"") -> 0 | Q36: ='Part 4'!AM20 -> 105 | T36: SWIFT DSL | U36: SD325PL/SWT-DSL | V36: 120 | W36: =IFERROR('Part 7'!FP690+0,0) -> 77 | X36: =IFERROR(V36-W36,"") -> 43 | Y36: ='Part 7'!FP18 -> 852 | AA36: MARUTI LIQUID TUBE BALENO | AB36: PC-129 | AC36: 0 | AD36: =IF($AB36="","",IF(TRIM(INDEX('Part 8'!$F$2:$IV$2,1,ROW()-1))=TRIM($AB36),INDEX('Part 8'!$F$244:$IV$244,1,ROW()-1),"CHECK")) -> 0 | AE36: =IFERROR(AC36-AD36,"") -> 0 | AF36: ='Part 8'!AN9 -> 0
B37: CELERO | C37: PC-86903 | D37: 95 | E37: {=IF($B37="","",IF(TRIM(INDEX('Part 1'!$L$2:$IV$2,1,ROW()-1))=TRIM($B37),INDEX('Part 1'!$L$1250:$IV$1250,1,ROW()-1),"CHECK"))} -> 89 | F37: =IFERROR(D37-E37,"") -> 6 | G37: ='Part 1'!AU30 -> 200 | L37: Skoda SUPERB | M37: PC-650140 | N37: 20 | O37: =IF($L37="","",IF(TRIM(INDEX('Part 4'!$E$2:$AY$2,1,ROW()-1))=TRIM($L37),INDEX('Part 4'!$E$778:$AY$778,1,ROW()-1),"CHECK")) -> 20 | P37: =IFERROR(N37-O37,"") -> 0 | Q37: ='Part 4'!AN20 -> 110 | T37: CRV | U37: SD301PL/CRV | V37: 0 | W37: =IFERROR('Part 7'!FQ690+0,0) -> 0 | X37: =IFERROR(V37-W37,"") -> 0 | Y37: ='Part 7'!FQ18 -> 281 | AA37: MARUTI SWIFT PTL SUCTION HOSE | AB37: PC-130 | AC37: 0 | AD37: =IF($AB37="","",IF(TRIM(INDEX('Part 8'!$F$2:$IV$2,1,ROW()-1))=TRIM($AB37),INDEX('Part 8'!$F$244:$IV$244,1,ROW()-1),"CHECK")) -> 0 | AE37: =IFERROR(AC37-AD37,"") -> 0 | AF37: ='Part 8'!AO9 -> 0
B38: CIAZ-Q5 | C38: PC-86901 | D38: 20 | E38: {=IF($B38="","",IF(TRIM(INDEX('Part 1'!$L$2:$IV$2,1,ROW()-1))=TRIM($B38),INDEX('Part 1'!$L$1250:$IV$1250,1,ROW()-1),"CHECK"))} -> 9 | F38: =IFERROR(D38-E38,"") -> 11 | G38: ='Part 1'!AV30 -> 56 | L38: Universal | M38: PC-6003 | N38: 0 | O38: =IF($L38="","",IF(TRIM(INDEX('Part 4'!$E$2:$AY$2,1,ROW()-1))=TRIM($L38),INDEX('Part 4'!$E$778:$AY$778,1,ROW()-1),"CHECK")) -> 0 | P38: =IFERROR(N38-O38,"") -> 0 | Q38: ='Part 4'!AO20 -> 0 | T38: CIVIC | U38: SD326PL/CIVIC | V38: 12 | W38: =IFERROR('Part 7'!FR690+0,0) -> 4 | X38: =IFERROR(V38-W38,"") -> 8 | Y38: ='Part 7'!FR18 -> 149 | AA38: MARUTI SWIFT DISCHARGE HOSE | AB38: PC-131 | AC38: 0 | AD38: =IF($AB38="","",IF(TRIM(INDEX('Part 8'!$F$2:$IV$2,1,ROW()-1))=TRIM($AB38),INDEX('Part 8'!$F$244:$IV$244,1,ROW()-1),"CHECK")) -> 10 | AE38: =IFERROR(AC38-AD38,"") -> -10 | AF38: ='Part 8'!AP9 -> 0
B39: COROLLA | C39: PC-86110 | D39: 16 | E39: {=IF($B39="","",IF(TRIM(INDEX('Part 1'!$L$2:$IV$2,1,ROW()-1))=TRIM($B39),INDEX('Part 1'!$L$1250:$IV$1250,1,ROW()-1),"CHECK"))} -> 14 | F39: =IFERROR(D39-E39,"") -> 2 | G39: ='Part 1'!AW30 -> 140 | L39: EYE GLASS | N39: 0 | O39: =IF($L39="","",IF(TRIM(INDEX('Part 4'!$E$2:$AY$2,1,ROW()-1))=TRIM($L39),INDEX('Part 4'!$E$778:$AY$778,1,ROW()-1),"CHECK")) -> 0 | P39: =IFERROR(N39-O39,"") -> 0 | Q39: ='Part 4'!AP20 -> -400 | T39: VARNA | U39: SD327PL/VARNA | V39: 6 | W39: =IFERROR('Part 7'!FS690+0,0) -> 4 | X39: =IFERROR(V39-W39,"") -> 2 | Y39: ='Part 7'!FS18 -> 277 | AA39: MARUTI SWIFT LIQUID TUBE RD TO COIL | AB39: PC-132 | AC39: 0 | AD39: =IF($AB39="","",IF(TRIM(INDEX('Part 8'!$F$2:$IV$2,1,ROW()-1))=TRIM($AB39),INDEX('Part 8'!$F$244:$IV$244,1,ROW()-1),"CHECK")) -> 5 | AE39: =IFERROR(AC39-AD39,"") -> -5 | AF39: ='Part 8'!AQ9 -> 0
B40: COROLLA-Q5 | C40: PC-86110A-Q5 | D40: 15 | E40: {=IF($B40="","",IF(TRIM(INDEX('Part 1'!$L$2:$IV$2,1,ROW()-1))=TRIM($B40),INDEX('Part 1'!$L$1250:$IV$1250,1,ROW()-1),"CHECK"))} -> 16 | F40: =IFERROR(D40-E40,"") -> -1 | G40: ='Part 1'!AX30 -> 200 | L40: Desiccant Drier/Filter | M40: PC-20242 | N40: 190 | O40: =IF($L40="","",IF(TRIM(INDEX('Part 4'!$E$2:$AY$2,1,ROW()-1))=TRIM($L40),INDEX('Part 4'!$E$778:$AY$778,1,ROW()-1),"CHECK")) -> 240 | P40: =IFERROR(N40-O40,"") -> -50 | Q40: ='Part 4'!AQ20 -> 8500 | T40: MHAWK | U40: SD328PL/MHWK | V40: 68 | W40: =IFERROR('Part 7'!FT690+0,0) -> 66 | X40: =IFERROR(V40-W40,"") -> 2 | Y40: ='Part 7'!FT18 -> 291 | AA40: MARUTI SWIFT PTL DISCHARGE HOSE NEW | AB40: PC-132A | AC40: 0 | AD40: =IF($AB40="","",IF(TRIM(INDEX('Part 8'!$F$2:$IV$2,1,ROW()-1))=TRIM($AB40),INDEX('Part 8'!$F$244:$IV$244,1,ROW()-1),"CHECK")) -> 0 | AE40: =IFERROR(AC40-AD40,"") -> 0 | AF40: ='Part 8'!AR9 -> 0
...

Sheet Part Summary
A1: PART SUMMARY 2019 — Challan book GST-Challan 2019-0001 to 2019-0490 (01.01.19 – 13.05.19). Total Qty = D × E, else Qty column. Cancelled = CANCEL mark in the challan block. Values from Pivot Data; checks live.
A3: Part Name | B3: Part Number | C3: Total Qty | D3: Cancelled Qty | E3: Net Qty (excl. Cancelled)
A4: 10 PK | B4: SDN/062/10PK | C4: 10 | D4: 0 | E4: 10
A5: 10"X10 B- (Straight Blade) | B5: TST-8801 | C5: 10 | D5: 10 | E5: 0
A6: 10"X6 B- ('S' Type Blade) | B6: TS-8805 | C6: 82 | D6: 32 | E6: 50
A7: 11mm flare iron nut | C7: 782 | D7: 0 | E7: 782
A8: 12"X10 B- Straight Blade | B8: TST-8801-A | C8: 10 | D8: 0 | E8: 10
A9: 12"X10 B- Straight Blade) | B9: TST-8801-A | C9: 56 | D9: 16 | E9: 40
A10: 12"X10 Blade- ('S' Type Blade) | B10: TS-8805-B | C10: 502 | D10: 72 | E10: 430
A11: 14"X10 B-(Straight Blade) | B11: TST-8801-B | C11: 42 | D11: 22 | E11: 20
A12: 14X25X20MM flare | C12: 200 | D12: 0 | E12: 200
A13: 14X28X20MM flare | C13: 60 | D13: 5 | E13: 55
A14: 14X30X20MM flare | C14: 30 | D14: 0 | E14: 30
A15: 14x15x18mm ORING - CUT TYPE | C15: 2 | D15: 0 | E15: 2
A16: 14x15x18mm flare - CUT TYPE | C16: 102 | D16: 20 | E16: 82
A17: 14x18x20mm flare | C17: 90 | D17: 0 | E17: 90
A18: 14x21x20mm flare | C18: 50 | D18: 0 | E18: 50
A19: 14x21x22mm flare | C19: 84 | D19: 14 | E19: 70
A20: 14x23x16mm flare | C20: 60 | D20: 0 | E20: 60
A21: 14x23x20mm flare | C21: 40 | D21: 10 | E21: 30
A22: 14x23x22mm flare | C22: 10 | D22: 0 | E22: 10
A23: 14x25x26mm flare | B23: 142526 | C23: 10 | D23: 0 | E23: 10
A24: 15mm flare iron nut | C24: 55 | D24: 0 | E24: 55
A25: 1PC SAMPLE SEND BY COURIER | C25: 2 | D25: 1 | E25: 1
A26: 2 PCS 86125 SCHEME OF 86541Q5 WAS NOT SUPPLIED IN 2019-0250, | C26: 2 | D26: 0 | E26: 2
A27: 25x28x20 | C27: 78 | D27: 2 | E27: 76
A28: 25x28x26 | C28: 20 | D28: 0 | E28: 20
A29: 3 Speed A/C Santro Switch | B29: PC-1001 | C29: 220 | D29: 20 | E29: 200
A30: 4 PCS 507 IN MULTIGROOVE | B30: 5H11-507MG | C30: 134 | D30: 4 | E30: 130
A31: 4 PCS 507-V GROVE PULLEY | B31: 5H11 | C31: 12 | D31: 0 | E31: 12
A32: 4 PCS 508 IN MULTIGROOVE | B32: 5H14-508MG | C32: 22 | D32: 8 | E32: 14
A33: 4 PCS 508-V GROVE PULLEY | B33: 5H14 | C33: 4 | D33: 0 | E33: 4
A34: 4 Speed A/C Xing Switch | C34: 145 | D34: 0 | E34: 145
A35: 404 BAZEL | B35: SEA-NAIR | C35: 40 | D35: 8 | E35: 32
A36: 505-V GROVE PULLEY | B36: COMPANY-A | C36: 3 | D36: 3 | E36: 0
A37: 507 IN MULTIGROOVE | B37: 5H11-507MG | C37: 36 | D37: 5 | E37: 31
A38: 507 IN MULTIGROOVE FREE WITH COOLING COIL | B38: 5H11-507MG | C38: 1 | D38: 0 | E38: 1
A39: 507 Small Single | B39: PC-7201 | C39: 25 | D39: 0 | E39: 25
A40: 507 V-GROVE FREE WITH CC | B40: 5H11 | C40: 1 | D40: 0 | E40: 1
A41: 507-7PK (WITHOUT BEARING) | B41: SDN-101/507/7PK | C41: 454 | D41: 0 | E41: 454
...

Sheet Pivot Summary
A1: PIVOT SUMMARY 2019 — PivotTable over Pivot Data (challan book)
A2: Cancelled filter "-" = active challans only. Double-click any total to list its lines. Grand total must equal Part Summary Net Qty.
A5: Cancelled | B5: (Multiple Items)
A7: Part Name | B7: Part Number | C7: Sum of Total Qty
A8: 10 PK | B8: SDN/062/10PK | C8: 10
A9: 10"X6 B- ('S' Type Blade) | B9: TS-8805 | C9: 50
A10: 11mm flare iron nut | C10: 782
A11: 12"X10 B- Straight Blade | B11: TST-8801-A | C11: 10
A12: 12"X10 B- Straight Blade) | B12: TST-8801-A | C12: 40
A13: 12"X10 Blade- ('S' Type Blade) | B13: TS-8805-B | C13: 430
A14: 14"X10 B-(Straight Blade) | B14: TST-8801-B | C14: 20
A15: 14x15x18mm flare - CUT TYPE | C15: 82
A16: 14x15x18mm ORING - CUT TYPE | C16: 2
A17: 14x18x20mm flare | C17: 90
A18: 14x21x20mm flare | C18: 50
A19: 14x21x22mm flare | C19: 70
A20: 14x23x16mm flare | C20: 60
A21: 14x23x20mm flare | C21: 30
A22: 14x23x22mm flare | C22: 10
A23: 14X25X20MM flare | C23: 200
A24: 14x25x26mm flare | B24: 142526 | C24: 10
A25: 14X28X20MM flare | C25: 55
A26: 14X30X20MM flare | C26: 30
A27: 15mm flare iron nut | C27: 55
A28: 1PC SAMPLE SEND BY COURIER | C28: 1
A29: 2 PCS 86125 SCHEME OF 86541Q5 WAS NOT SUPPLIED IN 2019-0250, | C29: 2
A30: 25x28x20 | C30: 76
A31: 25x28x26 | C31: 20
A32: 3 Speed A/C Santro Switch | B32: PC-1001 | C32: 200
A33: 4 PCS 507 IN MULTIGROOVE | B33: 5H11-507MG | C33: 130
A34: 4 PCS 507-V GROVE PULLEY | B34: 5H11 | C34: 12
A35: 4 PCS 508 IN MULTIGROOVE | B35: 5H14-508MG | C35: 14
A36: 4 PCS 508-V GROVE PULLEY | B36: 5H14 | C36: 4
A37: 4 Speed A/C Xing Switch | C37: 145
A38: 404 BAZEL | B38: SEA-NAIR | C38: 32
A39: 507 IN MULTIGROOVE | B39: 5H11-507MG | C39: 31
A40: 507 IN MULTIGROOVE FREE WITH COOLING COIL | B40: 5H11-507MG | C40: 1
A41: 507 Small Single | B41: PC-7201 | C41: 25
A42: 507 V-GROVE FREE WITH CC | B42: 5H11 | C42: 1
A43: 507/508 single seal | B43: PC-7053A PC-7200 | C43: 200
...

Sheet Condenser Audit
A1: CONDENSER (Part 1) — AUDIT 2019
A2: 221 Recon condenser rows: Challan recounted from active challan lines (Pivot Data, 01.01–13.05.19); every Part 1 ledger sale traced to its challan. Stock = Part 1 TOTAL SOLD.
B4: AT A GLANCE | C4: Rows | D4: Gap (pcs)
B5: Rows reviewed | C5: 221
B6: Tie (no gap) before audit | C6: 93
B7: Fixed — Recon formula missed challan lines | C7: 4 | D7: 18
B8: Explained — gap fully traced to ledger postings (noted on Recon, green) | C8: 69 | D8: 699
B10: CONFLICTS FOR DECISION | C10: Rows | D10: Gap (pcs)
B11: One code used for several car models | C11: 14 | D11: 712
B12: Ledger qty differs from challan line | C12: 12 | D12: 255
B13: Ledger sale, no challan line under this code | C13: 15 | D13: 234
B14: Ledger postings not fully traced | C14: 14 | D14: 150
B15: Total | C15: =SUM(C11:C14) -> 55 | D15: =SUM(D11:D14) -> 1351
A17: CONFLICT REGISTER
A18: # | B18: Conflict | C18: Recon row | D18: Part | E18: Code | F18: Recon Challan | G18: Challan lines | H18: Ledger sold | I18: Gap / detail
A19: 1 | B19: One code used for several car models | C19: 192 | D19: VERNA (FLUDIC)-Q5 | E19: PC-86541-Q5 | F19: 0 | G19: 240 | H19: 231 | I19: -231 — Lines under PC-86541-Q5 (240 pcs) carry: I-20 (DSL OLD)-Q5 / VARNA FLUDIC-DSL-Q5 / VARNA FLUDIC-DSL-Q5 WITH SCHEME; ledger books 231.
A20: 2 | B20: One code used for several car models | C20: 104 | D20: I-10 GRAND (PTL) | E20: PC-86448B | F20: 0 | G20: 205 | H20: 197 | I20: -197 — Lines under PC-86448B (205 pcs) carry: I-20 NEW PAD TYPE / I-10 GRAND (PTL) / I-20 (ELITE); ledger books 197.
A21: 3 | B21: One code used for several car models | C21: 197 | D21: WAGON R / ALTO (NEW) | E21: PC-86393 | F21: 498 | G21: 498 | H21: 452 | I21: 46 — Lines under PC-86393 (498 pcs) carry: WAGON R / ALTO (NEW)-K10 / ZEN ESTILO -T2; ledger books 452.
A22: 4 | B22: One code used for several car models | C22: 193 | D22: VERSA | E22: PC-86365 | F22: 129 | G22: 128 | H22: 84 | I22: 45 — Lines under PC-86365 (128 pcs) carry: EECO / VERSA; ledger books 84.
A23: 5 | B23: One code used for several car models | C23: 161 | D23: SAIL DSL | E23: PC-86910 | F23: 143 | G23: 143 | H23: 103 | I23: 40 — Lines under PC-86910 (143 pcs) carry: SAIL-DSL / TATA ARIA-DSL; ledger books 103.
A24: 6 | B24: One code used for several car models | C24: 178 | D24: SWIFT-NEW | E24: PC-86539 | F24: 335 | G24: 335 | H24: 297 | I24: 38 — Lines under PC-86539 (335 pcs) carry: SWIFT (NEW) / ERTIGA / SX 4 (NEW); ledger books 297.
A25: 7 | B25: One code used for several car models | C25: 179 | D25: SWIFT-NEW-Q5 | E25: PC-86539-Q5 | F25: 0 | G25: 58 | H25: 33 | I25: -33 — Lines under PC-86539-Q5 (58 pcs) carry: SWIFT (NEW)-Q5 / SX 4 (NEW)-Q5 / ERTIGA-Q5; ledger books 33.
A26: 8 | B26: One code used for several car models | C26: 123 | D26: INNOVA-T4-Q5 | E26: PC-86536-Q5 | F26: 81 | G26: 81 | H26: 60 | I26: 21 — Lines under PC-86536-Q5 (81 pcs) carry: INNOVA - T4 (Q5) / INNOVA - T4 (Q5) FREE 1 PCS PC CC I-10 GRAND ON 7 PCS 86536Q5; ledger books 60.
A27: 9 | B27: One code used for several car models | C27: 200 | D27: XYLO-Q5 SUBROS (BIG) | E27: PC-86449 | F27: 89 | G27: 88 | H27: 68 | I27: 21 — Lines under PC-86449 (88 pcs) carry: TEMPO TRAVELLER-NEW / XYLO SUBROS 3680 -BIG; ledger books 68.
A28: 10 | B28: One code used for several car models | C28: 50 | D28: DUSTER / TERRANO-110CC | E28: PC-86920 | F28: 69 | G28: 69 | H28: 50 | I28: 19 — Lines under PC-86920 (69 pcs) carry: DUSTER DSL 110CC / TERRANO; ledger books 50.
A29: 11 | B29: One code used for several car models | C29: 13 | D29: AUDI Q3 | E29: PCP-C86020 | F29: 28 | G29: 28 | H29: 20 | I29: 8 — Lines under PCP-C86020 (28 pcs) carry: AUDI Q3 PREMIUM Q5 / SKODA SUPERB (NEW) PREMIUM Q5; ledger books 20.
A30: 12 | B30: One code used for several car models | C30: 102 | D30: I-10 GRAND (DSL) | E30: PC-86655 | F30: 107 | G30: 107 | H30: 102 | I30: 5 — Lines under PC-86655 (107 pcs) carry: I-10 GRAND (DSL) / XCENT (DSL) / VARNA FLUDIC-PTL; ledger books 102.
... A73: 55 | B73: Ledger postings not fully traced | C73: 157 | D73: RITZ PETROL-Q5 | E73: PC-86370AQ5 | F73: 34 | G73: 34 | H73: 33 | I73: 1 — not posted: 2019-0349:1, 2019-0387:1, 2019-0442:1

Sheet CHALLAN
W1: ChallanNo | X1: Cancelled | Y1: CleanCode | Z1: Qty | AB1: CancelledChallans
W2: =IF(LEFT($H2&"",5)="2019-",$H2,"") | X2: =IF($W2="",0,IF(COUNTIF($AB$2:$AB$80,$W2)>0,1,0)) | Y2: =IF($C2="","",UPPER(TRIM(IFERROR(LEFT($C2&"",FIND("/",$C2&"")-1),$C2&"")))) | Z2: =IFERROR(IF(ISNUMBER($G2),$G2,0),0) | AB2: 2019-0001
A3: To, | G3: Dated.: | H3: 01.01.19 | W3: =IF(LEFT($H3&"",5)="2019-",$H3,W2) | X3: =IF($W3="",0,IF(COUNTIF($AB$2:$AB$80,$W3)>0,1,0)) | Y3: =IF($C3="","",UPPER(TRIM(IFERROR(LEFT($C3&"",FIND("/",$C3&"")-1),$C3&"")))) | Z3: =IFERROR(IF(ISNUMBER($G3),$G3,0),0) | AB3: 2019-0003
A4: Dealer-150 | F4: GST-Challan # | H4: 2019-0001 | W4: =IF(LEFT($H4&"",5)="2019-",$H4,W3) | X4: =IF($W4="",0,IF(COUNTIF($AB$2:$AB$80,$W4)>0,1,0)) | Y4: =IF($C4="","",UPPER(TRIM(IFERROR(LEFT($C4&"",FIND("/",$C4&"")-1),$C4&"")))) | Z4: =IFERROR(IF(ISNUMBER($G4),$G4,0),0) | AB4: 2019-0004
A5: Dealer-159 | W5: =IF(LEFT($H5&"",5)="2019-",$H5,W4) | X5: =IF($W5="",0,IF(COUNTIF($AB$2:$AB$80,$W5)>0,1,0)) | Y5: =IF($C5="","",UPPER(TRIM(IFERROR(LEFT($C5&"",FIND("/",$C5&"")-1),$C5&"")))) | Z5: =IFERROR(IF(ISNUMBER($G5),$G5,0),0) | AB5: 2019-0007
A6: Address line (redacted) | W6: =IF(LEFT($H6&"",5)="2019-",$H6,W5) | X6: =IF($W6="",0,IF(COUNTIF($AB$2:$AB$80,$W6)>0,1,0)) | Y6: =IF($C6="","",UPPER(TRIM(IFERROR(LEFT($C6&"",FIND("/",$C6&"")-1),$C6&"")))) | Z6: =IFERROR(IF(ISNUMBER($G6),$G6,0),0) | AB6: 2019-0010
A7: Address line (redacted) | W7: =IF(LEFT($H7&"",5)="2019-",$H7,W6) | X7: =IF($W7="",0,IF(COUNTIF($AB$2:$AB$80,$W7)>0,1,0)) | Y7: =IF($C7="","",UPPER(TRIM(IFERROR(LEFT($C7&"",FIND("/",$C7&"")-1),$C7&"")))) | Z7: =IFERROR(IF(ISNUMBER($G7),$G7,0),0) | AB7: 2019-0018
A8: GSTIN: | B8: GSTIN-MASKED | W8: =IF(LEFT($H8&"",5)="2019-",$H8,W7) | X8: =IF($W8="",0,IF(COUNTIF($AB$2:$AB$80,$W8)>0,1,0)) | Y8: =IF($C8="","",UPPER(TRIM(IFERROR(LEFT($C8&"",FIND("/",$C8&"")-1),$C8&"")))) | Z8: =IFERROR(IF(ISNUMBER($G8),$G8,0),0) | AB8: 2019-0040
W9: =IF(LEFT($H9&"",5)="2019-",$H9,W8) | X9: =IF($W9="",0,IF(COUNTIF($AB$2:$AB$80,$W9)>0,1,0)) | Y9: =IF($C9="","",UPPER(TRIM(IFERROR(LEFT($C9&"",FIND("/",$C9&"")-1),$C9&"")))) | Z9: =IFERROR(IF(ISNUMBER($G9),$G9,0),0) | AB9: 2019-0042
A10: Through : | W10: =IF(LEFT($H10&"",5)="2019-",$H10,W9) | X10: =IF($W10="",0,IF(COUNTIF($AB$2:$AB$80,$W10)>0,1,0)) | Y10: =IF($C10="","",UPPER(TRIM(IFERROR(LEFT($C10&"",FIND("/",$C10&"")-1),$C10&"")))) | Z10: =IFERROR(IF(ISNUMBER($G10),$G10,0),0) | AB10: 2019-0060
A11: Address line (redacted) | W11: =IF(LEFT($H11&"",5)="2019-",$H11,W10) | X11: =IF($W11="",0,IF(COUNTIF($AB$2:$AB$80,$W11)>0,1,0)) | Y11: =IF($C11="","",UPPER(TRIM(IFERROR(LEFT($C11&"",FIND("/",$C11&"")-1),$C11&"")))) | Z11: =IFERROR(IF(ISNUMBER($G11),$G11,0),0) | AB11: 2019-0064
W12: =IF(LEFT($H12&"",5)="2019-",$H12,W11) | X12: =IF($W12="",0,IF(COUNTIF($AB$2:$AB$80,$W12)>0,1,0)) | Y12: =IF($C12="","",UPPER(TRIM(IFERROR(LEFT($C12&"",FIND("/",$C12&"")-1),$C12&"")))) | Z12: =IFERROR(IF(ISNUMBER($G12),$G12,0),0) | AB12: 2019-0065
A13: Dear Sir, | W13: =IF(LEFT($H13&"",5)="2019-",$H13,W12) | X13: =IF($W13="",0,IF(COUNTIF($AB$2:$AB$80,$W13)>0,1,0)) | Y13: =IF($C13="","",UPPER(TRIM(IFERROR(LEFT($C13&"",FIND("/",$C13&"")-1),$C13&"")))) | Z13: =IFERROR(IF(ISNUMBER($G13),$G13,0),0) | AB13: 2019-0069
A14: According to instructions we are sending followng goods. Please acknowledge the same and after your | W14: =IF(LEFT($H14&"",5)="2019-",$H14,W13) | X14: =IF($W14="",0,IF(COUNTIF($AB$2:$AB$80,$W14)>0,1,0)) | Y14: =IF($C14="","",UPPER(TRIM(IFERROR(LEFT($C14&"",FIND("/",$C14&"")-1),$C14&"")))) | Z14: =IFERROR(IF(ISNUMBER($G14),$G14,0),0) | AB14: 2019-0076
A15: acknowledgement we will issue you sales invoice. | W15: =IF(LEFT($H15&"",5)="2019-",$H15,W14) | X15: =IF($W15="",0,IF(COUNTIF($AB$2:$AB$80,$W15)>0,1,0)) | Y15: =IF($C15="","",UPPER(TRIM(IFERROR(LEFT($C15&"",FIND("/",$C15&"")-1),$C15&"")))) | Z15: =IFERROR(IF(ISNUMBER($G15),$G15,0),0) | AB15: 2019-0078
A16: S.No. | B16: Description | C16: PART NO. | D16: CTN | E16: PCS CTN | F16: QTY | G16: TOTAL QTY | H16: PRICE | I16: AMOUNT | W16: =IF(LEFT($H16&"",5)="2019-",$H16,W15) | X16: =IF($W16="",0,IF(COUNTIF($AB$2:$AB$80,$W16)>0,1,0)) | Y16: =IF($C16="","",UPPER(TRIM(IFERROR(LEFT($C16&"",FIND("/",$C16&"")-1),$C16&"")))) | Z16: =IFERROR(IF(ISNUMBER($G16),$G16,0),0) | AB16: 2019-0105
B17: COMPANY-A CONDENSER | W17: =IF(LEFT($H17&"",5)="2019-",$H17,W16) | X17: =IF($W17="",0,IF(COUNTIF($AB$2:$AB$80,$W17)>0,1,0)) | Y17: =IF($C17="","",UPPER(TRIM(IFERROR(LEFT($C17&"",FIND("/",$C17&"")-1),$C17&"")))) | Z17: =IFERROR(IF(ISNUMBER($G17),$G17,0),0) | AB17: 2019-0106
B18: BEAT (PTL) | C18: PC-86535 | F18: 1 | G18: =+F18 | H18: 1 | I18: =+H18*G18 | W18: =IF(LEFT($H18&"",5)="2019-",$H18,W17) | X18: =IF($W18="",0,IF(COUNTIF($AB$2:$AB$80,$W18)>0,1,0)) | Y18: =IF($C18="","",UPPER(TRIM(IFERROR(LEFT($C18&"",FIND("/",$C18&"")-1),$C18&"")))) | Z18: =IFERROR(IF(ISNUMBER($G18),$G18,0),0) | AB18: 2019-0110
B19: DUSTER NEW DSL 2016 (BEHR-Q5) | C19: PC-86909Q5 | D19: 1 | F19: 2 | G19: =+F19 | H19: 1 | I19: =+H19*G19 | W19: =IF(LEFT($H19&"",5)="2019-",$H19,W18) | X19: =IF($W19="",0,IF(COUNTIF($AB$2:$AB$80,$W19)>0,1,0)) | Y19: =IF($C19="","",UPPER(TRIM(IFERROR(LEFT($C19&"",FIND("/",$C19&"")-1),$C19&"")))) | Z19: =IFERROR(IF(ISNUMBER($G19),$G19,0),0) | AB19: 2019-0120
B20: ENJOY-DSL | C20: PC-86201 | D20: 1 | F20: 2 | G20: =+F20 | H20: 1 | I20: =+H20*G20 | W20: =IF(LEFT($H20&"",5)="2019-",$H20,W19) | X20: =IF($W20="",0,IF(COUNTIF($AB$2:$AB$80,$W20)>0,1,0)) | Y20: =IF($C20="","",UPPER(TRIM(IFERROR(LEFT($C20&"",FIND("/",$C20&"")-1),$C20&"")))) | Z20: =IFERROR(IF(ISNUMBER($G20),$G20,0),0) | AB20: 2019-0121
B21: FLUENCE RENAULT -Q5 | C21: PC-86769BAQ5 | D21: 1 | F21: 2 | G21: =+F21 | H21: 1 | I21: =+H21*G21 | W21: =IF(LEFT($H21&"",5)="2019-",$H21,W20) | X21: =IF($W21="",0,IF(COUNTIF($AB$2:$AB$80,$W21)>0,1,0)) | Y21: =IF($C21="","",UPPER(TRIM(IFERROR(LEFT($C21&"",FIND("/",$C21&"")-1),$C21&"")))) | Z21: =IFERROR(IF(ISNUMBER($G21),$G21,0),0) | AB21: 2019-0124
B22: HONDA AMAZE -DSL-Q5 | C22: PC-86902Q5 | F22: 2 | G22: =+F22 | H22: 1 | I22: =+H22*G22 | W22: =IF(LEFT($H22&"",5)="2019-",$H22,W21) | X22: =IF($W22="",0,IF(COUNTIF($AB$2:$AB$80,$W22)>0,1,0)) | Y22: =IF($C22="","",UPPER(TRIM(IFERROR(LEFT($C22&"",FIND("/",$C22&"")-1),$C22&"")))) | Z22: =IFERROR(IF(ISNUMBER($G22),$G22,0),0) | AB22: 2019-0130
