Workbook

Sheet Recon
B1: Condensers | I1: Cooling Coil | P1: Blowers
B2: Part | D2: Challan (pcs) | E2: Stock Sold | F2: Gap | G2: Total Available | I2: Part | K2: Challan (pcs) | L2: Stock Sold | M2: Gap | N2: Total Available | P2: Part | R2: Challan (pcs) | S2: Stock Sold | T2: Gap | U2: Total Available
B3: INNOVA | C3: PC-86046 | D3: 340 | E3: =IF(AND(B3="",C3=""),"",IF(C3<>"",IF(COUNTIFS(Stock!$D$4:$IP$4,B3,Stock!$D$5:$IP$5,C3)>0,SUMIFS(Stock!$D$340:$IP$340,Stock!$D$4:$IP$4,B3,Stock!$D$5:$IP$5,C3),IF(COUNTIF(Stock!$D$5:$IP$5,C3)>0,SUMIF(Stock!$D$5:$IP$5,C3,Stock!$D$340:$IP$340),SUMIF(Stock!$D$4:$IP$4,B3,Stock!$D$340:$IP$340))),SUMIF(Stock!$D$4:$IP$4,B3,Stock!$D$340:$IP$340))) -> 265 | F3: =D3-E3 -> 75 | G3: =IF(AND(B3="",C3=""),"",IF(C3<>"",IF(COUNTIFS(Stock!$D$4:$IP$4,B3,Stock!$D$5:$IP$5,C3)>0,SUMIFS(Stock!$D$32:$IP$32,Stock!$D$4:$IP$4,B3,Stock!$D$5:$IP$5,C3),IF(COUNTIF(Stock!$D$5:$IP$5,C3)>0,SUMIF(Stock!$D$5:$IP$5,C3,Stock!$D$32:$IP$32),SUMIF(Stock!$D$4:$IP$4,B3,Stock!$D$32:$IP$32))),SUMIF(Stock!$D$4:$IP$4,B3,Stock!$D$32:$IP$32))) -> 360 | I3: A6 | J3: PC-A6 | K3: 602 | L3: =IF(AND(I3="",J3=""),"",IF(J3<>"",IF(COUNTIFS(Stock!$D$4:$IP$4,I3,Stock!$D$5:$IP$5,J3)>0,SUMIFS(Stock!$D$340:$IP$340,Stock!$D$4:$IP$4,I3,Stock!$D$5:$IP$5,J3),IF(COUNTIF(Stock!$D$5:$IP$5,J3)>0,SUMIF(Stock!$D$5:$IP$5,J3,Stock!$D$340:$IP$340),SUMIF(Stock!$D$4:$IP$4,I3,Stock!$D$340:$IP$340))),SUMIF(Stock!$D$4:$IP$4,I3,Stock!$D$340:$IP$340))) -> 250 | M3: =K3-L3 -> 352 | N3: =IF(AND(I3="",J3=""),"",IF(J3<>"",IF(COUNTIFS(Stock!$D$4:$IP$4,I3,Stock!$D$5:$IP$5,J3)>0,SUMIFS(Stock!$D$32:$IP$32,Stock!$D$4:$IP$4,I3,Stock!$D$5:$IP$5,J3),IF(COUNTIF(Stock!$D$5:$IP$5,J3)>0,SUMIF(Stock!$D$5:$IP$5,J3,Stock!$D$32:$IP$32),SUMIF(Stock!$D$4:$IP$4,I3,Stock!$D$32:$IP$32))),SUMIF(Stock!$D$4:$IP$4,I3,Stock!$D$32:$IP$32))) -> 650 | P3: MICROBUS-Tubefin | Q3: MICROBUS | R3: 62 | S3: =IF(AND(P3="",Q3=""),"",IF(Q3<>"",IF(COUNTIFS(Stock!$D$4:$IP$4,P3,Stock!$D$5:$IP$5,Q3)>0,SUMIFS(Stock!$D$340:$IP$340,Stock!$D$4:$IP$4,P3,Stock!$D$5:$IP$5,Q3),IF(COUNTIF(Stock!$D$5:$IP$5,Q3)>0,SUMIF(Stock!$D$5:$IP$5,Q3,Stock!$D$340:$IP$340),SUMIF(Stock!$D$4:$IP$4,P3,Stock!$D$340:$IP$340))),SUMIF(Stock!$D$4:$IP$4,P3,Stock!$D$340:$IP$340))) -> 42 | T3: =R3-S3 -> 20 | U3: =IF(AND(P3="",Q3=""),"",IF(Q3<>"",IF(COUNTIFS(Stock!$D$4:$IP$4,P3,Stock!$D$5:$IP$5,Q3)>0,SUMIFS(Stock!$D$32:$IP$32,Stock!$D$4:$IP$4,P3,Stock!$D$5:$IP$5,Q3),IF(COUNTIF(Stock!$D$5:$IP$5,Q3)>0,SUMIF(Stock!$D$5:$IP$5,Q3,Stock!$D$32:$IP$32),SUMIF(Stock!$D$4:$IP$4,P3,Stock!$D$32:$IP$32))),SUMIF(Stock!$D$4:$IP$4,P3,Stock!$D$32:$IP$32))) -> 62
B4: SKODA | C4: PC-86004 | D4: 85 | E4: =IF(AND(B4="",C4=""),"",IF(C4<>"",IF(COUNTIFS(Stock!$D$4:$IP$4,B4,Stock!$D$5:$IP$5,C4)>0,SUMIFS(Stock!$D$340:$IP$340,Stock!$D$4:$IP$4,B4,Stock!$D$5:$IP$5,C4),IF(COUNTIF(Stock!$D$5:$IP$5,C4)>0,SUMIF(Stock!$D$5:$IP$5,C4,Stock!$D$340:$IP$340),SUMIF(Stock!$D$4:$IP$4,B4,Stock!$D$340:$IP$340))),SUMIF(Stock!$D$4:$IP$4,B4,Stock!$D$340:$IP$340))) -> 45 | F4: =D4-E4 -> 40 | G4: =IF(AND(B4="",C4=""),"",IF(C4<>"",IF(COUNTIFS(Stock!$D$4:$IP$4,B4,Stock!$D$5:$IP$5,C4)>0,SUMIFS(Stock!$D$32:$IP$32,Stock!$D$4:$IP$4,B4,Stock!$D$5:$IP$5,C4),IF(COUNTIF(Stock!$D$5:$IP$5,C4)>0,SUMIF(Stock!$D$5:$IP$5,C4,Stock!$D$32:$IP$32),SUMIF(Stock!$D$4:$IP$4,B4,Stock!$D$32:$IP$32))),SUMIF(Stock!$D$4:$IP$4,B4,Stock!$D$32:$IP$32))) -> 94 | I4: Accent | J4: PC-055R | K4: 50 | L4: =IF(AND(I4="",J4=""),"",IF(J4<>"",IF(COUNTIFS(Stock!$D$4:$IP$4,I4,Stock!$D$5:$IP$5,J4)>0,SUMIFS(Stock!$D$340:$IP$340,Stock!$D$4:$IP$4,I4,Stock!$D$5:$IP$5,J4),IF(COUNTIF(Stock!$D$5:$IP$5,J4)>0,SUMIF(Stock!$D$5:$IP$5,J4,Stock!$D$340:$IP$340),SUMIF(Stock!$D$4:$IP$4,I4,Stock!$D$340:$IP$340))),SUMIF(Stock!$D$4:$IP$4,I4,Stock!$D$340:$IP$340))) -> 50 | M4: =K4-L4 -> 0 | N4: =IF(AND(I4="",J4=""),"",IF(J4<>"",IF(COUNTIFS(Stock!$D$4:$IP$4,I4,Stock!$D$5:$IP$5,J4)>0,SUMIFS(Stock!$D$32:$IP$32,Stock!$D$4:$IP$4,I4,Stock!$D$5:$IP$5,J4),IF(COUNTIF(Stock!$D$5:$IP$5,J4)>0,SUMIF(Stock!$D$5:$IP$5,J4,Stock!$D$32:$IP$32),SUMIF(Stock!$D$4:$IP$4,I4,Stock!$D$32:$IP$32))),SUMIF(Stock!$D$4:$IP$4,I4,Stock!$D$32:$IP$32))) -> 50 | P4: MICROBUS-PF | Q4: PFMICROBUS;PARALLFLOWMICROBUS;MULTIFLOWMICROBUS;848L | R4: 300 | S4: =IF(AND(P4="",Q4=""),"",IF(Q4<>"",IF(COUNTIFS(Stock!$D$4:$IP$4,P4,Stock!$D$5:$IP$5,Q4)>0,SUMIFS(Stock!$D$340:$IP$340,Stock!$D$4:$IP$4,P4,Stock!$D$5:$IP$5,Q4),IF(COUNTIF(Stock!$D$5:$IP$5,Q4)>0,SUMIF(Stock!$D$5:$IP$5,Q4,Stock!$D$340:$IP$340),SUMIF(Stock!$D$4:$IP$4,P4,Stock!$D$340:$IP$340))),SUMIF(Stock!$D$4:$IP$4,P4,Stock!$D$340:$IP$340))) -> 202 | T4: =R4-S4 -> 98 | U4: =IF(AND(P4="",Q4=""),"",IF(Q4<>"",IF(COUNTIFS(Stock!$D$4:$IP$4,P4,Stock!$D$5:$IP$5,Q4)>0,SUMIFS(Stock!$D$32:$IP$32,Stock!$D$4:$IP$4,P4,Stock!$D$5:$IP$5,Q4),IF(COUNTIF(Stock!$D$5:$IP$5,Q4)>0,SUMIF(Stock!$D$5:$IP$5,Q4,Stock!$D$32:$IP$32),SUMIF(Stock!$D$4:$IP$4,P4,Stock!$D$32:$IP$32))),SUMIF(Stock!$D$4:$IP$4,P4,Stock!$D$32:$IP$32))) -> 300
B5: INDICA/BEHR-R134A | C5: PC-86233 | D5: 785 | E5: =IF(AND(B5="",C5=""),"",IF(C5<>"",IF(COUNTIFS(Stock!$D$4:$IP$4,B5,Stock!$D$5:$IP$5,C5)>0,SUMIFS(Stock!$D$340:$IP$340,Stock!$D$4:$IP$4,B5,Stock!$D$5:$IP$5,C5),IF(COUNTIF(Stock!$D$5:$IP$5,C5)>0,SUMIF(Stock!$D$5:$IP$5,C5,Stock!$D$340:$IP$340),SUMIF(Stock!$D$4:$IP$4,B5,Stock!$D$340:$IP$340))),SUMIF(Stock!$D$4:$IP$4,B5,Stock!$D$340:$IP$340))) -> 585 | F5: =D5-E5 -> 200 | G5: =IF(AND(B5="",C5=""),"",IF(C5<>"",IF(COUNTIFS(Stock!$D$4:$IP$4,B5,Stock!$D$5:$IP$5,C5)>0,SUMIFS(Stock!$D$32:$IP$32,Stock!$D$4:$IP$4,B5,Stock!$D$5:$IP$5,C5),IF(COUNTIF(Stock!$D$5:$IP$5,C5)>0,SUMIF(Stock!$D$5:$IP$5,C5,Stock!$D$32:$IP$32),SUMIF(Stock!$D$4:$IP$4,B5,Stock!$D$32:$IP$32))),SUMIF(Stock!$D$4:$IP$4,B5,Stock!$D$32:$IP$32))) -> 785 | I5: ACCORD | J5: PC-510 | K5: 0 | L5: =IF(AND(I5="",J5=""),"",IF(J5<>"",IF(COUNTIFS(Stock!$D$4:$IP$4,I5,Stock!$D$5:$IP$5,J5)>0,SUMIFS(Stock!$D$340:$IP$340,Stock!$D$4:$IP$4,I5,Stock!$D$5:$IP$5,J5),IF(COUNTIF(Stock!$D$5:$IP$5,J5)>0,SUMIF(Stock!$D$5:$IP$5,J5,Stock!$D$340:$IP$340),SUMIF(Stock!$D$4:$IP$4,I5,Stock!$D$340:$IP$340))),SUMIF(Stock!$D$4:$IP$4,I5,Stock!$D$340:$IP$340))) -> 0 | M5: =K5-L5 -> 0 | N5: =IF(AND(I5="",J5=""),"",IF(J5<>"",IF(COUNTIFS(Stock!$D$4:$IP$4,I5,Stock!$D$5:$IP$5,J5)>0,SUMIFS(Stock!$D$32:$IP$32,Stock!$D$4:$IP$4,I5,Stock!$D$5:$IP$5,J5),IF(COUNTIF(Stock!$D$5:$IP$5,J5)>0,SUMIF(Stock!$D$5:$IP$5,J5,Stock!$D$32:$IP$32),SUMIF(Stock!$D$4:$IP$4,I5,Stock!$D$32:$IP$32))),SUMIF(Stock!$D$4:$IP$4,I5,Stock!$D$32:$IP$32))) -> 0 | P5: MiniBus | Q5: MINIBUS | R5: 14 | S5: =IF(AND(P5="",Q5=""),"",IF(Q5<>"",IF(COUNTIFS(Stock!$D$4:$IP$4,P5,Stock!$D$5:$IP$5,Q5)>0,SUMIFS(Stock!$D$340:$IP$340,Stock!$D$4:$IP$4,P5,Stock!$D$5:$IP$5,Q5),IF(COUNTIF(Stock!$D$5:$IP$5,Q5)>0,SUMIF(Stock!$D$5:$IP$5,Q5,Stock!$D$340:$IP$340),SUMIF(Stock!$D$4:$IP$4,P5,Stock!$D$340:$IP$340))),SUMIF(Stock!$D$4:$IP$4,P5,Stock!$D$340:$IP$340))) -> 4 | T5: =R5-S5 -> 10 | U5: =IF(AND(P5="",Q5=""),"",IF(Q5<>"",IF(COUNTIFS(Stock!$D$4:$IP$4,P5,Stock!$D$5:$IP$5,Q5)>0,SUMIFS(Stock!$D$32:$IP$32,Stock!$D$4:$IP$4,P5,Stock!$D$5:$IP$5,Q5),IF(COUNTIF(Stock!$D$5:$IP$5,Q5)>0,SUMIF(Stock!$D$5:$IP$5,Q5,Stock!$D$32:$IP$32),SUMIF(Stock!$D$4:$IP$4,P5,Stock!$D$32:$IP$32))),SUMIF(Stock!$D$4:$IP$4,P5,Stock!$D$32:$IP$32))) -> 80
B6: QUALIS-FLARE | C6: PC-86234 | D6: 95 | E6: =IF(AND(B6="",C6=""),"",IF(C6<>"",IF(COUNTIFS(Stock!$D$4:$IP$4,B6,Stock!$D$5:$IP$5,C6)>0,SUMIFS(Stock!$D$340:$IP$340,Stock!$D$4:$IP$4,B6,Stock!$D$5:$IP$5,C6),IF(COUNTIF(Stock!$D$5:$IP$5,C6)>0,SUMIF(Stock!$D$5:$IP$5,C6,Stock!$D$340:$IP$340),SUMIF(Stock!$D$4:$IP$4,B6,Stock!$D$340:$IP$340))),SUMIF(Stock!$D$4:$IP$4,B6,Stock!$D$340:$IP$340))) -> 50 | F6: =D6-E6 -> 45 | G6: =IF(AND(B6="",C6=""),"",IF(C6<>"",IF(COUNTIFS(Stock!$D$4:$IP$4,B6,Stock!$D$5:$IP$5,C6)>0,SUMIFS(Stock!$D$32:$IP$32,Stock!$D$4:$IP$4,B6,Stock!$D$5:$IP$5,C6),IF(COUNTIF(Stock!$D$5:$IP$5,C6)>0,SUMIF(Stock!$D$5:$IP$5,C6,Stock!$D$32:$IP$32),SUMIF(Stock!$D$4:$IP$4,B6,Stock!$D$32:$IP$32))),SUMIF(Stock!$D$4:$IP$4,B6,Stock!$D$32:$IP$32))) -> 100 | I6: AVEO | J6: PC-614 | K6: 51 | L6: =IF(AND(I6="",J6=""),"",IF(J6<>"",IF(COUNTIFS(Stock!$D$4:$IP$4,I6,Stock!$D$5:$IP$5,J6)>0,SUMIFS(Stock!$D$340:$IP$340,Stock!$D$4:$IP$4,I6,Stock!$D$5:$IP$5,J6),IF(COUNTIF(Stock!$D$5:$IP$5,J6)>0,SUMIF(Stock!$D$5:$IP$5,J6,Stock!$D$340:$IP$340),SUMIF(Stock!$D$4:$IP$4,I6,Stock!$D$340:$IP$340))),SUMIF(Stock!$D$4:$IP$4,I6,Stock!$D$340:$IP$340))) -> 0 | M6: =K6-L6 -> 51 | N6: =IF(AND(I6="",J6=""),"",IF(J6<>"",IF(COUNTIFS(Stock!$D$4:$IP$4,I6,Stock!$D$5:$IP$5,J6)>0,SUMIFS(Stock!$D$32:$IP$32,Stock!$D$4:$IP$4,I6,Stock!$D$5:$IP$5,J6),IF(COUNTIF(Stock!$D$5:$IP$5,J6)>0,SUMIF(Stock!$D$5:$IP$5,J6,Stock!$D$32:$IP$32),SUMIF(Stock!$D$4:$IP$4,I6,Stock!$D$32:$IP$32))),SUMIF(Stock!$D$4:$IP$4,I6,Stock!$D$32:$IP$32))) -> 0 | P6: SK | Q6: SK;SKBLOWER;UNICLASK;UNICLASKBLOWER | R6: 312 | S6: =IF(AND(P6="",Q6=""),"",IF(Q6<>"",IF(COUNTIFS(Stock!$D$4:$IP$4,P6,Stock!$D$5:$IP$5,Q6)>0,SUMIFS(Stock!$D$340:$IP$340,Stock!$D$4:$IP$4,P6,Stock!$D$5:$IP$5,Q6),IF(COUNTIF(Stock!$D$5:$IP$5,Q6)>0,SUMIF(Stock!$D$5:$IP$5,Q6,Stock!$D$340:$IP$340),SUMIF(Stock!$D$4:$IP$4,P6,Stock!$D$340:$IP$340))),SUMIF(Stock!$D$4:$IP$4,P6,Stock!$D$340:$IP$340))) -> 350 | T6: =R6-S6 -> -38 | U6: =IF(AND(P6="",Q6=""),"",IF(Q6<>"",IF(COUNTIFS(Stock!$D$4:$IP$4,P6,Stock!$D$5:$IP$5,Q6)>0,SUMIFS(Stock!$D$32:$IP$32,Stock!$D$4:$IP$4,P6,Stock!$D$5:$IP$5,Q6),IF(COUNTIF(Stock!$D$5:$IP$5,Q6)>0,SUMIF(Stock!$D$5:$IP$5,Q6,Stock!$D$32:$IP$32),SUMIF(Stock!$D$4:$IP$4,P6,Stock!$D$32:$IP$32))),SUMIF(Stock!$D$4:$IP$4,P6,Stock!$D$32:$IP$32))) -> 350
B7: Qualis-PAD | C7: PC-86235 | D7: 205 | E7: =IF(AND(B7="",C7=""),"",IF(C7<>"",IF(COUNTIFS(Stock!$D$4:$IP$4,B7,Stock!$D$5:$IP$5,C7)>0,SUMIFS(Stock!$D$340:$IP$340,Stock!$D$4:$IP$4,B7,Stock!$D$5:$IP$5,C7),IF(COUNTIF(Stock!$D$5:$IP$5,C7)>0,SUMIF(Stock!$D$5:$IP$5,C7,Stock!$D$340:$IP$340),SUMIF(Stock!$D$4:$IP$4,B7,Stock!$D$340:$IP$340))),SUMIF(Stock!$D$4:$IP$4,B7,Stock!$D$340:$IP$340))) -> 155 | F7: =D7-E7 -> 50 | G7: =IF(AND(B7="",C7=""),"",IF(C7<>"",IF(COUNTIFS(Stock!$D$4:$IP$4,B7,Stock!$D$5:$IP$5,C7)>0,SUMIFS(Stock!$D$32:$IP$32,Stock!$D$4:$IP$4,B7,Stock!$D$5:$IP$5,C7),IF(COUNTIF(Stock!$D$5:$IP$5,C7)>0,SUMIF(Stock!$D$5:$IP$5,C7,Stock!$D$32:$IP$32),SUMIF(Stock!$D$4:$IP$4,B7,Stock!$D$32:$IP$32))),SUMIF(Stock!$D$4:$IP$4,B7,Stock!$D$32:$IP$32))) -> 205 | I7: Baleno | J7: PC-142R | K7: 126 | L7: =IF(AND(I7="",J7=""),"",IF(J7<>"",IF(COUNTIFS(Stock!$D$4:$IP$4,I7,Stock!$D$5:$IP$5,J7)>0,SUMIFS(Stock!$D$340:$IP$340,Stock!$D$4:$IP$4,I7,Stock!$D$5:$IP$5,J7),IF(COUNTIF(Stock!$D$5:$IP$5,J7)>0,SUMIF(Stock!$D$5:$IP$5,J7,Stock!$D$340:$IP$340),SUMIF(Stock!$D$4:$IP$4,I7,Stock!$D$340:$IP$340))),SUMIF(Stock!$D$4:$IP$4,I7,Stock!$D$340:$IP$340))) -> 126 | M7: =K7-L7 -> 0 | N7: =IF(AND(I7="",J7=""),"",IF(J7<>"",IF(COUNTIFS(Stock!$D$4:$IP$4,I7,Stock!$D$5:$IP$5,J7)>0,SUMIFS(Stock!$D$32:$IP$32,Stock!$D$4:$IP$4,I7,Stock!$D$5:$IP$5,J7),IF(COUNTIF(Stock!$D$5:$IP$5,J7)>0,SUMIF(Stock!$D$5:$IP$5,J7,Stock!$D$32:$IP$32),SUMIF(Stock!$D$4:$IP$4,I7,Stock!$D$32:$IP$32))),SUMIF(Stock!$D$4:$IP$4,I7,Stock!$D$32:$IP$32))) -> 129 | P7: Concord-Elec, | Q7: CONCORD;UNICLACONCORD;UNICALCONCORD;CONCORDSUPERIOR;CONCORDBEIGE | R7: 597 | S7: =IF(AND(P7="",Q7=""),"",IF(Q7<>"",IF(COUNTIFS(Stock!$D$4:$IP$4,P7,Stock!$D$5:$IP$5,Q7)>0,SUMIFS(Stock!$D$340:$IP$340,Stock!$D$4:$IP$4,P7,Stock!$D$5:$IP$5,Q7),IF(COUNTIF(Stock!$D$5:$IP$5,Q7)>0,SUMIF(Stock!$D$5:$IP$5,Q7,Stock!$D$340:$IP$340),SUMIF(Stock!$D$4:$IP$4,P7,Stock!$D$340:$IP$340))),SUMIF(Stock!$D$4:$IP$4,P7,Stock!$D$340:$IP$340))) -> 577 | T7: =R7-S7 -> 20 | U7: =IF(AND(P7="",Q7=""),"",IF(Q7<>"",IF(COUNTIFS(Stock!$D$4:$IP$4,P7,Stock!$D$5:$IP$5,Q7)>0,SUMIFS(Stock!$D$32:$IP$32,Stock!$D$4:$IP$4,P7,Stock!$D$5:$IP$5,Q7),IF(COUNTIF(Stock!$D$5:$IP$5,Q7)>0,SUMIF(Stock!$D$5:$IP$5,Q7,Stock!$D$32:$IP$32),SUMIF(Stock!$D$4:$IP$4,P7,Stock!$D$32:$IP$32))),SUMIF(Stock!$D$4:$IP$4,P7,Stock!$D$32:$IP$32))) -> 579
B8: Qualis-O Ring | C8: PC-86244 | D8: 100 | E8: =IF(AND(B8="",C8=""),"",IF(C8<>"",IF(COUNTIFS(Stock!$D$4:$IP$4,B8,Stock!$D$5:$IP$5,C8)>0,SUMIFS(Stock!$D$340:$IP$340,Stock!$D$4:$IP$4,B8,Stock!$D$5:$IP$5,C8),IF(COUNTIF(Stock!$D$5:$IP$5,C8)>0,SUMIF(Stock!$D$5:$IP$5,C8,Stock!$D$340:$IP$340),SUMIF(Stock!$D$4:$IP$4,B8,Stock!$D$340:$IP$340))),SUMIF(Stock!$D$4:$IP$4,B8,Stock!$D$340:$IP$340))) -> 100 | F8: =D8-E8 -> 0 | G8: =IF(AND(B8="",C8=""),"",IF(C8<>"",IF(COUNTIFS(Stock!$D$4:$IP$4,B8,Stock!$D$5:$IP$5,C8)>0,SUMIFS(Stock!$D$32:$IP$32,Stock!$D$4:$IP$4,B8,Stock!$D$5:$IP$5,C8),IF(COUNTIF(Stock!$D$5:$IP$5,C8)>0,SUMIF(Stock!$D$5:$IP$5,C8,Stock!$D$32:$IP$32),SUMIF(Stock!$D$4:$IP$4,B8,Stock!$D$32:$IP$32))),SUMIF(Stock!$D$4:$IP$4,B8,Stock!$D$32:$IP$32))) -> 100 | I8: BOlero R134a | J8: PC-8095 | K8: 72 | L8: =IF(AND(I8="",J8=""),"",IF(J8<>"",IF(COUNTIFS(Stock!$D$4:$IP$4,I8,Stock!$D$5:$IP$5,J8)>0,SUMIFS(Stock!$D$340:$IP$340,Stock!$D$4:$IP$4,I8,Stock!$D$5:$IP$5,J8),IF(COUNTIF(Stock!$D$5:$IP$5,J8)>0,SUMIF(Stock!$D$5:$IP$5,J8,Stock!$D$340:$IP$340),SUMIF(Stock!$D$4:$IP$4,I8,Stock!$D$340:$IP$340))),SUMIF(Stock!$D$4:$IP$4,I8,Stock!$D$340:$IP$340))) -> 54 | M8: =K8-L8 -> 18 | N8: =IF(AND(I8="",J8=""),"",IF(J8<>"",IF(COUNTIFS(Stock!$D$4:$IP$4,I8,Stock!$D$5:$IP$5,J8)>0,SUMIFS(Stock!$D$32:$IP$32,Stock!$D$4:$IP$4,I8,Stock!$D$5:$IP$5,J8),IF(COUNTIF(Stock!$D$5:$IP$5,J8)>0,SUMIF(Stock!$D$5:$IP$5,J8,Stock!$D$32:$IP$32),SUMIF(Stock!$D$4:$IP$4,I8,Stock!$D$32:$IP$32))),SUMIF(Stock!$D$4:$IP$4,I8,Stock!$D$32:$IP$32))) -> 84 | P8: Concord-Normal | S8: =IF(AND(P8="",Q8=""),"",IF(Q8<>"",IF(COUNTIFS(Stock!$D$4:$IP$4,P8,Stock!$D$5:$IP$5,Q8)>0,SUMIFS(Stock!$D$340:$IP$340,Stock!$D$4:$IP$4,P8,Stock!$D$5:$IP$5,Q8),IF(COUNTIF(Stock!$D$5:$IP$5,Q8)>0,SUMIF(Stock!$D$5:$IP$5,Q8,Stock!$D$340:$IP$340),SUMIF(Stock!$D$4:$IP$4,P8,Stock!$D$340:$IP$340))),SUMIF(Stock!$D$4:$IP$4,P8,Stock!$D$340:$IP$340))) -> 0 | T8: =R8-S8 -> 0 | U8: =IF(AND(P8="",Q8=""),"",IF(Q8<>"",IF(COUNTIFS(Stock!$D$4:$IP$4,P8,Stock!$D$5:$IP$5,Q8)>0,SUMIFS(Stock!$D$32:$IP$32,Stock!$D$4:$IP$4,P8,Stock!$D$5:$IP$5,Q8),IF(COUNTIF(Stock!$D$5:$IP$5,Q8)>0,SUMIF(Stock!$D$5:$IP$5,Q8,Stock!$D$32:$IP$32),SUMIF(Stock!$D$4:$IP$4,P8,Stock!$D$32:$IP$32))),SUMIF(Stock!$D$4:$IP$4,P8,Stock!$D$32:$IP$32))) -> 0
B9: Ford Ikon | C9: PC-86034 | D9: 125 | E9: =IF(AND(B9="",C9=""),"",IF(C9<>"",IF(COUNTIFS(Stock!$D$4:$IP$4,B9,Stock!$D$5:$IP$5,C9)>0,SUMIFS(Stock!$D$340:$IP$340,Stock!$D$4:$IP$4,B9,Stock!$D$5:$IP$5,C9),IF(COUNTIF(Stock!$D$5:$IP$5,C9)>0,SUMIF(Stock!$D$5:$IP$5,C9,Stock!$D$340:$IP$340),SUMIF(Stock!$D$4:$IP$4,B9,Stock!$D$340:$IP$340))),SUMIF(Stock!$D$4:$IP$4,B9,Stock!$D$340:$IP$340))) -> 85 | F9: =D9-E9 -> 40 | G9: =IF(AND(B9="",C9=""),"",IF(C9<>"",IF(COUNTIFS(Stock!$D$4:$IP$4,B9,Stock!$D$5:$IP$5,C9)>0,SUMIFS(Stock!$D$32:$IP$32,Stock!$D$4:$IP$4,B9,Stock!$D$5:$IP$5,C9),IF(COUNTIF(Stock!$D$5:$IP$5,C9)>0,SUMIF(Stock!$D$5:$IP$5,C9,Stock!$D$32:$IP$32),SUMIF(Stock!$D$4:$IP$4,B9,Stock!$D$32:$IP$32))),SUMIF(Stock!$D$4:$IP$4,B9,Stock!$D$32:$IP$32))) -> 135 | I9: CAMERY | J9: PC-533 | L9: =IF(AND(I9="",J9=""),"",IF(J9<>"",IF(COUNTIFS(Stock!$D$4:$IP$4,I9,Stock!$D$5:$IP$5,J9)>0,SUMIFS(Stock!$D$340:$IP$340,Stock!$D$4:$IP$4,I9,Stock!$D$5:$IP$5,J9),IF(COUNTIF(Stock!$D$5:$IP$5,J9)>0,SUMIF(Stock!$D$5:$IP$5,J9,Stock!$D$340:$IP$340),SUMIF(Stock!$D$4:$IP$4,I9,Stock!$D$340:$IP$340))),SUMIF(Stock!$D$4:$IP$4,I9,Stock!$D$340:$IP$340))) -> 0 | M9: =K9-L9 -> 0 | N9: =IF(AND(I9="",J9=""),"",IF(J9<>"",IF(COUNTIFS(Stock!$D$4:$IP$4,I9,Stock!$D$5:$IP$5,J9)>0,SUMIFS(Stock!$D$32:$IP$32,Stock!$D$4:$IP$4,I9,Stock!$D$5:$IP$5,J9),IF(COUNTIF(Stock!$D$5:$IP$5,J9)>0,SUMIF(Stock!$D$5:$IP$5,J9,Stock!$D$32:$IP$32),SUMIF(Stock!$D$4:$IP$4,I9,Stock!$D$32:$IP$32))),SUMIF(Stock!$D$4:$IP$4,I9,Stock!$D$32:$IP$32))) -> 0 | P9: 405 | Q9: 405;405SUPERKING;SUPERKING;SK405;FSK405;405BLOWER;F405SUPERKINGBLOWER;BLOWERSUPERKING;FORMULA405SUPERKINGBLOWER;FSUPERKING405 | R9: 10 | S9: =IF(AND(P9="",Q9=""),"",IF(Q9<>"",IF(COUNTIFS(Stock!$D$4:$IP$4,P9,Stock!$D$5:$IP$5,Q9)>0,SUMIFS(Stock!$D$340:$IP$340,Stock!$D$4:$IP$4,P9,Stock!$D$5:$IP$5,Q9),IF(COUNTIF(Stock!$D$5:$IP$5,Q9)>0,SUMIF(Stock!$D$5:$IP$5,Q9,Stock!$D$340:$IP$340),SUMIF(Stock!$D$4:$IP$4,P9,Stock!$D$340:$IP$340))),SUMIF(Stock!$D$4:$IP$4,P9,Stock!$D$340:$IP$340))) -> 151 | T9: =R9-S9 -> -141 | U9: =IF(AND(P9="",Q9=""),"",IF(Q9<>"",IF(COUNTIFS(Stock!$D$4:$IP$4,P9,Stock!$D$5:$IP$5,Q9)>0,SUMIFS(Stock!$D$32:$IP$32,Stock!$D$4:$IP$4,P9,Stock!$D$5:$IP$5,Q9),IF(COUNTIF(Stock!$D$5:$IP$5,Q9)>0,SUMIF(Stock!$D$5:$IP$5,Q9,Stock!$D$32:$IP$32),SUMIF(Stock!$D$4:$IP$4,P9,Stock!$D$32:$IP$32))),SUMIF(Stock!$D$4:$IP$4,P9,Stock!$D$32:$IP$32))) -> 151
B10: BOLERO- R134A | C10: PC-86236 | D10: 95 | E10: =IF(AND(B10="",C10=""),"",IF(C10<>"",IF(COUNTIFS(Stock!$D$4:$IP$4,B10,Stock!$D$5:$IP$5,C10)>0,SUMIFS(Stock!$D$340:$IP$340,Stock!$D$4:$IP$4,B10,Stock!$D$5:$IP$5,C10),IF(COUNTIF(Stock!$D$5:$IP$5,C10)>0,SUMIF(Stock!$D$5:$IP$5,C10,Stock!$D$340:$IP$340),SUMIF(Stock!$D$4:$IP$4,B10,Stock!$D$340:$IP$340))),SUMIF(Stock!$D$4:$IP$4,B10,Stock!$D$340:$IP$340))) -> 80 | F10: =D10-E10 -> 15 | G10: =IF(AND(B10="",C10=""),"",IF(C10<>"",IF(COUNTIFS(Stock!$D$4:$IP$4,B10,Stock!$D$5:$IP$5,C10)>0,SUMIFS(Stock!$D$32:$IP$32,Stock!$D$4:$IP$4,B10,Stock!$D$5:$IP$5,C10),IF(COUNTIF(Stock!$D$5:$IP$5,C10)>0,SUMIF(Stock!$D$5:$IP$5,C10,Stock!$D$32:$IP$32),SUMIF(Stock!$D$4:$IP$4,B10,Stock!$D$32:$IP$32))),SUMIF(Stock!$D$4:$IP$4,B10,Stock!$D$32:$IP$32))) -> 80 | I10: Cielo | J10: PC-043R | K10: 25 | L10: =IF(AND(I10="",J10=""),"",IF(J10<>"",IF(COUNTIFS(Stock!$D$4:$IP$4,I10,Stock!$D$5:$IP$5,J10)>0,SUMIFS(Stock!$D$340:$IP$340,Stock!$D$4:$IP$4,I10,Stock!$D$5:$IP$5,J10),IF(COUNTIF(Stock!$D$5:$IP$5,J10)>0,SUMIF(Stock!$D$5:$IP$5,J10,Stock!$D$340:$IP$340),SUMIF(Stock!$D$4:$IP$4,I10,Stock!$D$340:$IP$340))),SUMIF(Stock!$D$4:$IP$4,I10,Stock!$D$340:$IP$340))) -> 25 | M10: =K10-L10 -> 0 | N10: =IF(AND(I10="",J10=""),"",IF(J10<>"",IF(COUNTIFS(Stock!$D$4:$IP$4,I10,Stock!$D$5:$IP$5,J10)>0,SUMIFS(Stock!$D$32:$IP$32,Stock!$D$4:$IP$4,I10,Stock!$D$5:$IP$5,J10),IF(COUNTIF(Stock!$D$5:$IP$5,J10)>0,SUMIF(Stock!$D$5:$IP$5,J10,Stock!$D$32:$IP$32),SUMIF(Stock!$D$4:$IP$4,I10,Stock!$D$32:$IP$32))),SUMIF(Stock!$D$4:$IP$4,I10,Stock!$D$32:$IP$32))) -> 25 | P10: 404 | Q10: 404;404BLOWER;BAZEL404;F404BAZEL;F404BAZELBLOWER;BAZELBLOWER404 | R10: 285 | S10: =IF(AND(P10="",Q10=""),"",IF(Q10<>"",IF(COUNTIFS(Stock!$D$4:$IP$4,P10,Stock!$D$5:$IP$5,Q10)>0,SUMIFS(Stock!$D$340:$IP$340,Stock!$D$4:$IP$4,P10,Stock!$D$5:$IP$5,Q10),IF(COUNTIF(Stock!$D$5:$IP$5,Q10)>0,SUMIF(Stock!$D$5:$IP$5,Q10,Stock!$D$340:$IP$340),SUMIF(Stock!$D$4:$IP$4,P10,Stock!$D$340:$IP$340))),SUMIF(Stock!$D$4:$IP$4,P10,Stock!$D$340:$IP$340))) -> 150 | T10: =R10-S10 -> 135 | U10: =IF(AND(P10="",Q10=""),"",IF(Q10<>"",IF(COUNTIFS(Stock!$D$4:$IP$4,P10,Stock!$D$5:$IP$5,Q10)>0,SUMIFS(Stock!$D$32:$IP$32,Stock!$D$4:$IP$4,P10,Stock!$D$5:$IP$5,Q10),IF(COUNTIF(Stock!$D$5:$IP$5,Q10)>0,SUMIF(Stock!$D$5:$IP$5,Q10,Stock!$D$32:$IP$32),SUMIF(Stock!$D$4:$IP$4,P10,Stock!$D$32:$IP$32))),SUMIF(Stock!$D$4:$IP$4,P10,Stock!$D$32:$IP$32))) -> 609
B11: Indigo | C11: PC-86237 | D11: 200 | E11: =IF(AND(B11="",C11=""),"",IF(C11<>"",IF(COUNTIFS(Stock!$D$4:$IP$4,B11,Stock!$D$5:$IP$5,C11)>0,SUMIFS(Stock!$D$340:$IP$340,Stock!$D$4:$IP$4,B11,Stock!$D$5:$IP$5,C11),IF(COUNTIF(Stock!$D$5:$IP$5,C11)>0,SUMIF(Stock!$D$5:$IP$5,C11,Stock!$D$340:$IP$340),SUMIF(Stock!$D$4:$IP$4,B11,Stock!$D$340:$IP$340))),SUMIF(Stock!$D$4:$IP$4,B11,Stock!$D$340:$IP$340))) -> 100 | F11: =D11-E11 -> 100 | G11: =IF(AND(B11="",C11=""),"",IF(C11<>"",IF(COUNTIFS(Stock!$D$4:$IP$4,B11,Stock!$D$5:$IP$5,C11)>0,SUMIFS(Stock!$D$32:$IP$32,Stock!$D$4:$IP$4,B11,Stock!$D$5:$IP$5,C11),IF(COUNTIF(Stock!$D$5:$IP$5,C11)>0,SUMIF(Stock!$D$5:$IP$5,C11,Stock!$D$32:$IP$32),SUMIF(Stock!$D$4:$IP$4,B11,Stock!$D$32:$IP$32))),SUMIF(Stock!$D$4:$IP$4,B11,Stock!$D$32:$IP$32))) -> 200 | I11: CIVIC | J11: PC-523 | L11: =IF(AND(I11="",J11=""),"",IF(J11<>"",IF(COUNTIFS(Stock!$D$4:$IP$4,I11,Stock!$D$5:$IP$5,J11)>0,SUMIFS(Stock!$D$340:$IP$340,Stock!$D$4:$IP$4,I11,Stock!$D$5:$IP$5,J11),IF(COUNTIF(Stock!$D$5:$IP$5,J11)>0,SUMIF(Stock!$D$5:$IP$5,J11,Stock!$D$340:$IP$340),SUMIF(Stock!$D$4:$IP$4,I11,Stock!$D$340:$IP$340))),SUMIF(Stock!$D$4:$IP$4,I11,Stock!$D$340:$IP$340))) -> 0 | M11: =K11-L11 -> 0 | N11: =IF(AND(I11="",J11=""),"",IF(J11<>"",IF(COUNTIFS(Stock!$D$4:$IP$4,I11,Stock!$D$5:$IP$5,J11)>0,SUMIFS(Stock!$D$32:$IP$32,Stock!$D$4:$IP$4,I11,Stock!$D$5:$IP$5,J11),IF(COUNTIF(Stock!$D$5:$IP$5,J11)>0,SUMIF(Stock!$D$5:$IP$5,J11,Stock!$D$32:$IP$32),SUMIF(Stock!$D$4:$IP$4,I11,Stock!$D$32:$IP$32))),SUMIF(Stock!$D$4:$IP$4,I11,Stock!$D$32:$IP$32))) -> 0 | P11: CONCORD WHEEL | Q11: CONCORDWHEEL | R11: 99 | S11: =IF(AND(P11="",Q11=""),"",IF(Q11<>"",IF(COUNTIFS(Stock!$D$4:$IP$4,P11,Stock!$D$5:$IP$5,Q11)>0,SUMIFS(Stock!$D$340:$IP$340,Stock!$D$4:$IP$4,P11,Stock!$D$5:$IP$5,Q11),IF(COUNTIF(Stock!$D$5:$IP$5,Q11)>0,SUMIF(Stock!$D$5:$IP$5,Q11,Stock!$D$340:$IP$340),SUMIF(Stock!$D$4:$IP$4,P11,Stock!$D$340:$IP$340))),SUMIF(Stock!$D$4:$IP$4,P11,Stock!$D$340:$IP$340))) -> 0 | T11: =R11-S11 -> 99 | U11: =IF(AND(P11="",Q11=""),"",IF(Q11<>"",IF(COUNTIFS(Stock!$D$4:$IP$4,P11,Stock!$D$5:$IP$5,Q11)>0,SUMIFS(Stock!$D$32:$IP$32,Stock!$D$4:$IP$4,P11,Stock!$D$5:$IP$5,Q11),IF(COUNTIF(Stock!$D$5:$IP$5,Q11)>0,SUMIF(Stock!$D$5:$IP$5,Q11,Stock!$D$32:$IP$32),SUMIF(Stock!$D$4:$IP$4,P11,Stock!$D$32:$IP$32))),SUMIF(Stock!$D$4:$IP$4,P11,Stock!$D$32:$IP$32))) -> 100
B12: SAFARI | C12: PC-86238 | D12: 100 | E12: =IF(AND(B12="",C12=""),"",IF(C12<>"",IF(COUNTIFS(Stock!$D$4:$IP$4,B12,Stock!$D$5:$IP$5,C12)>0,SUMIFS(Stock!$D$340:$IP$340,Stock!$D$4:$IP$4,B12,Stock!$D$5:$IP$5,C12),IF(COUNTIF(Stock!$D$5:$IP$5,C12)>0,SUMIF(Stock!$D$5:$IP$5,C12,Stock!$D$340:$IP$340),SUMIF(Stock!$D$4:$IP$4,B12,Stock!$D$340:$IP$340))),SUMIF(Stock!$D$4:$IP$4,B12,Stock!$D$340:$IP$340))) -> 100 | F12: =D12-E12 -> 0 | G12: =IF(AND(B12="",C12=""),"",IF(C12<>"",IF(COUNTIFS(Stock!$D$4:$IP$4,B12,Stock!$D$5:$IP$5,C12)>0,SUMIFS(Stock!$D$32:$IP$32,Stock!$D$4:$IP$4,B12,Stock!$D$5:$IP$5,C12),IF(COUNTIF(Stock!$D$5:$IP$5,C12)>0,SUMIF(Stock!$D$5:$IP$5,C12,Stock!$D$32:$IP$32),SUMIF(Stock!$D$4:$IP$4,B12,Stock!$D$32:$IP$32))),SUMIF(Stock!$D$4:$IP$4,B12,Stock!$D$32:$IP$32))) -> 100 | I12: CITY | L12: =IF(AND(I12="",J12=""),"",IF(J12<>"",IF(COUNTIFS(Stock!$D$4:$IP$4,I12,Stock!$D$5:$IP$5,J12)>0,SUMIFS(Stock!$D$340:$IP$340,Stock!$D$4:$IP$4,I12,Stock!$D$5:$IP$5,J12),IF(COUNTIF(Stock!$D$5:$IP$5,J12)>0,SUMIF(Stock!$D$5:$IP$5,J12,Stock!$D$340:$IP$340),SUMIF(Stock!$D$4:$IP$4,I12,Stock!$D$340:$IP$340))),SUMIF(Stock!$D$4:$IP$4,I12,Stock!$D$340:$IP$340))) -> 0 | M12: =K12-L12 -> 0 | N12: =IF(AND(I12="",J12=""),"",IF(J12<>"",IF(COUNTIFS(Stock!$D$4:$IP$4,I12,Stock!$D$5:$IP$5,J12)>0,SUMIFS(Stock!$D$32:$IP$32,Stock!$D$4:$IP$4,I12,Stock!$D$5:$IP$5,J12),IF(COUNTIF(Stock!$D$5:$IP$5,J12)>0,SUMIF(Stock!$D$5:$IP$5,J12,Stock!$D$32:$IP$32),SUMIF(Stock!$D$4:$IP$4,I12,Stock!$D$32:$IP$32))),SUMIF(Stock!$D$4:$IP$4,I12,Stock!$D$32:$IP$32))) -> 0 | P12: CONCORD MOTOR | Q12: CONCORDMOTOR | R12: 35 | S12: =IF(AND(P12="",Q12=""),"",IF(Q12<>"",IF(COUNTIFS(Stock!$D$4:$IP$4,P12,Stock!$D$5:$IP$5,Q12)>0,SUMIFS(Stock!$D$340:$IP$340,Stock!$D$4:$IP$4,P12,Stock!$D$5:$IP$5,Q12),IF(COUNTIF(Stock!$D$5:$IP$5,Q12)>0,SUMIF(Stock!$D$5:$IP$5,Q12,Stock!$D$340:$IP$340),SUMIF(Stock!$D$4:$IP$4,P12,Stock!$D$340:$IP$340))),SUMIF(Stock!$D$4:$IP$4,P12,Stock!$D$340:$IP$340))) -> 0 | T12: =R12-S12 -> 35 | U12: =IF(AND(P12="",Q12=""),"",IF(Q12<>"",IF(COUNTIFS(Stock!$D$4:$IP$4,P12,Stock!$D$5:$IP$5,Q12)>0,SUMIFS(Stock!$D$32:$IP$32,Stock!$D$4:$IP$4,P12,Stock!$D$5:$IP$5,Q12),IF(COUNTIF(Stock!$D$5:$IP$5,Q12)>0,SUMIF(Stock!$D$5:$IP$5,Q12,Stock!$D$32:$IP$32),SUMIF(Stock!$D$4:$IP$4,P12,Stock!$D$32:$IP$32))),SUMIF(Stock!$D$4:$IP$4,P12,Stock!$D$32:$IP$32))) -> 50
B13: Santro-ZING | C13: PC-86239 | D13: 185 | E13: =IF(AND(B13="",C13=""),"",IF(C13<>"",IF(COUNTIFS(Stock!$D$4:$IP$4,B13,Stock!$D$5:$IP$5,C13)>0,SUMIFS(Stock!$D$340:$IP$340,Stock!$D$4:$IP$4,B13,Stock!$D$5:$IP$5,C13),IF(COUNTIF(Stock!$D$5:$IP$5,C13)>0,SUMIF(Stock!$D$5:$IP$5,C13,Stock!$D$340:$IP$340),SUMIF(Stock!$D$4:$IP$4,B13,Stock!$D$340:$IP$340))),SUMIF(Stock!$D$4:$IP$4,B13,Stock!$D$340:$IP$340))) -> 200 | F13: =D13-E13 -> -15 | G13: =IF(AND(B13="",C13=""),"",IF(C13<>"",IF(COUNTIFS(Stock!$D$4:$IP$4,B13,Stock!$D$5:$IP$5,C13)>0,SUMIFS(Stock!$D$32:$IP$32,Stock!$D$4:$IP$4,B13,Stock!$D$5:$IP$5,C13),IF(COUNTIF(Stock!$D$5:$IP$5,C13)>0,SUMIF(Stock!$D$5:$IP$5,C13,Stock!$D$32:$IP$32),SUMIF(Stock!$D$4:$IP$4,B13,Stock!$D$32:$IP$32))),SUMIF(Stock!$D$4:$IP$4,B13,Stock!$D$32:$IP$32))) -> 200 | I13: Corrolla | J13: PC-114R | K13: 44 | L13: =IF(AND(I13="",J13=""),"",IF(J13<>"",IF(COUNTIFS(Stock!$D$4:$IP$4,I13,Stock!$D$5:$IP$5,J13)>0,SUMIFS(Stock!$D$340:$IP$340,Stock!$D$4:$IP$4,I13,Stock!$D$5:$IP$5,J13),IF(COUNTIF(Stock!$D$5:$IP$5,J13)>0,SUMIF(Stock!$D$5:$IP$5,J13,Stock!$D$340:$IP$340),SUMIF(Stock!$D$4:$IP$4,I13,Stock!$D$340:$IP$340))),SUMIF(Stock!$D$4:$IP$4,I13,Stock!$D$340:$IP$340))) -> 48 | M13: =K13-L13 -> -4 | N13: =IF(AND(I13="",J13=""),"",IF(J13<>"",IF(COUNTIFS(Stock!$D$4:$IP$4,I13,Stock!$D$5:$IP$5,J13)>0,SUMIFS(Stock!$D$32:$IP$32,Stock!$D$4:$IP$4,I13,Stock!$D$5:$IP$5,J13),IF(COUNTIF(Stock!$D$5:$IP$5,J13)>0,SUMIF(Stock!$D$5:$IP$5,J13,Stock!$D$32:$IP$32),SUMIF(Stock!$D$4:$IP$4,I13,Stock!$D$32:$IP$32))),SUMIF(Stock!$D$4:$IP$4,I13,Stock!$D$32:$IP$32))) -> 50 | P13: Switches | R13: Challan (pcs) <=283 | S13: =IF(AND(P13="",Q13=""),"",IF(Q13<>"",IF(COUNTIFS(Stock!$D$4:$IP$4,P13,Stock!$D$5:$IP$5,Q13)>0,SUMIFS(Stock!$D$340:$IP$340,Stock!$D$4:$IP$4,P13,Stock!$D$5:$IP$5,Q13),IF(COUNTIF(Stock!$D$5:$IP$5,Q13)>0,SUMIF(Stock!$D$5:$IP$5,Q13,Stock!$D$340:$IP$340),SUMIF(Stock!$D$4:$IP$4,P13,Stock!$D$340:$IP$340))),SUMIF(Stock!$D$4:$IP$4,P13,Stock!$D$340:$IP$340))) -> 0 | T13: Gap | U13: =IF(AND(P13="",Q13=""),"",IF(Q13<>"",IF(COUNTIFS(Stock!$D$4:$IP$4,P13,Stock!$D$5:$IP$5,Q13)>0,SUMIFS(Stock!$D$32:$IP$32,Stock!$D$4:$IP$4,P13,Stock!$D$5:$IP$5,Q13),IF(COUNTIF(Stock!$D$5:$IP$5,Q13)>0,SUMIF(Stock!$D$5:$IP$5,Q13,Stock!$D$32:$IP$32),SUMIF(Stock!$D$4:$IP$4,P13,Stock!$D$32:$IP$32))),SUMIF(Stock!$D$4:$IP$4,P13,Stock!$D$32:$IP$32))) -> 0 | V13: Match Key(s) | W13: Stock col idx | X13: Guard
B14: Maruti Car-800 MPFI | C14: PC-86092 | D14: 400 | E14: =IF(AND(B14="",C14=""),"",IF(C14<>"",IF(COUNTIFS(Stock!$D$4:$IP$4,B14,Stock!$D$5:$IP$5,C14)>0,SUMIFS(Stock!$D$340:$IP$340,Stock!$D$4:$IP$4,B14,Stock!$D$5:$IP$5,C14),IF(COUNTIF(Stock!$D$5:$IP$5,C14)>0,SUMIF(Stock!$D$5:$IP$5,C14,Stock!$D$340:$IP$340),SUMIF(Stock!$D$4:$IP$4,B14,Stock!$D$340:$IP$340))),SUMIF(Stock!$D$4:$IP$4,B14,Stock!$D$340:$IP$340))) -> 405 | F14: =D14-E14 -> -5 | G14: =IF(AND(B14="",C14=""),"",IF(C14<>"",IF(COUNTIFS(Stock!$D$4:$IP$4,B14,Stock!$D$5:$IP$5,C14)>0,SUMIFS(Stock!$D$32:$IP$32,Stock!$D$4:$IP$4,B14,Stock!$D$5:$IP$5,C14),IF(COUNTIF(Stock!$D$5:$IP$5,C14)>0,SUMIF(Stock!$D$5:$IP$5,C14,Stock!$D$32:$IP$32),SUMIF(Stock!$D$4:$IP$4,B14,Stock!$D$32:$IP$32))),SUMIF(Stock!$D$4:$IP$4,B14,Stock!$D$32:$IP$32))) -> 405 | I14: Esteem R-12 | J14: PC-036R12 | K14: 232 | L14: =IF(AND(I14="",J14=""),"",IF(J14<>"",IF(COUNTIFS(Stock!$D$4:$IP$4,I14,Stock!$D$5:$IP$5,J14)>0,SUMIFS(Stock!$D$340:$IP$340,Stock!$D$4:$IP$4,I14,Stock!$D$5:$IP$5,J14),IF(COUNTIF(Stock!$D$5:$IP$5,J14)>0,SUMIF(Stock!$D$5:$IP$5,J14,Stock!$D$340:$IP$340),SUMIF(Stock!$D$4:$IP$4,I14,Stock!$D$340:$IP$340))),SUMIF(Stock!$D$4:$IP$4,I14,Stock!$D$340:$IP$340))) -> 100 | M14: =K14-L14 -> 132 | N14: =IF(AND(I14="",J14=""),"",IF(J14<>"",IF(COUNTIFS(Stock!$D$4:$IP$4,I14,Stock!$D$5:$IP$5,J14)>0,SUMIFS(Stock!$D$32:$IP$32,Stock!$D$4:$IP$4,I14,Stock!$D$5:$IP$5,J14),IF(COUNTIF(Stock!$D$5:$IP$5,J14)>0,SUMIF(Stock!$D$5:$IP$5,J14,Stock!$D$32:$IP$32),SUMIF(Stock!$D$4:$IP$4,I14,Stock!$D$32:$IP$32))),SUMIF(Stock!$D$4:$IP$4,I14,Stock!$D$32:$IP$32))) -> 304 | P14: Santro-3 Speed | R14: 500 | S14: =IF(AND(P14="",Q14=""),"",IF(Q14<>"",IF(COUNTIFS(Stock!$D$4:$IP$4,P14,Stock!$D$5:$IP$5,Q14)>0,SUMIFS(Stock!$D$340:$IP$340,Stock!$D$4:$IP$4,P14,Stock!$D$5:$IP$5,Q14),IF(COUNTIF(Stock!$D$5:$IP$5,Q14)>0,SUMIF(Stock!$D$5:$IP$5,Q14,Stock!$D$340:$IP$340),SUMIF(Stock!$D$4:$IP$4,P14,Stock!$D$340:$IP$340))),SUMIF(Stock!$D$4:$IP$4,P14,Stock!$D$340:$IP$340))) -> 300 | T14: =R14-S14 -> 200 | U14: =IF(AND(P14="",Q14=""),"",IF(Q14<>"",IF(COUNTIFS(Stock!$D$4:$IP$4,P14,Stock!$D$5:$IP$5,Q14)>0,SUMIFS(Stock!$D$32:$IP$32,Stock!$D$4:$IP$4,P14,Stock!$D$5:$IP$5,Q14),IF(COUNTIF(Stock!$D$5:$IP$5,Q14)>0,SUMIF(Stock!$D$5:$IP$5,Q14,Stock!$D$32:$IP$32),SUMIF(Stock!$D$4:$IP$4,P14,Stock!$D$32:$IP$32))),SUMIF(Stock!$D$4:$IP$4,P14,Stock!$D$32:$IP$32))) -> 1799 | V14: 3SPEEDACSANTROSWITCH;SANTROACSWITCH | X14: {=IF(NOT(ISNUMBER($W14)),"CHECK",IF(OR(AND(TRIM($Q14&"")<>"",INDEX(Stock!$EW$5:$FU$5,$W14)=$Q14),INDEX(Stock!$EW$4:$FU$4,$W14)=$P14),"OK","CHECK"))} -> CHECK
B15: SANTRO | C15: PC-86125 | D15: 375 | E15: =IF(AND(B15="",C15=""),"",IF(C15<>"",IF(COUNTIFS(Stock!$D$4:$IP$4,B15,Stock!$D$5:$IP$5,C15)>0,SUMIFS(Stock!$D$340:$IP$340,Stock!$D$4:$IP$4,B15,Stock!$D$5:$IP$5,C15),IF(COUNTIF(Stock!$D$5:$IP$5,C15)>0,SUMIF(Stock!$D$5:$IP$5,C15,Stock!$D$340:$IP$340),SUMIF(Stock!$D$4:$IP$4,B15,Stock!$D$340:$IP$340))),SUMIF(Stock!$D$4:$IP$4,B15,Stock!$D$340:$IP$340))) -> 175 | F15: =D15-E15 -> 200 | G15: =IF(AND(B15="",C15=""),"",IF(C15<>"",IF(COUNTIFS(Stock!$D$4:$IP$4,B15,Stock!$D$5:$IP$5,C15)>0,SUMIFS(Stock!$D$32:$IP$32,Stock!$D$4:$IP$4,B15,Stock!$D$5:$IP$5,C15),IF(COUNTIF(Stock!$D$5:$IP$5,C15)>0,SUMIF(Stock!$D$5:$IP$5,C15,Stock!$D$32:$IP$32),SUMIF(Stock!$D$4:$IP$4,B15,Stock!$D$32:$IP$32))),SUMIF(Stock!$D$4:$IP$4,B15,Stock!$D$32:$IP$32))) -> 375 | I15: Esteem R-134a | J15: PC-036R-134 | K15: 131 | L15: =IF(AND(I15="",J15=""),"",IF(J15<>"",IF(COUNTIFS(Stock!$D$4:$IP$4,I15,Stock!$D$5:$IP$5,J15)>0,SUMIFS(Stock!$D$340:$IP$340,Stock!$D$4:$IP$4,I15,Stock!$D$5:$IP$5,J15),IF(COUNTIF(Stock!$D$5:$IP$5,J15)>0,SUMIF(Stock!$D$5:$IP$5,J15,Stock!$D$340:$IP$340),SUMIF(Stock!$D$4:$IP$4,I15,Stock!$D$340:$IP$340))),SUMIF(Stock!$D$4:$IP$4,I15,Stock!$D$340:$IP$340))) -> 104 | M15: =K15-L15 -> 27 | N15: =IF(AND(I15="",J15=""),"",IF(J15<>"",IF(COUNTIFS(Stock!$D$4:$IP$4,I15,Stock!$D$5:$IP$5,J15)>0,SUMIFS(Stock!$D$32:$IP$32,Stock!$D$4:$IP$4,I15,Stock!$D$5:$IP$5,J15),IF(COUNTIF(Stock!$D$5:$IP$5,J15)>0,SUMIF(Stock!$D$5:$IP$5,J15,Stock!$D$32:$IP$32),SUMIF(Stock!$D$4:$IP$4,I15,Stock!$D$32:$IP$32))),SUMIF(Stock!$D$4:$IP$4,I15,Stock!$D$32:$IP$32))) -> 206 | P15: Santro-4 Speed | R15: 500 | S15: =IF(AND(P15="",Q15=""),"",IF(Q15<>"",IF(COUNTIFS(Stock!$D$4:$IP$4,P15,Stock!$D$5:$IP$5,Q15)>0,SUMIFS(Stock!$D$340:$IP$340,Stock!$D$4:$IP$4,P15,Stock!$D$5:$IP$5,Q15),IF(COUNTIF(Stock!$D$5:$IP$5,Q15)>0,SUMIF(Stock!$D$5:$IP$5,Q15,Stock!$D$340:$IP$340),SUMIF(Stock!$D$4:$IP$4,P15,Stock!$D$340:$IP$340))),SUMIF(Stock!$D$4:$IP$4,P15,Stock!$D$340:$IP$340))) -> 400 | T15: =R15-S15 -> 100 | U15: =IF(AND(P15="",Q15=""),"",IF(Q15<>"",IF(COUNTIFS(Stock!$D$4:$IP$4,P15,Stock!$D$5:$IP$5,Q15)>0,SUMIFS(Stock!$D$32:$IP$32,Stock!$D$4:$IP$4,P15,Stock!$D$5:$IP$5,Q15),IF(COUNTIF(Stock!$D$5:$IP$5,Q15)>0,SUMIF(Stock!$D$5:$IP$5,Q15,Stock!$D$32:$IP$32),SUMIF(Stock!$D$4:$IP$4,P15,Stock!$D$32:$IP$32))),SUMIF(Stock!$D$4:$IP$4,P15,Stock!$D$32:$IP$32))) -> 2149 | V15: TOKAISANTROXINGACSWITCH;SANTROXINGACSWITCH;SANTROXING | X15: {=IF(NOT(ISNUMBER($W15)),"CHECK",IF(OR(AND(TRIM($Q15&"")<>"",INDEX(Stock!$EW$5:$FU$5,$W15)=$Q15),INDEX(Stock!$EW$4:$FU$4,$W15)=$P15),"OK","CHECK"))} -> CHECK
B16: Honda City-TYPE-3 | C16: PC-86240 | D16: 134 | E16: =IF(AND(B16="",C16=""),"",IF(C16<>"",IF(COUNTIFS(Stock!$D$4:$IP$4,B16,Stock!$D$5:$IP$5,C16)>0,SUMIFS(Stock!$D$340:$IP$340,Stock!$D$4:$IP$4,B16,Stock!$D$5:$IP$5,C16),IF(COUNTIF(Stock!$D$5:$IP$5,C16)>0,SUMIF(Stock!$D$5:$IP$5,C16,Stock!$D$340:$IP$340),SUMIF(Stock!$D$4:$IP$4,B16,Stock!$D$340:$IP$340))),SUMIF(Stock!$D$4:$IP$4,B16,Stock!$D$340:$IP$340))) -> 107 | F16: =D16-E16 -> 27 | G16: =IF(AND(B16="",C16=""),"",IF(C16<>"",IF(COUNTIFS(Stock!$D$4:$IP$4,B16,Stock!$D$5:$IP$5,C16)>0,SUMIFS(Stock!$D$32:$IP$32,Stock!$D$4:$IP$4,B16,Stock!$D$5:$IP$5,C16),IF(COUNTIF(Stock!$D$5:$IP$5,C16)>0,SUMIF(Stock!$D$5:$IP$5,C16,Stock!$D$32:$IP$32),SUMIF(Stock!$D$4:$IP$4,B16,Stock!$D$32:$IP$32))),SUMIF(Stock!$D$4:$IP$4,B16,Stock!$D$32:$IP$32))) -> 132 | I16: ESTILO | J16: PC-408 | K16: 1 | L16: =IF(AND(I16="",J16=""),"",IF(J16<>"",IF(COUNTIFS(Stock!$D$4:$IP$4,I16,Stock!$D$5:$IP$5,J16)>0,SUMIFS(Stock!$D$340:$IP$340,Stock!$D$4:$IP$4,I16,Stock!$D$5:$IP$5,J16),IF(COUNTIF(Stock!$D$5:$IP$5,J16)>0,SUMIF(Stock!$D$5:$IP$5,J16,Stock!$D$340:$IP$340),SUMIF(Stock!$D$4:$IP$4,I16,Stock!$D$340:$IP$340))),SUMIF(Stock!$D$4:$IP$4,I16,Stock!$D$340:$IP$340))) -> 0 | M16: =K16-L16 -> 1 | N16: =IF(AND(I16="",J16=""),"",IF(J16<>"",IF(COUNTIFS(Stock!$D$4:$IP$4,I16,Stock!$D$5:$IP$5,J16)>0,SUMIFS(Stock!$D$32:$IP$32,Stock!$D$4:$IP$4,I16,Stock!$D$5:$IP$5,J16),IF(COUNTIF(Stock!$D$5:$IP$5,J16)>0,SUMIF(Stock!$D$5:$IP$5,J16,Stock!$D$32:$IP$32),SUMIF(Stock!$D$4:$IP$4,I16,Stock!$D$32:$IP$32))),SUMIF(Stock!$D$4:$IP$4,I16,Stock!$D$32:$IP$32))) -> 0 | P16: Innova | R16: 664 | S16: =IF(AND(P16="",Q16=""),"",IF(Q16<>"",IF(COUNTIFS(Stock!$D$4:$IP$4,P16,Stock!$D$5:$IP$5,Q16)>0,SUMIFS(Stock!$D$340:$IP$340,Stock!$D$4:$IP$4,P16,Stock!$D$5:$IP$5,Q16),IF(COUNTIF(Stock!$D$5:$IP$5,Q16)>0,SUMIF(Stock!$D$5:$IP$5,Q16,Stock!$D$340:$IP$340),SUMIF(Stock!$D$4:$IP$4,P16,Stock!$D$340:$IP$340))),SUMIF(Stock!$D$4:$IP$4,P16,Stock!$D$340:$IP$340))) -> 741 | T16: =R16-S16 -> -77 | U16: =IF(AND(P16="",Q16=""),"",IF(Q16<>"",IF(COUNTIFS(Stock!$D$4:$IP$4,P16,Stock!$D$5:$IP$5,Q16)>0,SUMIFS(Stock!$D$32:$IP$32,Stock!$D$4:$IP$4,P16,Stock!$D$5:$IP$5,Q16),IF(COUNTIF(Stock!$D$5:$IP$5,Q16)>0,SUMIF(Stock!$D$5:$IP$5,Q16,Stock!$D$32:$IP$32),SUMIF(Stock!$D$4:$IP$4,P16,Stock!$D$32:$IP$32))),SUMIF(Stock!$D$4:$IP$4,P16,Stock!$D$32:$IP$32))) -> 1507 | V16: INNOVA;INNOVAACSWITCH;INNOVAACSWTICH;TOKAIINNOVAACSWITCH | X16: {=IF(NOT(ISNUMBER($W16)),"CHECK",IF(OR(AND(TRIM($Q16&"")<>"",INDEX(Stock!$EW$5:$FU$5,$W16)=$Q16),INDEX(Stock!$EW$4:$FU$4,$W16)=$P16),"OK","CHECK"))} -> CHECK
B17: Sumo VECTA | C17: PC-86241 | D17: 100 | E17: =IF(AND(B17="",C17=""),"",IF(C17<>"",IF(COUNTIFS(Stock!$D$4:$IP$4,B17,Stock!$D$5:$IP$5,C17)>0,SUMIFS(Stock!$D$340:$IP$340,Stock!$D$4:$IP$4,B17,Stock!$D$5:$IP$5,C17),IF(COUNTIF(Stock!$D$5:$IP$5,C17)>0,SUMIF(Stock!$D$5:$IP$5,C17,Stock!$D$340:$IP$340),SUMIF(Stock!$D$4:$IP$4,B17,Stock!$D$340:$IP$340))),SUMIF(Stock!$D$4:$IP$4,B17,Stock!$D$340:$IP$340))) -> 55 | F17: =D17-E17 -> 45 | G17: =IF(AND(B17="",C17=""),"",IF(C17<>"",IF(COUNTIFS(Stock!$D$4:$IP$4,B17,Stock!$D$5:$IP$5,C17)>0,SUMIFS(Stock!$D$32:$IP$32,Stock!$D$4:$IP$4,B17,Stock!$D$5:$IP$5,C17),IF(COUNTIF(Stock!$D$5:$IP$5,C17)>0,SUMIF(Stock!$D$5:$IP$5,C17,Stock!$D$32:$IP$32),SUMIF(Stock!$D$4:$IP$4,B17,Stock!$D$32:$IP$32))),SUMIF(Stock!$D$4:$IP$4,B17,Stock!$D$32:$IP$32))) -> 100 | I17: FORD IKON | J17: PC-053 | K17: 348 | L17: =IF(AND(I17="",J17=""),"",IF(J17<>"",IF(COUNTIFS(Stock!$D$4:$IP$4,I17,Stock!$D$5:$IP$5,J17)>0,SUMIFS(Stock!$D$340:$IP$340,Stock!$D$4:$IP$4,I17,Stock!$D$5:$IP$5,J17),IF(COUNTIF(Stock!$D$5:$IP$5,J17)>0,SUMIF(Stock!$D$5:$IP$5,J17,Stock!$D$340:$IP$340),SUMIF(Stock!$D$4:$IP$4,I17,Stock!$D$340:$IP$340))),SUMIF(Stock!$D$4:$IP$4,I17,Stock!$D$340:$IP$340))) -> 202 | M17: =K17-L17 -> 146 | N17: =IF(AND(I17="",J17=""),"",IF(J17<>"",IF(COUNTIFS(Stock!$D$4:$IP$4,I17,Stock!$D$5:$IP$5,J17)>0,SUMIFS(Stock!$D$32:$IP$32,Stock!$D$4:$IP$4,I17,Stock!$D$5:$IP$5,J17),IF(COUNTIF(Stock!$D$5:$IP$5,J17)>0,SUMIF(Stock!$D$5:$IP$5,J17,Stock!$D$32:$IP$32),SUMIF(Stock!$D$4:$IP$4,I17,Stock!$D$32:$IP$32))),SUMIF(Stock!$D$4:$IP$4,I17,Stock!$D$32:$IP$32))) -> 346 | P17: SANTRO | Q17: PC-1054B | R17: 100 | S17: =IF(AND(P17="",Q17=""),"",IF(Q17<>"",IF(COUNTIFS(Stock!$D$4:$IP$4,P17,Stock!$D$5:$IP$5,Q17)>0,SUMIFS(Stock!$D$340:$IP$340,Stock!$D$4:$IP$4,P17,Stock!$D$5:$IP$5,Q17),IF(COUNTIF(Stock!$D$5:$IP$5,Q17)>0,SUMIF(Stock!$D$5:$IP$5,Q17,Stock!$D$340:$IP$340),SUMIF(Stock!$D$4:$IP$4,P17,Stock!$D$340:$IP$340))),SUMIF(Stock!$D$4:$IP$4,P17,Stock!$D$340:$IP$340))) -> 100 | T17: =R17-S17 -> 0 | U17: =IF(AND(P17="",Q17=""),"",IF(Q17<>"",IF(COUNTIFS(Stock!$D$4:$IP$4,P17,Stock!$D$5:$IP$5,Q17)>0,SUMIFS(Stock!$D$32:$IP$32,Stock!$D$4:$IP$4,P17,Stock!$D$5:$IP$5,Q17),IF(COUNTIF(Stock!$D$5:$IP$5,Q17)>0,SUMIF(Stock!$D$5:$IP$5,Q17,Stock!$D$32:$IP$32),SUMIF(Stock!$D$4:$IP$4,P17,Stock!$D$32:$IP$32))),SUMIF(Stock!$D$4:$IP$4,P17,Stock!$D$32:$IP$32))) -> 848 | V17: PC1054B | X17: {=IF(NOT(ISNUMBER($W17)),"CHECK",IF(OR(AND(TRIM($Q17&"")<>"",INDEX(Stock!$EW$5:$FU$5,$W17)=$Q17),INDEX(Stock!$EW$4:$FU$4,$W17)=$P17),"OK","CHECK"))} -> CHECK
B18: BELANO | C18: PC-86242 | D18: 60 | E18: =IF(AND(B18="",C18=""),"",IF(C18<>"",IF(COUNTIFS(Stock!$D$4:$IP$4,B18,Stock!$D$5:$IP$5,C18)>0,SUMIFS(Stock!$D$340:$IP$340,Stock!$D$4:$IP$4,B18,Stock!$D$5:$IP$5,C18),IF(COUNTIF(Stock!$D$5:$IP$5,C18)>0,SUMIF(Stock!$D$5:$IP$5,C18,Stock!$D$340:$IP$340),SUMIF(Stock!$D$4:$IP$4,B18,Stock!$D$340:$IP$340))),SUMIF(Stock!$D$4:$IP$4,B18,Stock!$D$340:$IP$340))) -> 30 | F18: =D18-E18 -> 30 | G18: =IF(AND(B18="",C18=""),"",IF(C18<>"",IF(COUNTIFS(Stock!$D$4:$IP$4,B18,Stock!$D$5:$IP$5,C18)>0,SUMIFS(Stock!$D$32:$IP$32,Stock!$D$4:$IP$4,B18,Stock!$D$5:$IP$5,C18),IF(COUNTIF(Stock!$D$5:$IP$5,C18)>0,SUMIF(Stock!$D$5:$IP$5,C18,Stock!$D$32:$IP$32),SUMIF(Stock!$D$4:$IP$4,B18,Stock!$D$32:$IP$32))),SUMIF(Stock!$D$4:$IP$4,B18,Stock!$D$32:$IP$32))) -> 100 | I18: FIESTA | J18: PC-205 | K18: 92 | L18: =IF(AND(I18="",J18=""),"",IF(J18<>"",IF(COUNTIFS(Stock!$D$4:$IP$4,I18,Stock!$D$5:$IP$5,J18)>0,SUMIFS(Stock!$D$340:$IP$340,Stock!$D$4:$IP$4,I18,Stock!$D$5:$IP$5,J18),IF(COUNTIF(Stock!$D$5:$IP$5,J18)>0,SUMIF(Stock!$D$5:$IP$5,J18,Stock!$D$340:$IP$340),SUMIF(Stock!$D$4:$IP$4,I18,Stock!$D$340:$IP$340))),SUMIF(Stock!$D$4:$IP$4,I18,Stock!$D$340:$IP$340))) -> 104 | M18: =K18-L18 -> -12 | N18: =IF(AND(I18="",J18=""),"",IF(J18<>"",IF(COUNTIFS(Stock!$D$4:$IP$4,I18,Stock!$D$5:$IP$5,J18)>0,SUMIFS(Stock!$D$32:$IP$32,Stock!$D$4:$IP$4,I18,Stock!$D$5:$IP$5,J18),IF(COUNTIF(Stock!$D$5:$IP$5,J18)>0,SUMIF(Stock!$D$5:$IP$5,J18,Stock!$D$32:$IP$32),SUMIF(Stock!$D$4:$IP$4,I18,Stock!$D$32:$IP$32))),SUMIF(Stock!$D$4:$IP$4,I18,Stock!$D$32:$IP$32))) -> 104 | P18: OPEL-BIG | Q18: PC-1091 | S18: =IF(AND(P18="",Q18=""),"",IF(Q18<>"",IF(COUNTIFS(Stock!$D$4:$IP$4,P18,Stock!$D$5:$IP$5,Q18)>0,SUMIFS(Stock!$D$340:$IP$340,Stock!$D$4:$IP$4,P18,Stock!$D$5:$IP$5,Q18),IF(COUNTIF(Stock!$D$5:$IP$5,Q18)>0,SUMIF(Stock!$D$5:$IP$5,Q18,Stock!$D$340:$IP$340),SUMIF(Stock!$D$4:$IP$4,P18,Stock!$D$340:$IP$340))),SUMIF(Stock!$D$4:$IP$4,P18,Stock!$D$340:$IP$340))) -> 0 | T18: =R18-S18 -> 0 | U18: =IF(AND(P18="",Q18=""),"",IF(Q18<>"",IF(COUNTIFS(Stock!$D$4:$IP$4,P18,Stock!$D$5:$IP$5,Q18)>0,SUMIFS(Stock!$D$32:$IP$32,Stock!$D$4:$IP$4,P18,Stock!$D$5:$IP$5,Q18),IF(COUNTIF(Stock!$D$5:$IP$5,Q18)>0,SUMIF(Stock!$D$5:$IP$5,Q18,Stock!$D$32:$IP$32),SUMIF(Stock!$D$4:$IP$4,P18,Stock!$D$32:$IP$32))),SUMIF(Stock!$D$4:$IP$4,P18,Stock!$D$32:$IP$32))) -> 199 | V18: PC1091 | X18: {=IF(NOT(ISNUMBER($W18)),"CHECK",IF(OR(AND(TRIM($Q18&"")<>"",INDEX(Stock!$EW$5:$FU$5,$W18)=$Q18),INDEX(Stock!$EW$4:$FU$4,$W18)=$P18),"OK","CHECK"))} -> CHECK
B19: ESTEEM-R12 | C19: PC-86040 | D19: 110 | E19: =IF(AND(B19="",C19=""),"",IF(C19<>"",IF(COUNTIFS(Stock!$D$4:$IP$4,B19,Stock!$D$5:$IP$5,C19)>0,SUMIFS(Stock!$D$340:$IP$340,Stock!$D$4:$IP$4,B19,Stock!$D$5:$IP$5,C19),IF(COUNTIF(Stock!$D$5:$IP$5,C19)>0,SUMIF(Stock!$D$5:$IP$5,C19,Stock!$D$340:$IP$340),SUMIF(Stock!$D$4:$IP$4,B19,Stock!$D$340:$IP$340))),SUMIF(Stock!$D$4:$IP$4,B19,Stock!$D$340:$IP$340))) -> 0 | F19: =D19-E19 -> 110 | G19: =IF(AND(B19="",C19=""),"",IF(C19<>"",IF(COUNTIFS(Stock!$D$4:$IP$4,B19,Stock!$D$5:$IP$5,C19)>0,SUMIFS(Stock!$D$32:$IP$32,Stock!$D$4:$IP$4,B19,Stock!$D$5:$IP$5,C19),IF(COUNTIF(Stock!$D$5:$IP$5,C19)>0,SUMIF(Stock!$D$5:$IP$5,C19,Stock!$D$32:$IP$32),SUMIF(Stock!$D$4:$IP$4,B19,Stock!$D$32:$IP$32))),SUMIF(Stock!$D$4:$IP$4,B19,Stock!$D$32:$IP$32))) -> 200 | I19: Getz | J19: PC-024R (origin PC-207) | K19: 45 | L19: =IF(AND(I19="",J19=""),"",IF(J19<>"",IF(COUNTIFS(Stock!$D$4:$IP$4,I19,Stock!$D$5:$IP$5,J19)>0,SUMIFS(Stock!$D$340:$IP$340,Stock!$D$4:$IP$4,I19,Stock!$D$5:$IP$5,J19),IF(COUNTIF(Stock!$D$5:$IP$5,J19)>0,SUMIF(Stock!$D$5:$IP$5,J19,Stock!$D$340:$IP$340),SUMIF(Stock!$D$4:$IP$4,I19,Stock!$D$340:$IP$340))),SUMIF(Stock!$D$4:$IP$4,I19,Stock!$D$340:$IP$340))) -> 75 | M19: =K19-L19 -> -30 | N19: =IF(AND(I19="",J19=""),"",IF(J19<>"",IF(COUNTIFS(Stock!$D$4:$IP$4,I19,Stock!$D$5:$IP$5,J19)>0,SUMIFS(Stock!$D$32:$IP$32,Stock!$D$4:$IP$4,I19,Stock!$D$5:$IP$5,J19),IF(COUNTIF(Stock!$D$5:$IP$5,J19)>0,SUMIF(Stock!$D$5:$IP$5,J19,Stock!$D$32:$IP$32),SUMIF(Stock!$D$4:$IP$4,I19,Stock!$D$32:$IP$32))),SUMIF(Stock!$D$4:$IP$4,I19,Stock!$D$32:$IP$32))) -> 75 | P19: ESTEEM-R12 / Accent | Q19: PC-1046 | R19: 500 | S19: =IF(AND(P19="",Q19=""),"",IF(Q19<>"",IF(COUNTIFS(Stock!$D$4:$IP$4,P19,Stock!$D$5:$IP$5,Q19)>0,SUMIFS(Stock!$D$340:$IP$340,Stock!$D$4:$IP$4,P19,Stock!$D$5:$IP$5,Q19),IF(COUNTIF(Stock!$D$5:$IP$5,Q19)>0,SUMIF(Stock!$D$5:$IP$5,Q19,Stock!$D$340:$IP$340),SUMIF(Stock!$D$4:$IP$4,P19,Stock!$D$340:$IP$340))),SUMIF(Stock!$D$4:$IP$4,P19,Stock!$D$340:$IP$340))) -> 500 | T19: =R19-S19 -> 0 | U19: =IF(AND(P19="",Q19=""),"",IF(Q19<>"",IF(COUNTIFS(Stock!$D$4:$IP$4,P19,Stock!$D$5:$IP$5,Q19)>0,SUMIFS(Stock!$D$32:$IP$32,Stock!$D$4:$IP$4,P19,Stock!$D$5:$IP$5,Q19),IF(COUNTIF(Stock!$D$5:$IP$5,Q19)>0,SUMIF(Stock!$D$5:$IP$5,Q19,Stock!$D$32:$IP$32),SUMIF(Stock!$D$4:$IP$4,P19,Stock!$D$32:$IP$32))),SUMIF(Stock!$D$4:$IP$4,P19,Stock!$D$32:$IP$32))) -> 750 | V19: PC1046 | X19: {=IF(NOT(ISNUMBER($W19)),"CHECK",IF(OR(AND(TRIM($Q19&"")<>"",INDEX(Stock!$EW$5:$FU$5,$W19)=$Q19),INDEX(Stock!$EW$4:$FU$4,$W19)=$P19),"OK","CHECK"))} -> CHECK
B20: Esteem-134a | C20: PC-86090 | D20: 221 | E20: =IF(AND(B20="",C20=""),"",IF(C20<>"",IF(COUNTIFS(Stock!$D$4:$IP$4,B20,Stock!$D$5:$IP$5,C20)>0,SUMIFS(Stock!$D$340:$IP$340,Stock!$D$4:$IP$4,B20,Stock!$D$5:$IP$5,C20),IF(COUNTIF(Stock!$D$5:$IP$5,C20)>0,SUMIF(Stock!$D$5:$IP$5,C20,Stock!$D$340:$IP$340),SUMIF(Stock!$D$4:$IP$4,B20,Stock!$D$340:$IP$340))),SUMIF(Stock!$D$4:$IP$4,B20,Stock!$D$340:$IP$340))) -> 171 | F20: =D20-E20 -> 50 | G20: =IF(AND(B20="",C20=""),"",IF(C20<>"",IF(COUNTIFS(Stock!$D$4:$IP$4,B20,Stock!$D$5:$IP$5,C20)>0,SUMIFS(Stock!$D$32:$IP$32,Stock!$D$4:$IP$4,B20,Stock!$D$5:$IP$5,C20),IF(COUNTIF(Stock!$D$5:$IP$5,C20)>0,SUMIF(Stock!$D$5:$IP$5,C20,Stock!$D$32:$IP$32),SUMIF(Stock!$D$4:$IP$4,B20,Stock!$D$32:$IP$32))),SUMIF(Stock!$D$4:$IP$4,B20,Stock!$D$32:$IP$32))) -> 221 | I20: ELANTRA | J20: PC-135R | K20: 66 | L20: =IF(AND(I20="",J20=""),"",IF(J20<>"",IF(COUNTIFS(Stock!$D$4:$IP$4,I20,Stock!$D$5:$IP$5,J20)>0,SUMIFS(Stock!$D$340:$IP$340,Stock!$D$4:$IP$4,I20,Stock!$D$5:$IP$5,J20),IF(COUNTIF(Stock!$D$5:$IP$5,J20)>0,SUMIF(Stock!$D$5:$IP$5,J20,Stock!$D$340:$IP$340),SUMIF(Stock!$D$4:$IP$4,I20,Stock!$D$340:$IP$340))),SUMIF(Stock!$D$4:$IP$4,I20,Stock!$D$340:$IP$340))) -> 42 | M20: =K20-L20 -> 24 | N20: =IF(AND(I20="",J20=""),"",IF(J20<>"",IF(COUNTIFS(Stock!$D$4:$IP$4,I20,Stock!$D$5:$IP$5,J20)>0,SUMIFS(Stock!$D$32:$IP$32,Stock!$D$4:$IP$4,I20,Stock!$D$5:$IP$5,J20),IF(COUNTIF(Stock!$D$5:$IP$5,J20)>0,SUMIF(Stock!$D$5:$IP$5,J20,Stock!$D$32:$IP$32),SUMIF(Stock!$D$4:$IP$4,I20,Stock!$D$32:$IP$32))),SUMIF(Stock!$D$4:$IP$4,I20,Stock!$D$32:$IP$32))) -> 80 | P20: SONATA | Q20: PC-2126 | R20: 49 | S20: =IF(AND(P20="",Q20=""),"",IF(Q20<>"",IF(COUNTIFS(Stock!$D$4:$IP$4,P20,Stock!$D$5:$IP$5,Q20)>0,SUMIFS(Stock!$D$340:$IP$340,Stock!$D$4:$IP$4,P20,Stock!$D$5:$IP$5,Q20),IF(COUNTIF(Stock!$D$5:$IP$5,Q20)>0,SUMIF(Stock!$D$5:$IP$5,Q20,Stock!$D$340:$IP$340),SUMIF(Stock!$D$4:$IP$4,P20,Stock!$D$340:$IP$340))),SUMIF(Stock!$D$4:$IP$4,P20,Stock!$D$340:$IP$340))) -> 100 | T20: =R20-S20 -> -51 | U20: =IF(AND(P20="",Q20=""),"",IF(Q20<>"",IF(COUNTIFS(Stock!$D$4:$IP$4,P20,Stock!$D$5:$IP$5,Q20)>0,SUMIFS(Stock!$D$32:$IP$32,Stock!$D$4:$IP$4,P20,Stock!$D$5:$IP$5,Q20),IF(COUNTIF(Stock!$D$5:$IP$5,Q20)>0,SUMIF(Stock!$D$5:$IP$5,Q20,Stock!$D$32:$IP$32),SUMIF(Stock!$D$4:$IP$4,P20,Stock!$D$32:$IP$32))),SUMIF(Stock!$D$4:$IP$4,P20,Stock!$D$32:$IP$32))) -> 200 | V20: PC2126 | X20: {=IF(NOT(ISNUMBER($W20)),"CHECK",IF(OR(AND(TRIM($Q20&"")<>"",INDEX(Stock!$EW$5:$FU$5,$W20)=$Q20),INDEX(Stock!$EW$4:$FU$4,$W20)=$P20),"OK","CHECK"))} -> CHECK
B21: ACCENT CRD-I | C21: PC-86064B | D21: 100 | E21: =IF(AND(B21="",C21=""),"",IF(C21<>"",IF(COUNTIFS(Stock!$D$4:$IP$4,B21,Stock!$D$5:$IP$5,C21)>0,SUMIFS(Stock!$D$340:$IP$340,Stock!$D$4:$IP$4,B21,Stock!$D$5:$IP$5,C21),IF(COUNTIF(Stock!$D$5:$IP$5,C21)>0,SUMIF(Stock!$D$5:$IP$5,C21,Stock!$D$340:$IP$340),SUMIF(Stock!$D$4:$IP$4,B21,Stock!$D$340:$IP$340))),SUMIF(Stock!$D$4:$IP$4,B21,Stock!$D$340:$IP$340))) -> 75 | F21: =D21-E21 -> 25 | G21: =IF(AND(B21="",C21=""),"",IF(C21<>"",IF(COUNTIFS(Stock!$D$4:$IP$4,B21,Stock!$D$5:$IP$5,C21)>0,SUMIFS(Stock!$D$32:$IP$32,Stock!$D$4:$IP$4,B21,Stock!$D$5:$IP$5,C21),IF(COUNTIF(Stock!$D$5:$IP$5,C21)>0,SUMIF(Stock!$D$5:$IP$5,C21,Stock!$D$32:$IP$32),SUMIF(Stock!$D$4:$IP$4,B21,Stock!$D$32:$IP$32))),SUMIF(Stock!$D$4:$IP$4,B21,Stock!$D$32:$IP$32))) -> 100 | I21: SENTRO | J21: PC-144R | K21: 104 | L21: =IF(AND(I21="",J21=""),"",IF(J21<>"",IF(COUNTIFS(Stock!$D$4:$IP$4,I21,Stock!$D$5:$IP$5,J21)>0,SUMIFS(Stock!$D$340:$IP$340,Stock!$D$4:$IP$4,I21,Stock!$D$5:$IP$5,J21),IF(COUNTIF(Stock!$D$5:$IP$5,J21)>0,SUMIF(Stock!$D$5:$IP$5,J21,Stock!$D$340:$IP$340),SUMIF(Stock!$D$4:$IP$4,I21,Stock!$D$340:$IP$340))),SUMIF(Stock!$D$4:$IP$4,I21,Stock!$D$340:$IP$340))) -> 110 | M21: =K21-L21 -> -6 | N21: =IF(AND(I21="",J21=""),"",IF(J21<>"",IF(COUNTIFS(Stock!$D$4:$IP$4,I21,Stock!$D$5:$IP$5,J21)>0,SUMIFS(Stock!$D$32:$IP$32,Stock!$D$4:$IP$4,I21,Stock!$D$5:$IP$5,J21),IF(COUNTIF(Stock!$D$5:$IP$5,J21)>0,SUMIF(Stock!$D$5:$IP$5,J21,Stock!$D$32:$IP$32),SUMIF(Stock!$D$4:$IP$4,I21,Stock!$D$32:$IP$32))),SUMIF(Stock!$D$4:$IP$4,I21,Stock!$D$32:$IP$32))) -> 110 | P21: ESTEEM-R134/Lancer | Q21: PC-1042A | S21: =IF(AND(P21="",Q21=""),"",IF(Q21<>"",IF(COUNTIFS(Stock!$D$4:$IP$4,P21,Stock!$D$5:$IP$5,Q21)>0,SUMIFS(Stock!$D$340:$IP$340,Stock!$D$4:$IP$4,P21,Stock!$D$5:$IP$5,Q21),IF(COUNTIF(Stock!$D$5:$IP$5,Q21)>0,SUMIF(Stock!$D$5:$IP$5,Q21,Stock!$D$340:$IP$340),SUMIF(Stock!$D$4:$IP$4,P21,Stock!$D$340:$IP$340))),SUMIF(Stock!$D$4:$IP$4,P21,Stock!$D$340:$IP$340))) -> 0 | T21: =R21-S21 -> 0 | U21: =IF(AND(P21="",Q21=""),"",IF(Q21<>"",IF(COUNTIFS(Stock!$D$4:$IP$4,P21,Stock!$D$5:$IP$5,Q21)>0,SUMIFS(Stock!$D$32:$IP$32,Stock!$D$4:$IP$4,P21,Stock!$D$5:$IP$5,Q21),IF(COUNTIF(Stock!$D$5:$IP$5,Q21)>0,SUMIF(Stock!$D$5:$IP$5,Q21,Stock!$D$32:$IP$32),SUMIF(Stock!$D$4:$IP$4,P21,Stock!$D$32:$IP$32))),SUMIF(Stock!$D$4:$IP$4,P21,Stock!$D$32:$IP$32))) -> 200 | V21: PC1042A | X21: {=IF(NOT(ISNUMBER($W21)),"CHECK",IF(OR(AND(TRIM($Q21&"")<>"",INDEX(Stock!$EW$5:$FU$5,$W21)=$Q21),INDEX(Stock!$EW$4:$FU$4,$W21)=$P21),"OK","CHECK"))} -> CHECK
B22: OPEL-ASTRA | C22: PC-86243 | D22: 5 | E22: =IF(AND(B22="",C22=""),"",IF(C22<>"",IF(COUNTIFS(Stock!$D$4:$IP$4,B22,Stock!$D$5:$IP$5,C22)>0,SUMIFS(Stock!$D$340:$IP$340,Stock!$D$4:$IP$4,B22,Stock!$D$5:$IP$5,C22),IF(COUNTIF(Stock!$D$5:$IP$5,C22)>0,SUMIF(Stock!$D$5:$IP$5,C22,Stock!$D$340:$IP$340),SUMIF(Stock!$D$4:$IP$4,B22,Stock!$D$340:$IP$340))),SUMIF(Stock!$D$4:$IP$4,B22,Stock!$D$340:$IP$340))) -> 5 | F22: =D22-E22 -> 0 | G22: =IF(AND(B22="",C22=""),"",IF(C22<>"",IF(COUNTIFS(Stock!$D$4:$IP$4,B22,Stock!$D$5:$IP$5,C22)>0,SUMIFS(Stock!$D$32:$IP$32,Stock!$D$4:$IP$4,B22,Stock!$D$5:$IP$5,C22),IF(COUNTIF(Stock!$D$5:$IP$5,C22)>0,SUMIF(Stock!$D$5:$IP$5,C22,Stock!$D$32:$IP$32),SUMIF(Stock!$D$4:$IP$4,B22,Stock!$D$32:$IP$32))),SUMIF(Stock!$D$4:$IP$4,B22,Stock!$D$32:$IP$32))) -> 10 | I22: Indigo | J22: PC-7157 | K22: 322 | L22: =IF(AND(I22="",J22=""),"",IF(J22<>"",IF(COUNTIFS(Stock!$D$4:$IP$4,I22,Stock!$D$5:$IP$5,J22)>0,SUMIFS(Stock!$D$340:$IP$340,Stock!$D$4:$IP$4,I22,Stock!$D$5:$IP$5,J22),IF(COUNTIF(Stock!$D$5:$IP$5,J22)>0,SUMIF(Stock!$D$5:$IP$5,J22,Stock!$D$340:$IP$340),SUMIF(Stock!$D$4:$IP$4,I22,Stock!$D$340:$IP$340))),SUMIF(Stock!$D$4:$IP$4,I22,Stock!$D$340:$IP$340))) -> 150 | M22: =K22-L22 -> 172 | N22: =IF(AND(I22="",J22=""),"",IF(J22<>"",IF(COUNTIFS(Stock!$D$4:$IP$4,I22,Stock!$D$5:$IP$5,J22)>0,SUMIFS(Stock!$D$32:$IP$32,Stock!$D$4:$IP$4,I22,Stock!$D$5:$IP$5,J22),IF(COUNTIF(Stock!$D$5:$IP$5,J22)>0,SUMIF(Stock!$D$5:$IP$5,J22,Stock!$D$32:$IP$32),SUMIF(Stock!$D$4:$IP$4,I22,Stock!$D$32:$IP$32))),SUMIF(Stock!$D$4:$IP$4,I22,Stock!$D$32:$IP$32))) -> 300 | P22: OPEL-SMALL-2pin | Q22: PC-1087 | S22: =IF(AND(P22="",Q22=""),"",IF(Q22<>"",IF(COUNTIFS(Stock!$D$4:$IP$4,P22,Stock!$D$5:$IP$5,Q22)>0,SUMIFS(Stock!$D$340:$IP$340,Stock!$D$4:$IP$4,P22,Stock!$D$5:$IP$5,Q22),IF(COUNTIF(Stock!$D$5:$IP$5,Q22)>0,SUMIF(Stock!$D$5:$IP$5,Q22,Stock!$D$340:$IP$340),SUMIF(Stock!$D$4:$IP$4,P22,Stock!$D$340:$IP$340))),SUMIF(Stock!$D$4:$IP$4,P22,Stock!$D$340:$IP$340))) -> 0 | T22: =R22-S22 -> 0 | U22: =IF(AND(P22="",Q22=""),"",IF(Q22<>"",IF(COUNTIFS(Stock!$D$4:$IP$4,P22,Stock!$D$5:$IP$5,Q22)>0,SUMIFS(Stock!$D$32:$IP$32,Stock!$D$4:$IP$4,P22,Stock!$D$5:$IP$5,Q22),IF(COUNTIF(Stock!$D$5:$IP$5,Q22)>0,SUMIF(Stock!$D$5:$IP$5,Q22,Stock!$D$32:$IP$32),SUMIF(Stock!$D$4:$IP$4,P22,Stock!$D$32:$IP$32))),SUMIF(Stock!$D$4:$IP$4,P22,Stock!$D$32:$IP$32))) -> 224 | V22: PC1087 | X22: {=IF(NOT(ISNUMBER($W22)),"CHECK",IF(OR(AND(TRIM($Q22&"")<>"",INDEX(Stock!$EW$5:$FU$5,$W22)=$Q22),INDEX(Stock!$EW$4:$FU$4,$W22)=$P22),"OK","CHECK"))} -> CHECK
B23: ZEN-R134A | C23: PC-86245 | D23: 330 | E23: =IF(AND(B23="",C23=""),"",IF(C23<>"",IF(COUNTIFS(Stock!$D$4:$IP$4,B23,Stock!$D$5:$IP$5,C23)>0,SUMIFS(Stock!$D$340:$IP$340,Stock!$D$4:$IP$4,B23,Stock!$D$5:$IP$5,C23),IF(COUNTIF(Stock!$D$5:$IP$5,C23)>0,SUMIF(Stock!$D$5:$IP$5,C23,Stock!$D$340:$IP$340),SUMIF(Stock!$D$4:$IP$4,B23,Stock!$D$340:$IP$340))),SUMIF(Stock!$D$4:$IP$4,B23,Stock!$D$340:$IP$340))) -> 230 | F23: =D23-E23 -> 100 | G23: =IF(AND(B23="",C23=""),"",IF(C23<>"",IF(COUNTIFS(Stock!$D$4:$IP$4,B23,Stock!$D$5:$IP$5,C23)>0,SUMIFS(Stock!$D$32:$IP$32,Stock!$D$4:$IP$4,B23,Stock!$D$5:$IP$5,C23),IF(COUNTIF(Stock!$D$5:$IP$5,C23)>0,SUMIF(Stock!$D$5:$IP$5,C23,Stock!$D$32:$IP$32),SUMIF(Stock!$D$4:$IP$4,B23,Stock!$D$32:$IP$32))),SUMIF(Stock!$D$4:$IP$4,B23,Stock!$D$32:$IP$32))) -> 330 | I23: Innova | J23: PC-209 | K23: 100 | L23: =IF(AND(I23="",J23=""),"",IF(J23<>"",IF(COUNTIFS(Stock!$D$4:$IP$4,I23,Stock!$D$5:$IP$5,J23)>0,SUMIFS(Stock!$D$340:$IP$340,Stock!$D$4:$IP$4,I23,Stock!$D$5:$IP$5,J23),IF(COUNTIF(Stock!$D$5:$IP$5,J23)>0,SUMIF(Stock!$D$5:$IP$5,J23,Stock!$D$340:$IP$340),SUMIF(Stock!$D$4:$IP$4,I23,Stock!$D$340:$IP$340))),SUMIF(Stock!$D$4:$IP$4,I23,Stock!$D$340:$IP$340))) -> 100 | M23: =K23-L23 -> 0 | N23: =IF(AND(I23="",J23=""),"",IF(J23<>"",IF(COUNTIFS(Stock!$D$4:$IP$4,I23,Stock!$D$5:$IP$5,J23)>0,SUMIFS(Stock!$D$32:$IP$32,Stock!$D$4:$IP$4,I23,Stock!$D$5:$IP$5,J23),IF(COUNTIF(Stock!$D$5:$IP$5,J23)>0,SUMIF(Stock!$D$5:$IP$5,J23,Stock!$D$32:$IP$32),SUMIF(Stock!$D$4:$IP$4,I23,Stock!$D$32:$IP$32))),SUMIF(Stock!$D$4:$IP$4,I23,Stock!$D$32:$IP$32))) -> 100 | P23: HONDA CITY | Q23: PC-1045B | R23: 200 | S23: =IF(AND(P23="",Q23=""),"",IF(Q23<>"",IF(COUNTIFS(Stock!$D$4:$IP$4,P23,Stock!$D$5:$IP$5,Q23)>0,SUMIFS(Stock!$D$340:$IP$340,Stock!$D$4:$IP$4,P23,Stock!$D$5:$IP$5,Q23),IF(COUNTIF(Stock!$D$5:$IP$5,Q23)>0,SUMIF(Stock!$D$5:$IP$5,Q23,Stock!$D$340:$IP$340),SUMIF(Stock!$D$4:$IP$4,P23,Stock!$D$340:$IP$340))),SUMIF(Stock!$D$4:$IP$4,P23,Stock!$D$340:$IP$340))) -> 300 | T23: =R23-S23 -> -100 | U23: =IF(AND(P23="",Q23=""),"",IF(Q23<>"",IF(COUNTIFS(Stock!$D$4:$IP$4,P23,Stock!$D$5:$IP$5,Q23)>0,SUMIFS(Stock!$D$32:$IP$32,Stock!$D$4:$IP$4,P23,Stock!$D$5:$IP$5,Q23),IF(COUNTIF(Stock!$D$5:$IP$5,Q23)>0,SUMIF(Stock!$D$5:$IP$5,Q23,Stock!$D$32:$IP$32),SUMIF(Stock!$D$4:$IP$4,P23,Stock!$D$32:$IP$32))),SUMIF(Stock!$D$4:$IP$4,P23,Stock!$D$32:$IP$32))) -> 400 | V23: PC1045B | X23: {=IF(NOT(ISNUMBER($W23)),"CHECK",IF(OR(AND(TRIM($Q23&"")<>"",INDEX(Stock!$EW$5:$FU$5,$W23)=$Q23),INDEX(Stock!$EW$4:$FU$4,$W23)=$P23),"OK","CHECK"))} -> CHECK
B24: ZEN-R12 | C24: PC-86043 | D24: 400 | E24: =IF(AND(B24="",C24=""),"",IF(C24<>"",IF(COUNTIFS(Stock!$D$4:$IP$4,B24,Stock!$D$5:$IP$5,C24)>0,SUMIFS(Stock!$D$340:$IP$340,Stock!$D$4:$IP$4,B24,Stock!$D$5:$IP$5,C24),IF(COUNTIF(Stock!$D$5:$IP$5,C24)>0,SUMIF(Stock!$D$5:$IP$5,C24,Stock!$D$340:$IP$340),SUMIF(Stock!$D$4:$IP$4,B24,Stock!$D$340:$IP$340))),SUMIF(Stock!$D$4:$IP$4,B24,Stock!$D$340:$IP$340))) -> 0 | F24: =D24-E24 -> 400 | G24: =IF(AND(B24="",C24=""),"",IF(C24<>"",IF(COUNTIFS(Stock!$D$4:$IP$4,B24,Stock!$D$5:$IP$5,C24)>0,SUMIFS(Stock!$D$32:$IP$32,Stock!$D$4:$IP$4,B24,Stock!$D$5:$IP$5,C24),IF(COUNTIF(Stock!$D$5:$IP$5,C24)>0,SUMIF(Stock!$D$5:$IP$5,C24,Stock!$D$32:$IP$32),SUMIF(Stock!$D$4:$IP$4,B24,Stock!$D$32:$IP$32))),SUMIF(Stock!$D$4:$IP$4,B24,Stock!$D$32:$IP$32))) -> 400 | I24: Lancer HCC | J24: PC-206 | K24: 71 | L24: =IF(AND(I24="",J24=""),"",IF(J24<>"",IF(COUNTIFS(Stock!$D$4:$IP$4,I24,Stock!$D$5:$IP$5,J24)>0,SUMIFS(Stock!$D$340:$IP$340,Stock!$D$4:$IP$4,I24,Stock!$D$5:$IP$5,J24),IF(COUNTIF(Stock!$D$5:$IP$5,J24)>0,SUMIF(Stock!$D$5:$IP$5,J24,Stock!$D$340:$IP$340),SUMIF(Stock!$D$4:$IP$4,I24,Stock!$D$340:$IP$340))),SUMIF(Stock!$D$4:$IP$4,I24,Stock!$D$340:$IP$340))) -> 77 | M24: =K24-L24 -> -6 | N24: =IF(AND(I24="",J24=""),"",IF(J24<>"",IF(COUNTIFS(Stock!$D$4:$IP$4,I24,Stock!$D$5:$IP$5,J24)>0,SUMIFS(Stock!$D$32:$IP$32,Stock!$D$4:$IP$4,I24,Stock!$D$5:$IP$5,J24),IF(COUNTIF(Stock!$D$5:$IP$5,J24)>0,SUMIF(Stock!$D$5:$IP$5,J24,Stock!$D$32:$IP$32),SUMIF(Stock!$D$4:$IP$4,I24,Stock!$D$32:$IP$32))),SUMIF(Stock!$D$4:$IP$4,I24,Stock!$D$32:$IP$32))) -> 76 | P24: SWIFT | Q24: PC-1525 | R24: 154 | S24: =IF(AND(P24="",Q24=""),"",IF(Q24<>"",IF(COUNTIFS(Stock!$D$4:$IP$4,P24,Stock!$D$5:$IP$5,Q24)>0,SUMIFS(Stock!$D$340:$IP$340,Stock!$D$4:$IP$4,P24,Stock!$D$5:$IP$5,Q24),IF(COUNTIF(Stock!$D$5:$IP$5,Q24)>0,SUMIF(Stock!$D$5:$IP$5,Q24,Stock!$D$340:$IP$340),SUMIF(Stock!$D$4:$IP$4,P24,Stock!$D$340:$IP$340))),SUMIF(Stock!$D$4:$IP$4,P24,Stock!$D$340:$IP$340))) -> 0 | T24: =R24-S24 -> 154 | U24: =IF(AND(P24="",Q24=""),"",IF(Q24<>"",IF(COUNTIFS(Stock!$D$4:$IP$4,P24,Stock!$D$5:$IP$5,Q24)>0,SUMIFS(Stock!$D$32:$IP$32,Stock!$D$4:$IP$4,P24,Stock!$D$5:$IP$5,Q24),IF(COUNTIF(Stock!$D$5:$IP$5,Q24)>0,SUMIF(Stock!$D$5:$IP$5,Q24,Stock!$D$32:$IP$32),SUMIF(Stock!$D$4:$IP$4,P24,Stock!$D$32:$IP$32))),SUMIF(Stock!$D$4:$IP$4,P24,Stock!$D$32:$IP$32))) -> 222 | V24: PC1525 | X24: {=IF(NOT(ISNUMBER($W24)),"CHECK",IF(OR(AND(TRIM($Q24&"")<>"",INDEX(Stock!$EW$5:$FU$5,$W24)=$Q24),INDEX(Stock!$EW$4:$FU$4,$W24)=$P24),"OK","CHECK"))} -> CHECK
B25: ZEN DEISAL | C25: PC-86279 | D25: 100 | E25: =IF(AND(B25="",C25=""),"",IF(C25<>"",IF(COUNTIFS(Stock!$D$4:$IP$4,B25,Stock!$D$5:$IP$5,C25)>0,SUMIFS(Stock!$D$340:$IP$340,Stock!$D$4:$IP$4,B25,Stock!$D$5:$IP$5,C25),IF(COUNTIF(Stock!$D$5:$IP$5,C25)>0,SUMIF(Stock!$D$5:$IP$5,C25,Stock!$D$340:$IP$340),SUMIF(Stock!$D$4:$IP$4,B25,Stock!$D$340:$IP$340))),SUMIF(Stock!$D$4:$IP$4,B25,Stock!$D$340:$IP$340))) -> 15 | F25: =D25-E25 -> 85 | G25: =IF(AND(B25="",C25=""),"",IF(C25<>"",IF(COUNTIFS(Stock!$D$4:$IP$4,B25,Stock!$D$5:$IP$5,C25)>0,SUMIFS(Stock!$D$32:$IP$32,Stock!$D$4:$IP$4,B25,Stock!$D$5:$IP$5,C25),IF(COUNTIF(Stock!$D$5:$IP$5,C25)>0,SUMIF(Stock!$D$5:$IP$5,C25,Stock!$D$32:$IP$32),SUMIF(Stock!$D$4:$IP$4,B25,Stock!$D$32:$IP$32))),SUMIF(Stock!$D$4:$IP$4,B25,Stock!$D$32:$IP$32))) -> 100 | I25: Lancer MMC-2000 | J25: PC-051R | K25: 241 | L25: =IF(AND(I25="",J25=""),"",IF(J25<>"",IF(COUNTIFS(Stock!$D$4:$IP$4,I25,Stock!$D$5:$IP$5,J25)>0,SUMIFS(Stock!$D$340:$IP$340,Stock!$D$4:$IP$4,I25,Stock!$D$5:$IP$5,J25),IF(COUNTIF(Stock!$D$5:$IP$5,J25)>0,SUMIF(Stock!$D$5:$IP$5,J25,Stock!$D$340:$IP$340),SUMIF(Stock!$D$4:$IP$4,I25,Stock!$D$340:$IP$340))),SUMIF(Stock!$D$4:$IP$4,I25,Stock!$D$340:$IP$340))) -> 177 | M25: =K25-L25 -> 64 | N25: =IF(AND(I25="",J25=""),"",IF(J25<>"",IF(COUNTIFS(Stock!$D$4:$IP$4,I25,Stock!$D$5:$IP$5,J25)>0,SUMIFS(Stock!$D$32:$IP$32,Stock!$D$4:$IP$4,I25,Stock!$D$5:$IP$5,J25),IF(COUNTIF(Stock!$D$5:$IP$5,J25)>0,SUMIF(Stock!$D$5:$IP$5,J25,Stock!$D$32:$IP$32),SUMIF(Stock!$D$4:$IP$4,I25,Stock!$D$32:$IP$32))),SUMIF(Stock!$D$4:$IP$4,I25,Stock!$D$32:$IP$32))) -> 237 | P25: LENCER | Q25: PC-1044A | S25: =IF(AND(P25="",Q25=""),"",IF(Q25<>"",IF(COUNTIFS(Stock!$D$4:$IP$4,P25,Stock!$D$5:$IP$5,Q25)>0,SUMIFS(Stock!$D$340:$IP$340,Stock!$D$4:$IP$4,P25,Stock!$D$5:$IP$5,Q25),IF(COUNTIF(Stock!$D$5:$IP$5,Q25)>0,SUMIF(Stock!$D$5:$IP$5,Q25,Stock!$D$340:$IP$340),SUMIF(Stock!$D$4:$IP$4,P25,Stock!$D$340:$IP$340))),SUMIF(Stock!$D$4:$IP$4,P25,Stock!$D$340:$IP$340))) -> 100 | T25: =R25-S25 -> -100 | U25: =IF(AND(P25="",Q25=""),"",IF(Q25<>"",IF(COUNTIFS(Stock!$D$4:$IP$4,P25,Stock!$D$5:$IP$5,Q25)>0,SUMIFS(Stock!$D$32:$IP$32,Stock!$D$4:$IP$4,P25,Stock!$D$5:$IP$5,Q25),IF(COUNTIF(Stock!$D$5:$IP$5,Q25)>0,SUMIF(Stock!$D$5:$IP$5,Q25,Stock!$D$32:$IP$32),SUMIF(Stock!$D$4:$IP$4,P25,Stock!$D$32:$IP$32))),SUMIF(Stock!$D$4:$IP$4,P25,Stock!$D$32:$IP$32))) -> 200 | V25: PC1044A | X25: {=IF(NOT(ISNUMBER($W25)),"CHECK",IF(OR(AND(TRIM($Q25&"")<>"",INDEX(Stock!$EW$5:$FU$5,$W25)=$Q25),INDEX(Stock!$EW$4:$FU$4,$W25)=$P25),"OK","CHECK"))} -> CHECK
B26: ZEN DELPHI R12 | C26: PC-86270 R12 | D26: 97 | E26: =IF(AND(B26="",C26=""),"",IF(C26<>"",IF(COUNTIFS(Stock!$D$4:$IP$4,B26,Stock!$D$5:$IP$5,C26)>0,SUMIFS(Stock!$D$340:$IP$340,Stock!$D$4:$IP$4,B26,Stock!$D$5:$IP$5,C26),IF(COUNTIF(Stock!$D$5:$IP$5,C26)>0,SUMIF(Stock!$D$5:$IP$5,C26,Stock!$D$340:$IP$340),SUMIF(Stock!$D$4:$IP$4,B26,Stock!$D$340:$IP$340))),SUMIF(Stock!$D$4:$IP$4,B26,Stock!$D$340:$IP$340))) -> 0 | F26: =D26-E26 -> 97 | G26: =IF(AND(B26="",C26=""),"",IF(C26<>"",IF(COUNTIFS(Stock!$D$4:$IP$4,B26,Stock!$D$5:$IP$5,C26)>0,SUMIFS(Stock!$D$32:$IP$32,Stock!$D$4:$IP$4,B26,Stock!$D$5:$IP$5,C26),IF(COUNTIF(Stock!$D$5:$IP$5,C26)>0,SUMIF(Stock!$D$5:$IP$5,C26,Stock!$D$32:$IP$32),SUMIF(Stock!$D$4:$IP$4,B26,Stock!$D$32:$IP$32))),SUMIF(Stock!$D$4:$IP$4,B26,Stock!$D$32:$IP$32))) -> 150 | I26: Logan | J26: PC-407R | K26: 84 | L26: =IF(AND(I26="",J26=""),"",IF(J26<>"",IF(COUNTIFS(Stock!$D$4:$IP$4,I26,Stock!$D$5:$IP$5,J26)>0,SUMIFS(Stock!$D$340:$IP$340,Stock!$D$4:$IP$4,I26,Stock!$D$5:$IP$5,J26),IF(COUNTIF(Stock!$D$5:$IP$5,J26)>0,SUMIF(Stock!$D$5:$IP$5,J26,Stock!$D$340:$IP$340),SUMIF(Stock!$D$4:$IP$4,I26,Stock!$D$340:$IP$340))),SUMIF(Stock!$D$4:$IP$4,I26,Stock!$D$340:$IP$340))) -> 0 | M26: =K26-L26 -> 84 | N26: =IF(AND(I26="",J26=""),"",IF(J26<>"",IF(COUNTIFS(Stock!$D$4:$IP$4,I26,Stock!$D$5:$IP$5,J26)>0,SUMIFS(Stock!$D$32:$IP$32,Stock!$D$4:$IP$4,I26,Stock!$D$5:$IP$5,J26),IF(COUNTIF(Stock!$D$5:$IP$5,J26)>0,SUMIF(Stock!$D$5:$IP$5,J26,Stock!$D$32:$IP$32),SUMIF(Stock!$D$4:$IP$4,I26,Stock!$D$32:$IP$32))),SUMIF(Stock!$D$4:$IP$4,I26,Stock!$D$32:$IP$32))) -> 84 | P26: TOYOTA QUALIS | Q26: PC-1065 | R26: 100 | S26: =IF(AND(P26="",Q26=""),"",IF(Q26<>"",IF(COUNTIFS(Stock!$D$4:$IP$4,P26,Stock!$D$5:$IP$5,Q26)>0,SUMIFS(Stock!$D$340:$IP$340,Stock!$D$4:$IP$4,P26,Stock!$D$5:$IP$5,Q26),IF(COUNTIF(Stock!$D$5:$IP$5,Q26)>0,SUMIF(Stock!$D$5:$IP$5,Q26,Stock!$D$340:$IP$340),SUMIF(Stock!$D$4:$IP$4,P26,Stock!$D$340:$IP$340))),SUMIF(Stock!$D$4:$IP$4,P26,Stock!$D$340:$IP$340))) -> 100 | T26: =R26-S26 -> 0 | U26: =IF(AND(P26="",Q26=""),"",IF(Q26<>"",IF(COUNTIFS(Stock!$D$4:$IP$4,P26,Stock!$D$5:$IP$5,Q26)>0,SUMIFS(Stock!$D$32:$IP$32,Stock!$D$4:$IP$4,P26,Stock!$D$5:$IP$5,Q26),IF(COUNTIF(Stock!$D$5:$IP$5,Q26)>0,SUMIF(Stock!$D$5:$IP$5,Q26,Stock!$D$32:$IP$32),SUMIF(Stock!$D$4:$IP$4,P26,Stock!$D$32:$IP$32))),SUMIF(Stock!$D$4:$IP$4,P26,Stock!$D$32:$IP$32))) -> 300 | V26: PC1065 | X26: {=IF(NOT(ISNUMBER($W26)),"CHECK",IF(OR(AND(TRIM($Q26&"")<>"",INDEX(Stock!$EW$5:$FU$5,$W26)=$Q26),INDEX(Stock!$EW$4:$FU$4,$W26)=$P26),"OK","CHECK"))} -> CHECK
