Workbook

Sheet CHALLAN
A1: G & G ENTERPRISES
A2: (Importer & Exporter)
G3: Address line (redacted)
G4: New Delhi-XXXXXX
G5: M-XXXXXXXXXX
A7: DELIVERY CHALLAN
F9: Dated.: | G9: 03.04.10
A10: To, | F10: Challan # : | G10: GG/001/10-11
A11: Dealer-004
A12: Address line (redacted)
A13: Address line (redacted)
A15: Dear Sir,
A17: According to instructions we are sending followng goods. Please acknowledge the same and after your
A18: acknowledgement we will issue you sales invoice.
A20: S.No. | B20: Description | D20: Nos of ctn | E20: Nos of PCs/ctn | F20: Qty in PCs | G20: Price | H20: Amount
B22: COMPANY-A CONDENSER
A24: 1- | B24: ZEN DELHI-R12 | C24: PC-86270R12 | D24: 3 | E24: 5 | F24: =+E24*D24 | G24: 1 | H24: =+G24*F24
A26: 2- | B26: ZEN DELHI-R134A | C26: PC-86270R134A | D26: 3 | E26: 5 | F26: =+E26*D26 | G26: 1 | H26: =+G26*F26
B28: COMPANY-A HPLP
A29: 3- | B29: PALIO | C29: PC-1100 | D29: 1 | E29: 1*25 | F29: 25 | G29: 1 | H29: =+G29*F29
C34: TOTAL | D34: =SUM(D24:D33) | F34: =SUM(F24:F33) | H34: =SUM(H24:H33)
D37: for | E37: G & G Enterprises
E40: Auth. Sign
A58: DELIVERY CHALLAN
A61: To, | F61: Dated.: | G61: 03.04.10
A62: Dealer-009 | C62: ATTN: Contact-001 | F62: Challan # : | G62: GG/002/10-11
A63: Address line (redacted)
A64: Address line (redacted)
A66: Dear Sir,
A68: According to instructions we are sending followng goods. Please acknowledge the same and after your
A69: acknowledgement we will issue you sales invoice.
A71: S.No. | B71: Description | D71: Nos of ctn | E71: Nos of PCs/ctn | F71: Qty in PCs | G71: Price | H71: Amount
B73: COMP OIL
A74: 1- | B74: ND-8 | C74: 250ML | D74: 29 | E74: 24 | F74: =+E74*D74 | G74: 1 | H74: =+G74*F74
C79: TOTAL | D79: =SUM(D73:D78) | H79: =SUM(H73:H78)
A81: PAYMENT TERMS: WITHIN 15 DAYS.
D82: for | E82: G & G Enterprises
E85: Auth. Sign
A104: DELIVERY CHALLAN
A106: To, | F106: Dated.: | G106: 06.04.10
...

Sheet Recon
C1: Challan (pcs) | D1: Stock (Sold) | E1: Gap | F1: Total Available | J1: Coooling Coil | L1: Challan (pcs) | M1: Stock (Sold) | N1: Gap | O1: Total Available | Q1: R.Drier | S1: Challan (pcs) | T1: Stock (Sold) | U1: Gap | V1: Total Available | X1: Switches | Z1: Challan (pcs) | AA1: Stock (Sold) | AB1: Gap | AC1: Total Available | AE1: Blowers | AG1: Challan (pcs) | AH1: Stock (Sold) | AI1: Gap | AJ1: Total Available | AK1: Match key | AM1: SEAL | AO1: Challan (pcs) | AP1: Stock (Sold) | AQ1: Gap | AR1: Total Available | AT1: TOKODEN FAN | AV1: Challan (pcs) | AW1: Stock (Sold) | AX1: Gap | AY1: Total Available | AZ1: Match key | BB1: EXPENSION VALVE | BD1: Challan (pcs) | BE1: Stock (Sold) | BF1: Gap | BG1: Total Available | BH1: Match key | BJ1: COOLING COIL (PREMIUM) | BL1: Challan (pcs) | BM1: Stock (Sold) | BN1: Gap | BO1: Total Available | BP1: Match key | BR1: COMPRESSOR / HOSE / TAPE / GAS | BT1: Challan (pcs) | BU1: Stock (Sold) | BV1: Gap | BW1: Total Available | BY1: SDN COMPRESSOR CLUTCH PARTS | CA1: Challan (pcs) | CB1: Stock (Sold) | CC1: Gap | CD1: Total Available | CF1: OIL & AGRICULTURAL HOSE (Part 3) | CG1: Stock unit | CH1: Challan (pcs) | CI1: Stock (Sold) | CJ1: Gap | CK1: Total Available | CL1: Stock header (guard)
A2: ACCENT CRD-I | B2: PC-86064 | C2: 88 | D2: {=IF($A2="","",IF(TRIM(INDEX('Part 1'!$F$3:$CZ$3,1,ROW()-1))=TRIM($A2),INDEX('Part 1'!$F$386:$CZ$386,1,ROW()-1),"CHECK"))} -> 100 | E2: =IF(OR($A2="",$D2="CHECK",$D2=""),"",$C2-$D2) -> -12 | F2: {=IF($A2="","",IF(TRIM(INDEX('Part 1'!$F$3:$CZ$3,1,ROW()-1))=TRIM($A2),INDEX('Part 1'!$F$38:$CZ$38,1,ROW()-1),"CHECK"))} -> 100 | J2: A6 | K2: PC-A6 | L2: 715 | M2: {=IF($J2="","",IF(TRIM(INDEX('Part 1'!$CS$3:$EQ$3,1,ROW()-1))=TRIM($J2),INDEX('Part 1'!$CS$386:$EQ$386,1,ROW()-1),"CHECK"))} -> 702 | N2: =IF(OR($J2="",$M2="CHECK",$M2=""),"",$L2-$M2) -> 13 | O2: {=IF($J2="","",IF(TRIM(INDEX('Part 1'!$CS$3:$EQ$3,1,ROW()-1))=TRIM($J2),INDEX('Part 1'!$CS$38:$EQ$38,1,ROW()-1),"CHECK"))} -> 1008 | Q2: Ambasdor/ BOlero | R2: PC-8120 | S2: 325 | T2: {=IF($Q2="","",IF(TRIM(INDEX('Part 1'!$GD$3:$HB$3,1,ROW()-1))=TRIM($Q2),INDEX('Part 1'!$GD$386:$HB$386,1,ROW()-1),"CHECK"))} -> 325 | U2: =IF(OR($Q2="",$T2="CHECK",$T2=""),"",$S2-$T2) -> 0 | V2: {=IF($Q2="","",IF(TRIM(INDEX('Part 1'!$GD$3:$HB$3,1,ROW()-1))=TRIM($Q2),INDEX('Part 1'!$GD$38:$HB$38,1,ROW()-1),"CHECK"))} -> 750 | X2: CONCORD A/C SWITCH | Z2: 2 | AA2: {=IF($X2="","",IF(TRIM(INDEX('Part 1'!$FG$3:$GC$3,1,ROW()-1))=TRIM($X2),INDEX('Part 1'!$FG$386:$GC$386,1,ROW()-1),"CHECK"))} -> 2 | AB2: =IF(OR($X2="",$AA2="CHECK",$AA2=""),"",$Z2-$AA2) -> 0 | AC2: {=IF($X2="","",IF(TRIM(INDEX('Part 1'!$FG$3:$GC$3,1,ROW()-1))=TRIM($X2),INDEX('Part 1'!$FG$38:$GC$38,1,ROW()-1),"CHECK"))} -> 0 | AE2: MICROBUS-Tubefin | AG2: 155 | AH2: {=IF($AE2="","",IF(TRIM(INDEX('Part 1'!$ER$3:$FF$3,1,ROW()-1))=TRIM($AE2),INDEX('Part 1'!$ER$386:$FF$386,1,ROW()-1),"CHECK"))} -> 155 | AI2: =IF(OR($AE2="",$AH2="CHECK",$AH2=""),"",ROUND($AG2-$AH2,2)) -> 0 | AJ2: {=IF($AE2="","",IF(TRIM(INDEX('Part 1'!$ER$3:$FF$3,1,ROW()-1))=TRIM($AE2),INDEX('Part 1'!$ER$38:$FF$38,1,ROW()-1),"CHECK"))} -> 155 | AK2: MICROBUS BLOWER | AM2: 507 | AN2: PC-7001A | AO2: 0 | AP2: {=IF($AM2="","",IF(TRIM(INDEX('Part 1'!$HC$3:$HT$3,1,ROW()-1))=TRIM($AM2),INDEX('Part 1'!$HC$386:$HT$386,1,ROW()-1),"CHECK"))} -> 0 | AQ2: =IF(OR($AM2="",$AP2="CHECK",$AP2=""),"",ROUND($AO2-$AP2,2)) -> 0 | AR2: {=IF($AM2="","",IF(TRIM(INDEX('Part 1'!$HC$3:$HT$3,1,ROW()-1))=TRIM($AM2),INDEX('Part 1'!$HC$38:$HT$38,1,ROW()-1),"CHECK"))} -> 0 | AT2: 10" Staight -80w | AU2: TST-8801 | AV2: 1020 | AW2: {=IF($AT2="","",IF(TRIM(INDEX('Part 1'!$HU$3:$IC$3,1,ROW()-1))=TRIM($AT2),INDEX('Part 1'!$HU$386:$IC$386,1,ROW()-1),"CHECK"))} -> 1030 | AX2: =IF(OR($AT2="",$AW2="CHECK",$AW2=""),"",ROUND($AV2-$AW2,2)) -> -10 | AY2: {=IF($AT2="","",IF(TRIM(INDEX('Part 1'!$HU$3:$IC$3,1,ROW()-1))=TRIM($AT2),INDEX('Part 1'!$HU$38:$IC$38,1,ROW()-1),"CHECK"))} -> 2000 | AZ2: 10" Staight -80w | BB2: TRAVERA / ACCENT | BC2: FK-C906 | BD2: 50 | BE2: {=IF($BB2="","",IF(TRIM(INDEX('Part 1'!$ID$3:$IP$3,1,ROW()-1))=TRIM($BB2),INDEX('Part 1'!$ID$386:$IP$386,1,ROW()-1),"CHECK"))} -> 50 | BF2: =IF(OR($BB2="",$BE2="CHECK",$BE2=""),"",ROUND($BD2-$BE2,2)) -> 0 | BG2: {=IF($BB2="","",IF(TRIM(INDEX('Part 1'!$ID$3:$IP$3,1,ROW()-1))=TRIM($BB2),INDEX('Part 1'!$ID$38:$IP$38,1,ROW()-1),"CHECK"))} -> 200 | BH2: TRAVERA / ACCENT | BJ2: ACCENT | BK2: PC-E420 | BL2: 70 | BM2: {=IF($BJ2="","",IF(TRIM(INDEX('Part 2'!$F$3:$AS$3,1,ROW()-1))=TRIM($BJ2),INDEX('Part 2'!$F$243:$AS$243,1,ROW()-1),"CHECK"))} -> 70 | BN2: =IF(OR($BJ2="",$BM2="CHECK",$BM2=""),"",ROUND($BL2-$BM2,2)) -> 0 | BO2: {=IF($BJ2="","",IF(TRIM(INDEX('Part 2'!$F$3:$AS$3,1,ROW()-1))=TRIM($BJ2),INDEX('Part 2'!$F$33:$AS$33,1,ROW()-1),"CHECK"))} -> 70 | BP2: ACCENT | BR2: compressor SM-5 | BS2: AT | BT2: 100 | BU2: =IF(TRIM('Part 2'!$AT$3&" "&'Part 2'!$AT$4)=TRIM($BR2),'Part 2'!$AT$243,"CHECK") -> 100 | BV2: =IF(OR($BR2="",$BU2="CHECK"),"",ROUND($BT2-$BU2,2)) -> 0 | BW2: =IF(TRIM('Part 2'!$AT$3&" "&'Part 2'!$AT$4)=TRIM($BR2),'Part 2'!$AT$33,"CHECK") -> 100 | BY2: PLATE HONDA | BZ2: SD-1001 | CA2: 60 | CB2: {=IF($BY2="","",IF(TRIM(INDEX('Part 2'!$BJ$3:$CZ$3,1,ROW()-1))=TRIM($BZ2),INDEX('Part 2'!$BJ$243:$CZ$243,1,ROW()-1),"CHECK"))} -> 60 | CC2: =IF(OR($BY2="",$CB2="CHECK"),"",ROUND($CA2-$CB2,2)) -> 0 | CD2: {=IF($BY2="","",IF(TRIM(INDEX('Part 2'!$BJ$3:$CZ$3,1,ROW()-1))=TRIM($BZ2),INDEX('Part 2'!$BJ$33:$CZ$33,1,ROW()-1),"CHECK"))} -> 60 | CF2: 1 LITR | CG2: PCS | CH2: 7464 | CI2: =IF(TRIM('Part 3'!$F$3&" "&'Part 3'!$F$4)=TRIM($CL2),'Part 3'!$F$57,"CHECK") -> 7464 | CJ2: =IF(OR($CH2="",$CI2="CHECK"),"",ROUND($CH2-$CI2,2)) -> 0 | CK2: =IF(TRIM('Part 3'!$F$3&" "&'Part 3'!$F$4)=TRIM($CL2),'Part 3'!$F$16,"CHECK") -> 12696 | CL2: 1 LITR PCS
A3: ACCENT-PETROL | B3: PC-86248 | C3: 101 | D3: {=IF($A3="","",IF(TRIM(INDEX('Part 1'!$F$3:$CZ$3,1,ROW()-1))=TRIM($A3),INDEX('Part 1'!$F$386:$CZ$386,1,ROW()-1),"CHECK"))} -> 101 | E3: =IF(OR($A3="",$D3="CHECK",$D3=""),"",$C3-$D3) -> 0 | F3: {=IF($A3="","",IF(TRIM(INDEX('Part 1'!$F$3:$CZ$3,1,ROW()-1))=TRIM($A3),INDEX('Part 1'!$F$38:$CZ$38,1,ROW()-1),"CHECK"))} -> 100 | J3: 848L MICROBUS COIL | L3: 0 | M3: {=IF($J3="","",IF(TRIM(INDEX('Part 1'!$CS$3:$EQ$3,1,ROW()-1))=TRIM($J3),INDEX('Part 1'!$CS$386:$EQ$386,1,ROW()-1),"CHECK"))} -> 0 | N3: =IF(OR($J3="",$M3="CHECK",$M3=""),"",$L3-$M3) -> 0 | O3: {=IF($J3="","",IF(TRIM(INDEX('Part 1'!$CS$3:$EQ$3,1,ROW()-1))=TRIM($J3),INDEX('Part 1'!$CS$38:$EQ$38,1,ROW()-1),"CHECK"))} -> 0 | Q3: AVEO | R3: PC-8797 | S3: 50 | T3: {=IF($Q3="","",IF(TRIM(INDEX('Part 1'!$GD$3:$HB$3,1,ROW()-1))=TRIM($Q3),INDEX('Part 1'!$GD$386:$HB$386,1,ROW()-1),"CHECK"))} -> 50 | U3: =IF(OR($Q3="",$T3="CHECK",$T3=""),"",$S3-$T3) -> 0 | V3: {=IF($Q3="","",IF(TRIM(INDEX('Part 1'!$GD$3:$HB$3,1,ROW()-1))=TRIM($Q3),INDEX('Part 1'!$GD$38:$HB$38,1,ROW()-1),"CHECK"))} -> 50 | X3: CONCORD RESISTANCE | Z3: 0 | AA3: {=IF($X3="","",IF(TRIM(INDEX('Part 1'!$FG$3:$GC$3,1,ROW()-1))=TRIM($X3),INDEX('Part 1'!$FG$386:$GC$386,1,ROW()-1),"CHECK"))} -> 0 | AB3: =IF(OR($X3="",$AA3="CHECK",$AA3=""),"",$Z3-$AA3) -> 0 | AC3: {=IF($X3="","",IF(TRIM(INDEX('Part 1'!$FG$3:$GC$3,1,ROW()-1))=TRIM($X3),INDEX('Part 1'!$FG$38:$GC$38,1,ROW()-1),"CHECK"))} -> 0 | AE3: MICROBUS-PF | AG3: 0 | AH3: {=IF($AE3="","",IF(TRIM(INDEX('Part 1'!$ER$3:$FF$3,1,ROW()-1))=TRIM($AE3),INDEX('Part 1'!$ER$386:$FF$386,1,ROW()-1),"CHECK"))} -> 0 | AI3: =IF(OR($AE3="",$AH3="CHECK",$AH3=""),"",ROUND($AG3-$AH3,2)) -> 0 | AJ3: {=IF($AE3="","",IF(TRIM(INDEX('Part 1'!$ER$3:$FF$3,1,ROW()-1))=TRIM($AE3),INDEX('Part 1'!$ER$38:$FF$38,1,ROW()-1),"CHECK"))} -> 0 | AM3: 508 | AN3: PC-7004A | AO3: 0 | AP3: {=IF($AM3="","",IF(TRIM(INDEX('Part 1'!$HC$3:$HT$3,1,ROW()-1))=TRIM($AM3),INDEX('Part 1'!$HC$386:$HT$386,1,ROW()-1),"CHECK"))} -> 0 | AQ3: =IF(OR($AM3="",$AP3="CHECK",$AP3=""),"",ROUND($AO3-$AP3,2)) -> 0 | AR3: {=IF($AM3="","",IF(TRIM(INDEX('Part 1'!$HC$3:$HT$3,1,ROW()-1))=TRIM($AM3),INDEX('Part 1'!$HC$38:$HT$38,1,ROW()-1),"CHECK"))} -> 0 | AT3: 10" 'S' 80w | AU3: TS-8805 | AV3: 751 | AW3: {=IF($AT3="","",IF(TRIM(INDEX('Part 1'!$HU$3:$IC$3,1,ROW()-1))=TRIM($AT3),INDEX('Part 1'!$HU$386:$IC$386,1,ROW()-1),"CHECK"))} -> 751 | AX3: =IF(OR($AT3="",$AW3="CHECK",$AW3=""),"",ROUND($AV3-$AW3,2)) -> 0 | AY3: {=IF($AT3="","",IF(TRIM(INDEX('Part 1'!$HU$3:$IC$3,1,ROW()-1))=TRIM($AT3),INDEX('Part 1'!$HU$38:$IC$38,1,ROW()-1),"CHECK"))} -> 2000 | AZ3: 10" 'S' 80w | BB3: SKODA | BC3: FK-1080 | BD3: 150 | BE3: {=IF($BB3="","",IF(TRIM(INDEX('Part 1'!$ID$3:$IP$3,1,ROW()-1))=TRIM($BB3),INDEX('Part 1'!$ID$386:$IP$386,1,ROW()-1),"CHECK"))} -> 150 | BF3: =IF(OR($BB3="",$BE3="CHECK",$BE3=""),"",ROUND($BD3-$BE3,2)) -> 0 | BG3: {=IF($BB3="","",IF(TRIM(INDEX('Part 1'!$ID$3:$IP$3,1,ROW()-1))=TRIM($BB3),INDEX('Part 1'!$ID$38:$IP$38,1,ROW()-1),"CHECK"))} -> 200 | BH3: SKODA | BJ3: AVEO | BK3: PC-E614 | BL3: 32 | BM3: {=IF($BJ3="","",IF(TRIM(INDEX('Part 2'!$F$3:$AS$3,1,ROW()-1))=TRIM($BJ3),INDEX('Part 2'!$F$243:$AS$243,1,ROW()-1),"CHECK"))} -> 32 | BN3: =IF(OR($BJ3="",$BM3="CHECK",$BM3=""),"",ROUND($BL3-$BM3,2)) -> 0 | BO3: {=IF($BJ3="","",IF(TRIM(INDEX('Part 2'!$F$3:$AS$3,1,ROW()-1))=TRIM($BJ3),INDEX('Part 2'!$F$33:$AS$33,1,ROW()-1),"CHECK"))} -> 79 | BP3: AVEO | BR3: SM-7 | BS3: AU | BT3: 600 | BU3: =IF(TRIM('Part 2'!$AU$3&" "&'Part 2'!$AU$4)=TRIM($BR3),'Part 2'!$AU$243,"CHECK") -> 566 | BV3: =IF(OR($BR3="",$BU3="CHECK"),"",ROUND($BT3-$BU3,2)) -> 34 | BW3: =IF(TRIM('Part 2'!$AU$3&" "&'Part 2'!$AU$4)=TRIM($BR3),'Part 2'!$AU$33,"CHECK") -> 600 | BY3: MAGNATTE COIL HONDA | BZ3: SD-1001A | CA3: 120 | CB3: {=IF($BY3="","",IF(TRIM(INDEX('Part 2'!$BJ$3:$CZ$3,1,ROW()-1))=TRIM($BZ3),INDEX('Part 2'!$BJ$243:$CZ$243,1,ROW()-1),"CHECK"))} -> 120 | CC3: =IF(OR($BY3="",$CB3="CHECK"),"",ROUND($CA3-$CB3,2)) -> 0 | CD3: {=IF($BY3="","",IF(TRIM(INDEX('Part 2'!$BJ$3:$CZ$3,1,ROW()-1))=TRIM($BZ3),INDEX('Part 2'!$BJ$33:$CZ$33,1,ROW()-1),"CHECK"))} -> 120 | CF3: 250G | CG3: PCS | CH3: 1704 | CI3: =IF(TRIM('Part 3'!$G$3&" "&'Part 3'!$G$4)=TRIM($CL3),'Part 3'!$G$57,"CHECK") -> 1704 | CJ3: =IF(OR($CH3="",$CI3="CHECK"),"",ROUND($CH3-$CI3,2)) -> 0 | CK3: =IF(TRIM('Part 3'!$G$3&" "&'Part 3'!$G$4)=TRIM($CL3),'Part 3'!$G$16,"CHECK") -> 1704 | CL3: 250G PCS
A4: ACCORD | C4: 0 | D4: {=IF($A4="","",IF(TRIM(INDEX('Part 1'!$F$3:$CZ$3,1,ROW()-1))=TRIM($A4),INDEX('Part 1'!$F$386:$CZ$386,1,ROW()-1),"CHECK"))} -> 0 | E4: =IF(OR($A4="",$D4="CHECK",$D4=""),"",$C4-$D4) -> 0 | F4: {=IF($A4="","",IF(TRIM(INDEX('Part 1'!$F$3:$CZ$3,1,ROW()-1))=TRIM($A4),INDEX('Part 1'!$F$38:$CZ$38,1,ROW()-1),"CHECK"))} -> 0 | J4: Accent | K4: PC-055R | L4: 258 | M4: {=IF($J4="","",IF(TRIM(INDEX('Part 1'!$CS$3:$EQ$3,1,ROW()-1))=TRIM($J4),INDEX('Part 1'!$CS$386:$EQ$386,1,ROW()-1),"CHECK"))} -> 258 | N4: =IF(OR($J4="",$M4="CHECK",$M4=""),"",$L4-$M4) -> 0 | O4: {=IF($J4="","",IF(TRIM(INDEX('Part 1'!$CS$3:$EQ$3,1,ROW()-1))=TRIM($J4),INDEX('Part 1'!$CS$38:$EQ$38,1,ROW()-1),"CHECK"))} -> 306 | Q4: BUS-UNI | R4: PC-61020 | S4: 460 | T4: {=IF($Q4="","",IF(TRIM(INDEX('Part 1'!$GD$3:$HB$3,1,ROW()-1))=TRIM($Q4),INDEX('Part 1'!$GD$386:$HB$386,1,ROW()-1),"CHECK"))} -> 460 | U4: =IF(OR($Q4="",$T4="CHECK",$T4=""),"",$S4-$T4) -> 0 | V4: {=IF($Q4="","",IF(TRIM(INDEX('Part 1'!$GD$3:$HB$3,1,ROW()-1))=TRIM($Q4),INDEX('Part 1'!$GD$38:$HB$38,1,ROW()-1),"CHECK"))} -> 460 | X4: esteem r12 ordanary | Y4: PC-1052 | Z4: 0 | AA4: {=IF($X4="","",IF(TRIM(INDEX('Part 1'!$FG$3:$GC$3,1,ROW()-1))=TRIM($X4),INDEX('Part 1'!$FG$386:$GC$386,1,ROW()-1),"CHECK"))} -> 0 | AB4: =IF(OR($X4="",$AA4="CHECK",$AA4=""),"",$Z4-$AA4) -> 0 | AC4: {=IF($X4="","",IF(TRIM(INDEX('Part 1'!$FG$3:$GC$3,1,ROW()-1))=TRIM($X4),INDEX('Part 1'!$FG$38:$GC$38,1,ROW()-1),"CHECK"))} -> 800 | AE4: MiniBus | AG4: 66 | AH4: {=IF($AE4="","",IF(TRIM(INDEX('Part 1'!$ER$3:$FF$3,1,ROW()-1))=TRIM($AE4),INDEX('Part 1'!$ER$386:$FF$386,1,ROW()-1),"CHECK"))} -> 66 | AI4: =IF(OR($AE4="",$AH4="CHECK",$AH4=""),"",ROUND($AG4-$AH4,2)) -> 0 | AJ4: {=IF($AE4="","",IF(TRIM(INDEX('Part 1'!$ER$3:$FF$3,1,ROW()-1))=TRIM($AE4),INDEX('Part 1'!$ER$38:$FF$38,1,ROW()-1),"CHECK"))} -> 66 | AK4: MINIBUS | AM4: 507 single seal | AN4: PC-7053A | AO4: 600 | AP4: {=IF($AM4="","",IF(TRIM(INDEX('Part 1'!$HC$3:$HT$3,1,ROW()-1))=TRIM($AM4),INDEX('Part 1'!$HC$386:$HT$386,1,ROW()-1),"CHECK"))} -> 600 | AQ4: =IF(OR($AM4="",$AP4="CHECK",$AP4=""),"",ROUND($AO4-$AP4,2)) -> 0 | AR4: {=IF($AM4="","",IF(TRIM(INDEX('Part 1'!$HC$3:$HT$3,1,ROW()-1))=TRIM($AM4),INDEX('Part 1'!$HC$38:$HT$38,1,ROW()-1),"CHECK"))} -> 3000 | AT4: 12" Staight -80w | AU4: TST-8801-A | AV4: 635 | AW4: {=IF($AT4="","",IF(TRIM(INDEX('Part 1'!$HU$3:$IC$3,1,ROW()-1))=TRIM($AT4),INDEX('Part 1'!$HU$386:$IC$386,1,ROW()-1),"CHECK"))} -> 635 | AX4: =IF(OR($AT4="",$AW4="CHECK",$AW4=""),"",ROUND($AV4-$AW4,2)) -> 0 | AY4: {=IF($AT4="","",IF(TRIM(INDEX('Part 1'!$HU$3:$IC$3,1,ROW()-1))=TRIM($AT4),INDEX('Part 1'!$HU$38:$IC$38,1,ROW()-1),"CHECK"))} -> 2000 | AZ4: 12" Staight -80w | BB4: WR/ALTO | BC4: FK-1089D | BD4: 0 | BE4: {=IF($BB4="","",IF(TRIM(INDEX('Part 1'!$ID$3:$IP$3,1,ROW()-1))=TRIM($BB4),INDEX('Part 1'!$ID$386:$IP$386,1,ROW()-1),"CHECK"))} -> 0 | BF4: =IF(OR($BB4="",$BE4="CHECK",$BE4=""),"",ROUND($BD4-$BE4,2)) -> 0 | BG4: {=IF($BB4="","",IF(TRIM(INDEX('Part 1'!$ID$3:$IP$3,1,ROW()-1))=TRIM($BB4),INDEX('Part 1'!$ID$38:$IP$38,1,ROW()-1),"CHECK"))} -> 200 | BH4: WR/ALTO | BJ4: BALENO | BK4: PC-E407 | BL4: 126 | BM4: {=IF($BJ4="","",IF(TRIM(INDEX('Part 2'!$F$3:$AS$3,1,ROW()-1))=TRIM($BJ4),INDEX('Part 2'!$F$243:$AS$243,1,ROW()-1),"CHECK"))} -> 126 | BN4: =IF(OR($BJ4="",$BM4="CHECK",$BM4=""),"",ROUND($BL4-$BM4,2)) -> 0 | BO4: {=IF($BJ4="","",IF(TRIM(INDEX('Part 2'!$F$3:$AS$3,1,ROW()-1))=TRIM($BJ4),INDEX('Part 2'!$F$33:$AS$33,1,ROW()-1),"CHECK"))} -> 128 | BP4: BALENO | BR4: SM-8 | BS4: AV | BT4: 200 | BU4: =IF(TRIM('Part 2'!$AV$3&" "&'Part 2'!$AV$4)=TRIM($BR4),'Part 2'!$AV$243,"CHECK") -> 234 | BV4: =IF(OR($BR4="",$BU4="CHECK"),"",ROUND($BT4-$BU4,2)) -> -34 | BW4: =IF(TRIM('Part 2'!$AV$3&" "&'Part 2'!$AV$4)=TRIM($BR4),'Part 2'!$AV$33,"CHECK") -> 200 | BY4: PULLEY PULL HONDA | BZ4: SD-1001B | CA4: 48 | CB4: {=IF($BY4="","",IF(TRIM(INDEX('Part 2'!$BJ$3:$CZ$3,1,ROW()-1))=TRIM($BZ4),INDEX('Part 2'!$BJ$243:$CZ$243,1,ROW()-1),"CHECK"))} -> 48 | CC4: =IF(OR($BY4="",$CB4="CHECK"),"",ROUND($CA4-$CB4,2)) -> 0 | CD4: {=IF($BY4="","",IF(TRIM(INDEX('Part 2'!$BJ$3:$CZ$3,1,ROW()-1))=TRIM($BZ4),INDEX('Part 2'!$BJ$33:$CZ$33,1,ROW()-1),"CHECK"))} -> 48 | CF4: 4 LTR | CG4: BOTTLE | CH4: 504 | CI4: =IF(TRIM('Part 3'!$H$3&" "&'Part 3'!$H$4)=TRIM($CL4),'Part 3'!$H$57,"CHECK") -> 504 | CJ4: =IF(OR($CH4="",$CI4="CHECK"),"",ROUND($CH4-$CI4,2)) -> 0 | CK4: =IF(TRIM('Part 3'!$H$3&" "&'Part 3'!$H$4)=TRIM($CL4),'Part 3'!$H$16,"CHECK") -> 504 | CL4: 4 LTR BOTTLE
A5: AMBASDOR | B5: PC-86041 | C5: 150 | D5: {=IF($A5="","",IF(TRIM(INDEX('Part 1'!$F$3:$CZ$3,1,ROW()-1))=TRIM($A5),INDEX('Part 1'!$F$386:$CZ$386,1,ROW()-1),"CHECK"))} -> 150 | E5: =IF(OR($A5="",$D5="CHECK",$D5=""),"",$C5-$D5) -> 0 | F5: {=IF($A5="","",IF(TRIM(INDEX('Part 1'!$F$3:$CZ$3,1,ROW()-1))=TRIM($A5),INDEX('Part 1'!$F$38:$CZ$38,1,ROW()-1),"CHECK"))} -> 150 | J5: ACCORD | K5: PC-510 | L5: 0 | M5: {=IF($J5="","",IF(TRIM(INDEX('Part 1'!$CS$3:$EQ$3,1,ROW()-1))=TRIM($J5),INDEX('Part 1'!$CS$386:$EQ$386,1,ROW()-1),"CHECK"))} -> 0 | N5: =IF(OR($J5="",$M5="CHECK",$M5=""),"",$L5-$M5) -> 0 | O5: {=IF($J5="","",IF(TRIM(INDEX('Part 1'!$CS$3:$EQ$3,1,ROW()-1))=TRIM($J5),INDEX('Part 1'!$CS$38:$EQ$38,1,ROW()-1),"CHECK"))} -> 0 | Q5: Daewoo Cielo | R5: PC-8263 | S5: 20 | T5: {=IF($Q5="","",IF(TRIM(INDEX('Part 1'!$GD$3:$HB$3,1,ROW()-1))=TRIM($Q5),INDEX('Part 1'!$GD$386:$HB$386,1,ROW()-1),"CHECK"))} -> 20 | U5: =IF(OR($Q5="",$T5="CHECK",$T5=""),"",$S5-$T5) -> 0 | V5: {=IF($Q5="","",IF(TRIM(INDEX('Part 1'!$GD$3:$HB$3,1,ROW()-1))=TRIM($Q5),INDEX('Part 1'!$GD$38:$HB$38,1,ROW()-1),"CHECK"))} -> 0 | X5: ESTEEM-R12 / Accent | Y5: PC-1046 | Z5: 149 | AA5: {=IF($X5="","",IF(TRIM(INDEX('Part 1'!$FG$3:$GC$3,1,ROW()-1))=TRIM($X5),INDEX('Part 1'!$FG$386:$GC$386,1,ROW()-1),"CHECK"))} -> 149 | AB5: =IF(OR($X5="",$AA5="CHECK",$AA5=""),"",$Z5-$AA5) -> 0 | AC5: {=IF($X5="","",IF(TRIM(INDEX('Part 1'!$FG$3:$GC$3,1,ROW()-1))=TRIM($X5),INDEX('Part 1'!$FG$38:$GC$38,1,ROW()-1),"CHECK"))} -> 1000 | AE5: SK | AG5: 550 | AH5: {=IF($AE5="","",IF(TRIM(INDEX('Part 1'!$ER$3:$FF$3,1,ROW()-1))=TRIM($AE5),INDEX('Part 1'!$ER$386:$FF$386,1,ROW()-1),"CHECK"))} -> 550 | AI5: =IF(OR($AE5="",$AH5="CHECK",$AH5=""),"",ROUND($AG5-$AH5,2)) -> 0 | AJ5: {=IF($AE5="","",IF(TRIM(INDEX('Part 1'!$ER$3:$FF$3,1,ROW()-1))=TRIM($AE5),INDEX('Part 1'!$ER$38:$FF$38,1,ROW()-1),"CHECK"))} -> 550 | AK5: SK BLOWER | AM5: 507-AA | AN5: PC-7001A | AO5: 2250 | AP5: {=IF($AM5="","",IF(TRIM(INDEX('Part 1'!$HC$3:$HT$3,1,ROW()-1))=TRIM($AM5),INDEX('Part 1'!$HC$386:$HT$386,1,ROW()-1),"CHECK"))} -> 1950 | AQ5: =IF(OR($AM5="",$AP5="CHECK",$AP5=""),"",ROUND($AO5-$AP5,2)) -> 300 | AR5: {=IF($AM5="","",IF(TRIM(INDEX('Part 1'!$HC$3:$HT$3,1,ROW()-1))=TRIM($AM5),INDEX('Part 1'!$HC$38:$HT$38,1,ROW()-1),"CHECK"))} -> 3000 | AT5: 12" 'S' 80w | AU5: TS-8805-B | AV5: 985 | AW5: {=IF($AT5="","",IF(TRIM(INDEX('Part 1'!$HU$3:$IC$3,1,ROW()-1))=TRIM($AT5),INDEX('Part 1'!$HU$386:$IC$386,1,ROW()-1),"CHECK"))} -> 985 | AX5: =IF(OR($AT5="",$AW5="CHECK",$AW5=""),"",ROUND($AV5-$AW5,2)) -> 0 | AY5: {=IF($AT5="","",IF(TRIM(INDEX('Part 1'!$HU$3:$IC$3,1,ROW()-1))=TRIM($AT5),INDEX('Part 1'!$HU$38:$IC$38,1,ROW()-1),"CHECK"))} -> 2000 | AZ5: 12" 'S' 80w | BB5: OPEL / INDICA BEHR C/ SCORPIO | BC5: FK-1181 | BD5: 200 | BE5: {=IF($BB5="","",IF(TRIM(INDEX('Part 1'!$ID$3:$IP$3,1,ROW()-1))=TRIM($BB5),INDEX('Part 1'!$ID$386:$IP$386,1,ROW()-1),"CHECK"))} -> 200 | BF5: =IF(OR($BB5="",$BE5="CHECK",$BE5=""),"",ROUND($BD5-$BE5,2)) -> 0 | BG5: {=IF($BB5="","",IF(TRIM(INDEX('Part 1'!$ID$3:$IP$3,1,ROW()-1))=TRIM($BB5),INDEX('Part 1'!$ID$38:$IP$38,1,ROW()-1),"CHECK"))} -> 200 | BH5: OPEL / INDICA BEHR C/ SCORPIO | BJ5: CAMRY | BK5: PC-E533 | BL5: 24 | BM5: {=IF($BJ5="","",IF(TRIM(INDEX('Part 2'!$F$3:$AS$3,1,ROW()-1))=TRIM($BJ5),INDEX('Part 2'!$F$243:$AS$243,1,ROW()-1),"CHECK"))} -> 24 | BN5: =IF(OR($BJ5="",$BM5="CHECK",$BM5=""),"",ROUND($BL5-$BM5,2)) -> 0 | BO5: {=IF($BJ5="","",IF(TRIM(INDEX('Part 2'!$F$3:$AS$3,1,ROW()-1))=TRIM($BJ5),INDEX('Part 2'!$F$33:$AS$33,1,ROW()-1),"CHECK"))} -> 58 | BP5: CAMRY | BR5: SM-10 | BS5: AW | BT5: 110 | BU5: =IF(TRIM('Part 2'!$AW$3&" "&'Part 2'!$AW$4)=TRIM($BR5),'Part 2'!$AW$243,"CHECK") -> 100 | BV5: =IF(OR($BR5="",$BU5="CHECK"),"",ROUND($BT5-$BU5,2)) -> 10 | BW5: =IF(TRIM('Part 2'!$AW$3&" "&'Part 2'!$AW$4)=TRIM($BR5),'Part 2'!$AW$33,"CHECK") -> 100 | BY5: PLATE HUB SONATA | BZ5: SD-1002 | CA5: 60 | CB5: {=IF($BY5="","",IF(TRIM(INDEX('Part 2'!$BJ$3:$CZ$3,1,ROW()-1))=TRIM($BZ5),INDEX('Part 2'!$BJ$243:$CZ$243,1,ROW()-1),"CHECK"))} -> 60 | CC5: =IF(OR($BY5="",$CB5="CHECK"),"",ROUND($CA5-$CB5,2)) -> 0 | CD5: {=IF($BY5="","",IF(TRIM(INDEX('Part 2'!$BJ$3:$CZ$3,1,ROW()-1))=TRIM($BZ5),INDEX('Part 2'!$BJ$33:$CZ$33,1,ROW()-1),"CHECK"))} -> 60 | CF5: 20 LTR | CG5: DRUM | CH5: 30 | CI5: =IF(TRIM('Part 3'!$I$3&" "&'Part 3'!$I$4)=TRIM($CL5),'Part 3'!$I$57,"CHECK") -> 20 | CJ5: =IF(OR($CH5="",$CI5="CHECK"),"",ROUND($CH5-$CI5,2)) -> 10 | CK5: =IF(TRIM('Part 3'!$I$3&" "&'Part 3'!$I$4)=TRIM($CL5),'Part 3'!$I$16,"CHECK") -> 30 | CL5: 20 LTR DRUM
A6: AVEO | B6: PC-86177 | C6: 67 | D6: {=IF($A6="","",IF(TRIM(INDEX('Part 1'!$F$3:$CZ$3,1,ROW()-1))=TRIM($A6),INDEX('Part 1'!$F$386:$CZ$386,1,ROW()-1),"CHECK"))} -> 65 | E6: =IF(OR($A6="",$D6="CHECK",$D6=""),"",$C6-$D6) -> 2 | F6: {=IF($A6="","",IF(TRIM(INDEX('Part 1'!$F$3:$CZ$3,1,ROW()-1))=TRIM($A6),INDEX('Part 1'!$F$38:$CZ$38,1,ROW()-1),"CHECK"))} -> 100 | J6: Baleno | K6: PC-142R | L6: 52 | M6: {=IF($J6="","",IF(TRIM(INDEX('Part 1'!$CS$3:$EQ$3,1,ROW()-1))=TRIM($J6),INDEX('Part 1'!$CS$386:$EQ$386,1,ROW()-1),"CHECK"))} -> 52 | N6: =IF(OR($J6="",$M6="CHECK",$M6=""),"",$L6-$M6) -> 0 | O6: {=IF($J6="","",IF(TRIM(INDEX('Part 1'!$CS$3:$EQ$3,1,ROW()-1))=TRIM($J6),INDEX('Part 1'!$CS$38:$EQ$38,1,ROW()-1),"CHECK"))} -> 84 | Q6: DESICCANT FILTER/DRIER | S6: 199 | T6: {=IF($Q6="","",IF(TRIM(INDEX('Part 1'!$GD$3:$HB$3,1,ROW()-1))=TRIM($Q6),INDEX('Part 1'!$GD$386:$HB$386,1,ROW()-1),"CHECK"))} -> 200 | U6: =IF(OR($Q6="",$T6="CHECK",$T6=""),"",$S6-$T6) -> -1 | V6: {=IF($Q6="","",IF(TRIM(INDEX('Part 1'!$GD$3:$HB$3,1,ROW()-1))=TRIM($Q6),INDEX('Part 1'!$GD$38:$HB$38,1,ROW()-1),"CHECK"))} -> 1200 | X6: ESTEEM-R134/Lancer | Y6: PC-1042A & 1044A | Z6: 300 | AA6: {=IF($X6="","",IF(TRIM(INDEX('Part 1'!$FG$3:$GC$3,1,ROW()-1))=TRIM($X6),INDEX('Part 1'!$FG$386:$GC$386,1,ROW()-1),"CHECK"))} -> 300 | AB6: =IF(OR($X6="",$AA6="CHECK",$AA6=""),"",$Z6-$AA6) -> 0 | AC6: {=IF($X6="","",IF(TRIM(INDEX('Part 1'!$FG$3:$GC$3,1,ROW()-1))=TRIM($X6),INDEX('Part 1'!$FG$38:$GC$38,1,ROW()-1),"CHECK"))} -> 1200 | AE6: Concord-Elec, | AG6: 1554 | AH6: {=IF($AE6="","",IF(TRIM(INDEX('Part 1'!$ER$3:$FF$3,1,ROW()-1))=TRIM($AE6),INDEX('Part 1'!$ER$386:$FF$386,1,ROW()-1),"CHECK"))} -> 1534 | AI6: =IF(OR($AE6="",$AH6="CHECK",$AH6=""),"",ROUND($AG6-$AH6,2)) -> 20 | AJ6: {=IF($AE6="","",IF(TRIM(INDEX('Part 1'!$ER$3:$FF$3,1,ROW()-1))=TRIM($AE6),INDEX('Part 1'!$ER$38:$FF$38,1,ROW()-1),"CHECK"))} -> 1600 | AK6: CONCORD BLOWER | AM6: 508-AA | AN6: PC-7004A | AO6: 400 | AP6: {=IF($AM6="","",IF(TRIM(INDEX('Part 1'!$HC$3:$HT$3,1,ROW()-1))=TRIM($AM6),INDEX('Part 1'!$HC$386:$HT$386,1,ROW()-1),"CHECK"))} -> 250 | AQ6: =IF(OR($AM6="",$AP6="CHECK",$AP6=""),"",ROUND($AO6-$AP6,2)) -> 150 | AR6: {=IF($AM6="","",IF(TRIM(INDEX('Part 1'!$HC$3:$HT$3,1,ROW()-1))=TRIM($AM6),INDEX('Part 1'!$HC$38:$HT$38,1,ROW()-1),"CHECK"))} -> 1500 | AT6: 12" 'S' 100w BEHR | AU6: TS-8805-CB | AV6: 400 | AW6: {=IF($AT6="","",IF(TRIM(INDEX('Part 1'!$HU$3:$IC$3,1,ROW()-1))=TRIM($AT6),INDEX('Part 1'!$HU$386:$IC$386,1,ROW()-1),"CHECK"))} -> 410 | AX6: =IF(OR($AT6="",$AW6="CHECK",$AW6=""),"",ROUND($AV6-$AW6,2)) -> -10 | AY6: {=IF($AT6="","",IF(TRIM(INDEX('Part 1'!$HU$3:$IC$3,1,ROW()-1))=TRIM($AT6),INDEX('Part 1'!$HU$38:$IC$38,1,ROW()-1),"CHECK"))} -> 400 | AZ6: 12" 'S' 100w BEHR | BB6: HONDA CITY | BC6: FK-1034 | BD6: 50 | BE6: {=IF($BB6="","",IF(TRIM(INDEX('Part 1'!$ID$3:$IP$3,1,ROW()-1))=TRIM($BB6),INDEX('Part 1'!$ID$386:$IP$386,1,ROW()-1),"CHECK"))} -> 50 | BF6: =IF(OR($BB6="",$BE6="CHECK",$BE6=""),"",ROUND($BD6-$BE6,2)) -> 0 | BG6: {=IF($BB6="","",IF(TRIM(INDEX('Part 1'!$ID$3:$IP$3,1,ROW()-1))=TRIM($BB6),INDEX('Part 1'!$ID$38:$IP$38,1,ROW()-1),"CHECK"))} -> 200 | BH6: HONDA CITY | BJ6: CORROLA | BK6: PC-E443 | BL6: 108 | BM6: {=IF($BJ6="","",IF(TRIM(INDEX('Part 2'!$F$3:$AS$3,1,ROW()-1))=TRIM($BJ6),INDEX('Part 2'!$F$243:$AS$243,1,ROW()-1),"CHECK"))} -> 108 | BN6: =IF(OR($BJ6="",$BM6="CHECK",$BM6=""),"",ROUND($BL6-$BM6,2)) -> 0 | BO6: {=IF($BJ6="","",IF(TRIM(INDEX('Part 2'!$F$3:$AS$3,1,ROW()-1))=TRIM($BJ6),INDEX('Part 2'!$F$33:$AS$33,1,ROW()-1),"CHECK"))} -> 109 | BP6: CORROLA | BR6: COMP BACK PLATE 505/507-F | BS6: AX | BT6: 400 | BU6: =IF(TRIM('Part 2'!$AX$3&" "&'Part 2'!$AX$4)=TRIM($BR6),'Part 2'!$AX$243,"CHECK") -> 400 | BV6: =IF(OR($BR6="",$BU6="CHECK"),"",ROUND($BT6-$BU6,2)) -> 0 | BW6: =IF(TRIM('Part 2'!$AX$3&" "&'Part 2'!$AX$4)=TRIM($BR6),'Part 2'!$AX$33,"CHECK") -> 600 | BY6: MAGNETIC COIL SONATA | BZ6: SD-1002A | CA6: 150 | CB6: {=IF($BY6="","",IF(TRIM(INDEX('Part 2'!$BJ$3:$CZ$3,1,ROW()-1))=TRIM($BZ6),INDEX('Part 2'!$BJ$243:$CZ$243,1,ROW()-1),"CHECK"))} -> 150 | CC6: =IF(OR($BY6="",$CB6="CHECK"),"",ROUND($CA6-$CB6,2)) -> 0 | CD6: {=IF($BY6="","",IF(TRIM(INDEX('Part 2'!$BJ$3:$CZ$3,1,ROW()-1))=TRIM($BZ6),INDEX('Part 2'!$BJ$33:$CZ$33,1,ROW()-1),"CHECK"))} -> 150 | CF6: AGRICULTURL HOSE (weight) - not reconcilable, see note | CG6: KG | CI6: =IF(TRIM('Part 3'!$J$3&" "&'Part 3'!$J$4)=TRIM($CL6),'Part 3'!$J$57,"CHECK") -> 1350 | CJ6: =IF(OR($CH6="",$CI6="CHECK"),"",ROUND($CH6-$CI6,2)) | CK6: =IF(TRIM('Part 3'!$J$3&" "&'Part 3'!$J$4)=TRIM($CL6),'Part 3'!$J$16,"CHECK") -> 1350 | CL6: AGRICULTURL HOSE KG
A7: A-STAR | B7: PC-86274 | C7: 25 | D7: {=IF($A7="","",IF(TRIM(INDEX('Part 1'!$F$3:$CZ$3,1,ROW()-1))=TRIM($A7),INDEX('Part 1'!$F$386:$CZ$386,1,ROW()-1),"CHECK"))} -> 25 | E7: =IF(OR($A7="",$D7="CHECK",$D7=""),"",$C7-$D7) -> 0 | F7: {=IF($A7="","",IF(TRIM(INDEX('Part 1'!$F$3:$CZ$3,1,ROW()-1))=TRIM($A7),INDEX('Part 1'!$F$38:$CZ$38,1,ROW()-1),"CHECK"))} -> 50 | J7: BOlero R134a | K7: PC-8095 | L7: 90 | M7: {=IF($J7="","",IF(TRIM(INDEX('Part 1'!$CS$3:$EQ$3,1,ROW()-1))=TRIM($J7),INDEX('Part 1'!$CS$386:$EQ$386,1,ROW()-1),"CHECK"))} -> 90 | N7: =IF(OR($J7="",$M7="CHECK",$M7=""),"",$L7-$M7) -> 0 | O7: {=IF($J7="","",IF(TRIM(INDEX('Part 1'!$CS$3:$EQ$3,1,ROW()-1))=TRIM($J7),INDEX('Part 1'!$CS$38:$EQ$38,1,ROW()-1),"CHECK"))} -> 125 | Q7: Esteem-R12 | R7: PC-8005 | S7: 4800 | T7: {=IF($Q7="","",IF(TRIM(INDEX('Part 1'!$GD$3:$HB$3,1,ROW()-1))=TRIM($Q7),INDEX('Part 1'!$GD$386:$HB$386,1,ROW()-1),"CHECK"))} -> 4800 | U7: =IF(OR($Q7="",$T7="CHECK",$T7=""),"",$S7-$T7) -> 0 | V7: {=IF($Q7="","",IF(TRIM(INDEX('Part 1'!$GD$3:$HB$3,1,ROW()-1))=TRIM($Q7),INDEX('Part 1'!$GD$38:$HB$38,1,ROW()-1),"CHECK"))} -> 7500 | X7: HONDA CITY | Y7: PC-1045B | Z7: 0 | AA7: {=IF($X7="","",IF(TRIM(INDEX('Part 1'!$FG$3:$GC$3,1,ROW()-1))=TRIM($X7),INDEX('Part 1'!$FG$386:$GC$386,1,ROW()-1),"CHECK"))} -> 0 | AB7: =IF(OR($X7="",$AA7="CHECK",$AA7=""),"",$Z7-$AA7) -> 0 | AC7: {=IF($X7="","",IF(TRIM(INDEX('Part 1'!$FG$3:$GC$3,1,ROW()-1))=TRIM($X7),INDEX('Part 1'!$FG$38:$GC$38,1,ROW()-1),"CHECK"))} -> 200 | AE7: CONCORD-AL-GREY | AG7: 162 | AH7: {=IF($AE7="","",IF(TRIM(INDEX('Part 1'!$ER$3:$FF$3,1,ROW()-1))=TRIM($AE7),INDEX('Part 1'!$ER$386:$FF$386,1,ROW()-1),"CHECK"))} -> 33 | AI7: =IF(OR($AE7="",$AH7="CHECK",$AH7=""),"",ROUND($AG7-$AH7,2)) -> 129 | AJ7: {=IF($AE7="","",IF(TRIM(INDEX('Part 1'!$ER$3:$FF$3,1,ROW()-1))=TRIM($AE7),INDEX('Part 1'!$ER$38:$FF$38,1,ROW()-1),"CHECK"))} -> 0 | AM7: BOLERO | AN7: PC-7237 | AO7: 680 | AP7: {=IF($AM7="","",IF(TRIM(INDEX('Part 1'!$HC$3:$HT$3,1,ROW()-1))=TRIM($AM7),INDEX('Part 1'!$HC$386:$HT$386,1,ROW()-1),"CHECK"))} -> 680 | AQ7: =IF(OR($AM7="",$AP7="CHECK",$AP7=""),"",ROUND($AO7-$AP7,2)) -> 0 | AR7: {=IF($AM7="","",IF(TRIM(INDEX('Part 1'!$HC$3:$HT$3,1,ROW()-1))=TRIM($AM7),INDEX('Part 1'!$HC$38:$HT$38,1,ROW()-1),"CHECK"))} -> 700 | AT7: 14" Staight -80w | AU7: TST-8801-B | AV7: 256 | AW7: {=IF($AT7="","",IF(TRIM(INDEX('Part 1'!$HU$3:$IC$3,1,ROW()-1))=TRIM($AT7),INDEX('Part 1'!$HU$386:$IC$386,1,ROW()-1),"CHECK"))} -> 256 | AX7: =IF(OR($AT7="",$AW7="CHECK",$AW7=""),"",ROUND($AV7-$AW7,2)) -> 0 | AY7: {=IF($AT7="","",IF(TRIM(INDEX('Part 1'!$HU$3:$IC$3,1,ROW()-1))=TRIM($AT7),INDEX('Part 1'!$HU$38:$IC$38,1,ROW()-1),"CHECK"))} -> 400 | AZ7: 14" Staight -80w | BB7: LANCER MMC | BC7: FK-1031B | BD7: 0 | BE7: {=IF($BB7="","",IF(TRIM(INDEX('Part 1'!$ID$3:$IP$3,1,ROW()-1))=TRIM($BB7),INDEX('Part 1'!$ID$386:$IP$386,1,ROW()-1),"CHECK"))} -> 0 | BF7: =IF(OR($BB7="",$BE7="CHECK",$BE7=""),"",ROUND($BD7-$BE7,2)) -> 0 | BG7: {=IF($BB7="","",IF(TRIM(INDEX('Part 1'!$ID$3:$IP$3,1,ROW()-1))=TRIM($BB7),INDEX('Part 1'!$ID$38:$IP$38,1,ROW()-1),"CHECK"))} -> 200 | BH7: LANCER MMC | BJ7: ESTEEM R 12 | BK7: PC-E406 | BL7: 204 | BM7: {=IF($BJ7="","",IF(TRIM(INDEX('Part 2'!$F$3:$AS$3,1,ROW()-1))=TRIM($BJ7),INDEX('Part 2'!$F$243:$AS$243,1,ROW()-1),"CHECK"))} -> 224 | BN7: =IF(OR($BJ7="",$BM7="CHECK",$BM7=""),"",ROUND($BL7-$BM7,2)) -> -20 | BO7: {=IF($BJ7="","",IF(TRIM(INDEX('Part 2'!$F$3:$AS$3,1,ROW()-1))=TRIM($BJ7),INDEX('Part 2'!$F$33:$AS$33,1,ROW()-1),"CHECK"))} -> 218 | BP7: ESTEEM R 12 | BR7: 505/507-O | BS7: AY | BT7: 180 | BU7: =IF(TRIM('Part 2'!$AY$3&" "&'Part 2'!$AY$4)=TRIM($BR7),'Part 2'!$AY$243,"CHECK") -> 195 | BV7: =IF(OR($BR7="",$BU7="CHECK"),"",ROUND($BT7-$BU7,2)) -> -15 | BW7: =IF(TRIM('Part 2'!$AY$3&" "&'Part 2'!$AY$4)=TRIM($BR7),'Part 2'!$AY$33,"CHECK") -> 600 | BY7: PULLEY PULL SONATA | BZ7: SD-1002B | CA7: 24 | CB7: {=IF($BY7="","",IF(TRIM(INDEX('Part 2'!$BJ$3:$CZ$3,1,ROW()-1))=TRIM($BZ7),INDEX('Part 2'!$BJ$243:$CZ$243,1,ROW()-1),"CHECK"))} -> 24 | CC7: =IF(OR($BY7="",$CB7="CHECK"),"",ROUND($CA7-$CB7,2)) -> 0 | CD7: {=IF($BY7="","",IF(TRIM(INDEX('Part 2'!$BJ$3:$CZ$3,1,ROW()-1))=TRIM($BZ7),INDEX('Part 2'!$BJ$33:$CZ$33,1,ROW()-1),"CHECK"))} -> 24 | CF7: AGRICULTURL HOSE (count) | CG7: ROLLS | CH7: 100 | CI7: =IF(TRIM('Part 3'!$K$3&" "&'Part 3'!$K$4)=TRIM($CL7),'Part 3'!$K$57,"CHECK") -> 100 | CJ7: =IF(OR($CH7="",$CI7="CHECK"),"",ROUND($CH7-$CI7,2)) -> 0 | CK7: =IF(TRIM('Part 3'!$K$3&" "&'Part 3'!$K$4)=TRIM($CL7),'Part 3'!$K$16,"CHECK") -> 100 | CL7: ROLLS
A8: BELANO | B8: PC-86242 | C8: 40 | D8: {=IF($A8="","",IF(TRIM(INDEX('Part 1'!$F$3:$CZ$3,1,ROW()-1))=TRIM($A8),INDEX('Part 1'!$F$386:$CZ$386,1,ROW()-1),"CHECK"))} -> 40 | E8: =IF(OR($A8="",$D8="CHECK",$D8=""),"",$C8-$D8) -> 0 | F8: {=IF($A8="","",IF(TRIM(INDEX('Part 1'!$F$3:$CZ$3,1,ROW()-1))=TRIM($A8),INDEX('Part 1'!$F$38:$CZ$38,1,ROW()-1),"CHECK"))} -> 0 | J8: Cielo | K8: PC-043R | L8: 12 | M8: {=IF($J8="","",IF(TRIM(INDEX('Part 1'!$CS$3:$EQ$3,1,ROW()-1))=TRIM($J8),INDEX('Part 1'!$CS$386:$EQ$386,1,ROW()-1),"CHECK"))} -> 12 | N8: =IF(OR($J8="",$M8="CHECK",$M8=""),"",$L8-$M8) -> 0 | O8: {=IF($J8="","",IF(TRIM(INDEX('Part 1'!$CS$3:$EQ$3,1,ROW()-1))=TRIM($J8),INDEX('Part 1'!$CS$38:$EQ$38,1,ROW()-1),"CHECK"))} -> 30 | Q8: Esteem-R134A | R8: PC-8006 | S8: 4600 | T8: {=IF($Q8="","",IF(TRIM(INDEX('Part 1'!$GD$3:$HB$3,1,ROW()-1))=TRIM($Q8),INDEX('Part 1'!$GD$386:$HB$386,1,ROW()-1),"CHECK"))} -> 4600 | U8: =IF(OR($Q8="",$T8="CHECK",$T8=""),"",$S8-$T8) -> 0 | V8: {=IF($Q8="","",IF(TRIM(INDEX('Part 1'!$GD$3:$HB$3,1,ROW()-1))=TRIM($Q8),INDEX('Part 1'!$GD$38:$HB$38,1,ROW()-1),"CHECK"))} -> 8500 | X8: INDICA R-134A-4 pin | Y8: PC-1066 | Z8: 1000 | AA8: {=IF($X8="","",IF(TRIM(INDEX('Part 1'!$FG$3:$GC$3,1,ROW()-1))=TRIM($X8),INDEX('Part 1'!$FG$386:$GC$386,1,ROW()-1),"CHECK"))} -> 1000 | AB8: =IF(OR($X8="",$AA8="CHECK",$AA8=""),"",$Z8-$AA8) -> 0 | AC8: {=IF($X8="","",IF(TRIM(INDEX('Part 1'!$FG$3:$GC$3,1,ROW()-1))=TRIM($X8),INDEX('Part 1'!$FG$38:$GC$38,1,ROW()-1),"CHECK"))} -> 1000 | AE8: CONCORD-AL-BEIGE | AG8: 0 | AH8: {=IF($AE8="","",IF(TRIM(INDEX('Part 1'!$ER$3:$FF$3,1,ROW()-1))=TRIM($AE8),INDEX('Part 1'!$ER$386:$FF$386,1,ROW()-1),"CHECK"))} -> 0 | AI8: =IF(OR($AE8="",$AH8="CHECK",$AH8=""),"",ROUND($AG8-$AH8,2)) -> 0 | AJ8: {=IF($AE8="","",IF(TRIM(INDEX('Part 1'!$ER$3:$FF$3,1,ROW()-1))=TRIM($AE8),INDEX('Part 1'!$ER$38:$FF$38,1,ROW()-1),"CHECK"))} -> 0 | AM8: Clelo | AN8: PC-7059A | AO8: 0 | AP8: {=IF($AM8="","",IF(TRIM(INDEX('Part 1'!$HC$3:$HT$3,1,ROW()-1))=TRIM($AM8),INDEX('Part 1'!$HC$386:$HT$386,1,ROW()-1),"CHECK"))} -> 0 | AQ8: =IF(OR($AM8="",$AP8="CHECK",$AP8=""),"",ROUND($AO8-$AP8,2)) -> 0 | AR8: {=IF($AM8="","",IF(TRIM(INDEX('Part 1'!$HC$3:$HT$3,1,ROW()-1))=TRIM($AM8),INDEX('Part 1'!$HC$38:$HT$38,1,ROW()-1),"CHECK"))} -> 100 | AT8: 14" 'S' 100w JPI | AU8: TS-8805-A | AV8: 305 | AW8: {=IF($AT8="","",IF(TRIM(INDEX('Part 1'!$HU$3:$IC$3,1,ROW()-1))=TRIM($AT8),INDEX('Part 1'!$HU$386:$IC$386,1,ROW()-1),"CHECK"))} -> 305 | AX8: =IF(OR($AT8="",$AW8="CHECK",$AW8=""),"",ROUND($AV8-$AW8,2)) -> 0 | AY8: {=IF($AT8="","",IF(TRIM(INDEX('Part 1'!$HU$3:$IC$3,1,ROW()-1))=TRIM($AT8),INDEX('Part 1'!$HU$38:$IC$38,1,ROW()-1),"CHECK"))} -> 200 | AZ8: 14" 'S' 100w JPI | BB8: SANTRO | BC8: FK-1023B | BD8: 50 | BE8: {=IF($BB8="","",IF(TRIM(INDEX('Part 1'!$ID$3:$IP$3,1,ROW()-1))=TRIM($BB8),INDEX('Part 1'!$ID$386:$IP$386,1,ROW()-1),"CHECK"))} -> 50 | BF8: =IF(OR($BB8="",$BE8="CHECK",$BE8=""),"",ROUND($BD8-$BE8,2)) -> 0 | BG8: {=IF($BB8="","",IF(TRIM(INDEX('Part 1'!$ID$3:$IP$3,1,ROW()-1))=TRIM($BB8),INDEX('Part 1'!$ID$38:$IP$38,1,ROW()-1),"CHECK"))} -> 400 | BH8: SANTRO | BJ8: ESTEEM R 134A | BK8: PC-E035 | BL8: 203 | BM8: {=IF($BJ8="","",IF(TRIM(INDEX('Part 2'!$F$3:$AS$3,1,ROW()-1))=TRIM($BJ8),INDEX('Part 2'!$F$243:$AS$243,1,ROW()-1),"CHECK"))} -> 207 | BN8: =IF(OR($BJ8="",$BM8="CHECK",$BM8=""),"",ROUND($BL8-$BM8,2)) -> -4 | BO8: {=IF($BJ8="","",IF(TRIM(INDEX('Part 2'!$F$3:$AS$3,1,ROW()-1))=TRIM($BJ8),INDEX('Part 2'!$F$33:$AS$33,1,ROW()-1),"CHECK"))} -> 207 | BP8: ESTEEM R 134A | BR8: 508/510-F | BS8: AZ | BT8: 50 | BU8: =IF(TRIM('Part 2'!$AZ$3&" "&'Part 2'!$AZ$4)=TRIM($BR8),'Part 2'!$AZ$243,"CHECK") -> 50 | BV8: =IF(OR($BR8="",$BU8="CHECK"),"",ROUND($BT8-$BU8,2)) -> 0 | BW8: =IF(TRIM('Part 2'!$AZ$3&" "&'Part 2'!$AZ$4)=TRIM($BR8),'Part 2'!$AZ$33,"CHECK") -> 250 | BY8: PLATE HUB QUALIS | BZ8: SD-1003 | CA8: 60 | CB8: {=IF($BY8="","",IF(TRIM(INDEX('Part 2'!$BJ$3:$CZ$3,1,ROW()-1))=TRIM($BZ8),INDEX('Part 2'!$BJ$243:$CZ$243,1,ROW()-1),"CHECK"))} -> 60 | CC8: =IF(OR($BY8="",$CB8="CHECK"),"",ROUND($CA8-$CB8,2)) -> 0 | CD8: {=IF($BY8="","",IF(TRIM(INDEX('Part 2'!$BJ$3:$CZ$3,1,ROW()-1))=TRIM($BZ8),INDEX('Part 2'!$BJ$33:$CZ$33,1,ROW()-1),"CHECK"))} -> 60
A9: BOLERO- R134A | B9: PC-86236 | C9: 105 | D9: {=IF($A9="","",IF(TRIM(INDEX('Part 1'!$F$3:$CZ$3,1,ROW()-1))=TRIM($A9),INDEX('Part 1'!$F$386:$CZ$386,1,ROW()-1),"CHECK"))} -> 105 | E9: =IF(OR($A9="",$D9="CHECK",$D9=""),"",$C9-$D9) -> 0 | F9: {=IF($A9="","",IF(TRIM(INDEX('Part 1'!$F$3:$CZ$3,1,ROW()-1))=TRIM($A9),INDEX('Part 1'!$F$38:$CZ$38,1,ROW()-1),"CHECK"))} -> 100 | J9: Corrolla | K9: PC-114R | L9: 0 | M9: {=IF($J9="","",IF(TRIM(INDEX('Part 1'!$CS$3:$EQ$3,1,ROW()-1))=TRIM($J9),INDEX('Part 1'!$CS$386:$EQ$386,1,ROW()-1),"CHECK"))} -> 0 | N9: =IF(OR($J9="",$M9="CHECK",$M9=""),"",$L9-$M9) -> 0 | O9: {=IF($J9="","",IF(TRIM(INDEX('Part 1'!$CS$3:$EQ$3,1,ROW()-1))=TRIM($J9),INDEX('Part 1'!$CS$38:$EQ$38,1,ROW()-1),"CHECK"))} -> 0 | Q9: Ford | R9: PC-8321 | S9: 87 | T9: {=IF($Q9="","",IF(TRIM(INDEX('Part 1'!$GD$3:$HB$3,1,ROW()-1))=TRIM($Q9),INDEX('Part 1'!$GD$386:$HB$386,1,ROW()-1),"CHECK"))} -> 89 | U9: =IF(OR($Q9="",$T9="CHECK",$T9=""),"",$S9-$T9) -> -2 | V9: {=IF($Q9="","",IF(TRIM(INDEX('Part 1'!$GD$3:$HB$3,1,ROW()-1))=TRIM($Q9),INDEX('Part 1'!$GD$38:$HB$38,1,ROW()-1),"CHECK"))} -> 0 | X9: Innova a/c switch | Z9: 199 | AA9: {=IF($X9="","",IF(TRIM(INDEX('Part 1'!$FG$3:$GC$3,1,ROW()-1))=TRIM($X9),INDEX('Part 1'!$FG$386:$GC$386,1,ROW()-1),"CHECK"))} -> 199 | AB9: =IF(OR($X9="",$AA9="CHECK",$AA9=""),"",$Z9-$AA9) -> 0 | AC9: {=IF($X9="","",IF(TRIM(INDEX('Part 1'!$FG$3:$GC$3,1,ROW()-1))=TRIM($X9),INDEX('Part 1'!$FG$38:$GC$38,1,ROW()-1),"CHECK"))} -> 0 | AE9: CONCORD-COPPER-GREY | AG9: 96 | AH9: {=IF($AE9="","",IF(TRIM(INDEX('Part 1'!$ER$3:$FF$3,1,ROW()-1))=TRIM($AE9),INDEX('Part 1'!$ER$386:$FF$386,1,ROW()-1),"CHECK"))} -> 27 | AI9: =IF(OR($AE9="",$AH9="CHECK",$AH9=""),"",ROUND($AG9-$AH9,2)) -> 69 | AJ9: {=IF($AE9="","",IF(TRIM(INDEX('Part 1'!$ER$3:$FF$3,1,ROW()-1))=TRIM($AE9),INDEX('Part 1'!$ER$38:$FF$38,1,ROW()-1),"CHECK"))} -> 0 | AM9: GASKET 505/507 | AO9: 0 | AP9: {=IF($AM9="","",IF(TRIM(INDEX('Part 1'!$HC$3:$HT$3,1,ROW()-1))=TRIM($AM9),INDEX('Part 1'!$HC$386:$HT$386,1,ROW()-1),"CHECK"))} -> 0 | AQ9: =IF(OR($AM9="",$AP9="CHECK",$AP9=""),"",ROUND($AO9-$AP9,2)) -> 0 | AR9: {=IF($AM9="","",IF(TRIM(INDEX('Part 1'!$HC$3:$HT$3,1,ROW()-1))=TRIM($AM9),INDEX('Part 1'!$HC$38:$HT$38,1,ROW()-1),"CHECK"))} -> 0 | AT9: 15" 'S' Scorpio | AV9: 50 | AW9: {=IF($AT9="","",IF(TRIM(INDEX('Part 1'!$HU$3:$IC$3,1,ROW()-1))=TRIM($AT9),INDEX('Part 1'!$HU$386:$IC$386,1,ROW()-1),"CHECK"))} -> 50 | AX9: =IF(OR($AT9="",$AW9="CHECK",$AW9=""),"",ROUND($AV9-$AW9,2)) -> 0 | AY9: {=IF($AT9="","",IF(TRIM(INDEX('Part 1'!$HU$3:$IC$3,1,ROW()-1))=TRIM($AT9),INDEX('Part 1'!$HU$38:$IC$38,1,ROW()-1),"CHECK"))} -> 200 | AZ9: 15" 'S' Scorpio | BB9: FLARE | BC9: FK-1011 | BD9: 100 | BE9: {=IF($BB9="","",IF(TRIM(INDEX('Part 1'!$ID$3:$IP$3,1,ROW()-1))=TRIM($BB9),INDEX('Part 1'!$ID$386:$IP$386,1,ROW()-1),"CHECK"))} -> 100 | BF9: =IF(OR($BB9="",$BE9="CHECK",$BE9=""),"",ROUND($BD9-$BE9,2)) -> 0 | BG9: {=IF($BB9="","",IF(TRIM(INDEX('Part 1'!$ID$3:$IP$3,1,ROW()-1))=TRIM($BB9),INDEX('Part 1'!$ID$38:$IP$38,1,ROW()-1),"CHECK"))} -> 600 | BH9: FLARE | BJ9: FIESTA | BK9: PC-E417 | BL9: 520 | BM9: {=IF($BJ9="","",IF(TRIM(INDEX('Part 2'!$F$3:$AS$3,1,ROW()-1))=TRIM($BJ9),INDEX('Part 2'!$F$243:$AS$243,1,ROW()-1),"CHECK"))} -> 520 | BN9: =IF(OR($BJ9="",$BM9="CHECK",$BM9=""),"",ROUND($BL9-$BM9,2)) -> 0 | BO9: {=IF($BJ9="","",IF(TRIM(INDEX('Part 2'!$F$3:$AS$3,1,ROW()-1))=TRIM($BJ9),INDEX('Part 2'!$F$33:$AS$33,1,ROW()-1),"CHECK"))} -> 518 | BP9: FIESTA | BR9: 508/510-O | BS9: BA | BT9: 70 | BU9: =IF(TRIM('Part 2'!$BA$3&" "&'Part 2'!$BA$4)=TRIM($BR9),'Part 2'!$BA$243,"CHECK") -> 55 | BV9: =IF(OR($BR9="",$BU9="CHECK"),"",ROUND($BT9-$BU9,2)) -> 15 | BW9: =IF(TRIM('Part 2'!$BA$3&" "&'Part 2'!$BA$4)=TRIM($BR9),'Part 2'!$BA$33,"CHECK") -> 100 | BY9: MAGNATTE COIL QUALIS | BZ9: SD-1003A | CA9: 120 | CB9: {=IF($BY9="","",IF(TRIM(INDEX('Part 2'!$BJ$3:$CZ$3,1,ROW()-1))=TRIM($BZ9),INDEX('Part 2'!$BJ$243:$CZ$243,1,ROW()-1),"CHECK"))} -> 120 | CC9: =IF(OR($BY9="",$CB9="CHECK"),"",ROUND($CA9-$CB9,2)) -> 0 | CD9: {=IF($BY9="","",IF(TRIM(INDEX('Part 2'!$BJ$3:$CZ$3,1,ROW()-1))=TRIM($BZ9),INDEX('Part 2'!$BJ$33:$CZ$33,1,ROW()-1),"CHECK"))} -> 120
A10: CIELO | C10: 0 | D10: {=IF($A10="","",IF(TRIM(INDEX('Part 1'!$F$3:$CZ$3,1,ROW()-1))=TRIM($A10),INDEX('Part 1'!$F$386:$CZ$386,1,ROW()-1),"CHECK"))} -> 0 | E10: =IF(OR($A10="",$D10="CHECK",$D10=""),"",$C10-$D10) -> 0 | F10: {=IF($A10="","",IF(TRIM(INDEX('Part 1'!$F$3:$CZ$3,1,ROW()-1))=TRIM($A10),INDEX('Part 1'!$F$38:$CZ$38,1,ROW()-1),"CHECK"))} -> 0 | J10: ELANTRA | K10: PC-135R | L10: 14 | M10: {=IF($J10="","",IF(TRIM(INDEX('Part 1'!$CS$3:$EQ$3,1,ROW()-1))=TRIM($J10),INDEX('Part 1'!$CS$386:$EQ$386,1,ROW()-1),"CHECK"))} -> 14 | N10: =IF(OR($J10="",$M10="CHECK",$M10=""),"",$L10-$M10) -> 0 | O10: {=IF($J10="","",IF(TRIM(INDEX('Part 1'!$CS$3:$EQ$3,1,ROW()-1))=TRIM($J10),INDEX('Part 1'!$CS$38:$EQ$38,1,ROW()-1),"CHECK"))} -> 132 | Q10: Honda City | R10: PC-8020 | S10: 500 | T10: {=IF($Q10="","",IF(TRIM(INDEX('Part 1'!$GD$3:$HB$3,1,ROW()-1))=TRIM($Q10),INDEX('Part 1'!$GD$386:$HB$386,1,ROW()-1),"CHECK"))} -> 500 | U10: =IF(OR($Q10="",$T10="CHECK",$T10=""),"",$S10-$T10) -> 0 | V10: {=IF($Q10="","",IF(TRIM(INDEX('Part 1'!$GD$3:$HB$3,1,ROW()-1))=TRIM($Q10),INDEX('Part 1'!$GD$38:$HB$38,1,ROW()-1),"CHECK"))} -> 600 | X10: LANCER BLOWER SWITCH | Y10: PC-926 | Z10: 250 | AA10: {=IF($X10="","",IF(TRIM(INDEX('Part 1'!$FG$3:$GC$3,1,ROW()-1))=TRIM($X10),INDEX('Part 1'!$FG$386:$GC$386,1,ROW()-1),"CHECK"))} -> 250 | AB10: =IF(OR($X10="",$AA10="CHECK",$AA10=""),"",$Z10-$AA10) -> 0 | AC10: {=IF($X10="","",IF(TRIM(INDEX('Part 1'!$FG$3:$GC$3,1,ROW()-1))=TRIM($X10),INDEX('Part 1'!$FG$38:$GC$38,1,ROW()-1),"CHECK"))} -> 500 | AE10: CONCORD-COPPER-BEIGE | AG10: 0 | AH10: {=IF($AE10="","",IF(TRIM(INDEX('Part 1'!$ER$3:$FF$3,1,ROW()-1))=TRIM($AE10),INDEX('Part 1'!$ER$386:$FF$386,1,ROW()-1),"CHECK"))} -> 6 | AI10: =IF(OR($AE10="",$AH10="CHECK",$AH10=""),"",ROUND($AG10-$AH10,2)) -> -6 | AJ10: {=IF($AE10="","",IF(TRIM(INDEX('Part 1'!$ER$3:$FF$3,1,ROW()-1))=TRIM($AE10),INDEX('Part 1'!$ER$38:$FF$38,1,ROW()-1),"CHECK"))} -> 0 | AM10: H.CITY | AN10: PC-7061A | AO10: 0 | AP10: {=IF($AM10="","",IF(TRIM(INDEX('Part 1'!$HC$3:$HT$3,1,ROW()-1))=TRIM($AM10),INDEX('Part 1'!$HC$386:$HT$386,1,ROW()-1),"CHECK"))} -> 0 | AQ10: =IF(OR($AM10="",$AP10="CHECK",$AP10=""),"",ROUND($AO10-$AP10,2)) -> 0 | AR10: {=IF($AM10="","",IF(TRIM(INDEX('Part 1'!$HC$3:$HT$3,1,ROW()-1))=TRIM($AM10),INDEX('Part 1'!$HC$38:$HT$38,1,ROW()-1),"CHECK"))} -> 0 | AT10: 16" 'S' Scorpio | AV10: 71 | AW10: {=IF($AT10="","",IF(TRIM(INDEX('Part 1'!$HU$3:$IC$3,1,ROW()-1))=TRIM($AT10),INDEX('Part 1'!$HU$386:$IC$386,1,ROW()-1),"CHECK"))} -> 71 | AX10: =IF(OR($AT10="",$AW10="CHECK",$AW10=""),"",ROUND($AV10-$AW10,2)) -> 0 | AY10: {=IF($AT10="","",IF(TRIM(INDEX('Part 1'!$HU$3:$IC$3,1,ROW()-1))=TRIM($AT10),INDEX('Part 1'!$HU$38:$IC$38,1,ROW()-1),"CHECK"))} -> 0 | AZ10: 16" 'S' Scorpio | BB10: O-RING | BC10: FK-1012 | BD10: 100 | BE10: {=IF($BB10="","",IF(TRIM(INDEX('Part 1'!$ID$3:$IP$3,1,ROW()-1))=TRIM($BB10),INDEX('Part 1'!$ID$386:$IP$386,1,ROW()-1),"CHECK"))} -> 100 | BF10: =IF(OR($BB10="",$BE10="CHECK",$BE10=""),"",ROUND($BD10-$BE10,2)) -> 0 | BG10: {=IF($BB10="","",IF(TRIM(INDEX('Part 1'!$ID$3:$IP$3,1,ROW()-1))=TRIM($BB10),INDEX('Part 1'!$ID$38:$IP$38,1,ROW()-1),"CHECK"))} -> 600 | BH10: O-RING | BJ10: GETZ | BK10: PC-E422 | BL10: 4 | BM10: {=IF($BJ10="","",IF(TRIM(INDEX('Part 2'!$F$3:$AS$3,1,ROW()-1))=TRIM($BJ10),INDEX('Part 2'!$F$243:$AS$243,1,ROW()-1),"CHECK"))} -> 28 | BN10: =IF(OR($BJ10="",$BM10="CHECK",$BM10=""),"",ROUND($BL10-$BM10,2)) -> -24 | BO10: {=IF($BJ10="","",IF(TRIM(INDEX('Part 2'!$F$3:$AS$3,1,ROW()-1))=TRIM($BJ10),INDEX('Part 2'!$F$33:$AS$33,1,ROW()-1),"CHECK"))} -> 72 | BP10: GETZ | BR10: HCC SANTRO | BS10: BB | BT10: 0 | BU10: =IF(TRIM('Part 2'!$BB$3&" "&'Part 2'!$BB$4)=TRIM($BR10),'Part 2'!$BB$243,"CHECK") -> 0 | BV10: =IF(OR($BR10="",$BU10="CHECK"),"",ROUND($BT10-$BU10,2)) -> 0 | BW10: =IF(TRIM('Part 2'!$BB$3&" "&'Part 2'!$BB$4)=TRIM($BR10),'Part 2'!$BB$33,"CHECK") -> 0 | BY10: PULLEY PULL QUALIS | BZ10: SD-1003B | CA10: 108 | CB10: {=IF($BY10="","",IF(TRIM(INDEX('Part 2'!$BJ$3:$CZ$3,1,ROW()-1))=TRIM($BZ10),INDEX('Part 2'!$BJ$243:$CZ$243,1,ROW()-1),"CHECK"))} -> 108 | CC10: =IF(OR($BY10="",$CB10="CHECK"),"",ROUND($CA10-$CB10,2)) -> 0 | CD10: {=IF($BY10="","",IF(TRIM(INDEX('Part 2'!$BJ$3:$CZ$3,1,ROW()-1))=TRIM($BZ10),INDEX('Part 2'!$BJ$33:$CZ$33,1,ROW()-1),"CHECK"))} -> 108
A11: COROLLA | B11: PC-86110 | C11: 85 | D11: {=IF($A11="","",IF(TRIM(INDEX('Part 1'!$F$3:$CZ$3,1,ROW()-1))=TRIM($A11),INDEX('Part 1'!$F$386:$CZ$386,1,ROW()-1),"CHECK"))} -> 85 | E11: =IF(OR($A11="",$D11="CHECK",$D11=""),"",$C11-$D11) -> 0 | F11: {=IF($A11="","",IF(TRIM(INDEX('Part 1'!$F$3:$CZ$3,1,ROW()-1))=TRIM($A11),INDEX('Part 1'!$F$38:$CZ$38,1,ROW()-1),"CHECK"))} -> 75 | J11: Esteem R-12 | K11: PC-036R12 | L11: 96 | M11: {=IF($J11="","",IF(TRIM(INDEX('Part 1'!$CS$3:$EQ$3,1,ROW()-1))=TRIM($J11),INDEX('Part 1'!$CS$386:$EQ$386,1,ROW()-1),"CHECK"))} -> 96 | N11: =IF(OR($J11="",$M11="CHECK",$M11=""),"",$L11-$M11) -> 0 | O11: {=IF($J11="","",IF(TRIM(INDEX('Part 1'!$CS$3:$EQ$3,1,ROW()-1))=TRIM($J11),INDEX('Part 1'!$CS$38:$EQ$38,1,ROW()-1),"CHECK"))} -> 96 | Q11: Indica Behr | R11: PC-8115 | S11: 100 | T11: {=IF($Q11="","",IF(TRIM(INDEX('Part 1'!$GD$3:$HB$3,1,ROW()-1))=TRIM($Q11),INDEX('Part 1'!$GD$386:$HB$386,1,ROW()-1),"CHECK"))} -> 100 | U11: =IF(OR($Q11="",$T11="CHECK",$T11=""),"",$S11-$T11) -> 0 | V11: {=IF($Q11="","",IF(TRIM(INDEX('Part 1'!$GD$3:$HB$3,1,ROW()-1))=TRIM($Q11),INDEX('Part 1'!$GD$38:$HB$38,1,ROW()-1),"CHECK"))} -> 0 | X11: LENCER | Y11: PC-1044A & 1042A | Z11: 0 | AA11: {=IF($X11="","",IF(TRIM(INDEX('Part 1'!$FG$3:$GC$3,1,ROW()-1))=TRIM($X11),INDEX('Part 1'!$FG$386:$GC$386,1,ROW()-1),"CHECK"))} -> 0 | AB11: =IF(OR($X11="",$AA11="CHECK",$AA11=""),"",$Z11-$AA11) -> 0 | AC11: {=IF($X11="","",IF(TRIM(INDEX('Part 1'!$FG$3:$GC$3,1,ROW()-1))=TRIM($X11),INDEX('Part 1'!$FG$38:$GC$38,1,ROW()-1),"CHECK"))} -> 300 | AE11: Concord-Normal | AG11: 0 | AH11: {=IF($AE11="","",IF(TRIM(INDEX('Part 1'!$ER$3:$FF$3,1,ROW()-1))=TRIM($AE11),INDEX('Part 1'!$ER$386:$FF$386,1,ROW()-1),"CHECK"))} -> 0 | AI11: =IF(OR($AE11="",$AH11="CHECK",$AH11=""),"",ROUND($AG11-$AH11,2)) -> 0 | AJ11: {=IF($AE11="","",IF(TRIM(INDEX('Part 1'!$ER$3:$FF$3,1,ROW()-1))=TRIM($AE11),INDEX('Part 1'!$ER$38:$FF$38,1,ROW()-1),"CHECK"))} -> 0 | AM11: ND | AN11: PC-7031A | AO11: 1912 | AP11: {=IF($AM11="","",IF(TRIM(INDEX('Part 1'!$HC$3:$HT$3,1,ROW()-1))=TRIM($AM11),INDEX('Part 1'!$HC$386:$HT$386,1,ROW()-1),"CHECK"))} -> 1912 | AQ11: =IF(OR($AM11="",$AP11="CHECK",$AP11=""),"",ROUND($AO11-$AP11,2)) -> 0 | AR11: {=IF($AM11="","",IF(TRIM(INDEX('Part 1'!$HC$3:$HT$3,1,ROW()-1))=TRIM($AM11),INDEX('Part 1'!$HC$38:$HT$38,1,ROW()-1),"CHECK"))} -> 3000 | BB11: QUALIS | BC11: FK-1015 | BD11: 200 | BE11: {=IF($BB11="","",IF(TRIM(INDEX('Part 1'!$ID$3:$IP$3,1,ROW()-1))=TRIM($BB11),INDEX('Part 1'!$ID$386:$IP$386,1,ROW()-1),"CHECK"))} -> 200 | BF11: =IF(OR($BB11="",$BE11="CHECK",$BE11=""),"",ROUND($BD11-$BE11,2)) -> 0 | BG11: {=IF($BB11="","",IF(TRIM(INDEX('Part 1'!$ID$3:$IP$3,1,ROW()-1))=TRIM($BB11),INDEX('Part 1'!$ID$38:$IP$38,1,ROW()-1),"CHECK"))} -> 200 | BH11: QUALIS | BJ11: HONDA ACCORD | BK11: PC-E510 | BL11: 109 | BM11: {=IF($BJ11="","",IF(TRIM(INDEX('Part 2'!$F$3:$AS$3,1,ROW()-1))=TRIM($BJ11),INDEX('Part 2'!$F$243:$AS$243,1,ROW()-1),"CHECK"))} -> 109 | BN11: =IF(OR($BJ11="",$BM11="CHECK",$BM11=""),"",ROUND($BL11-$BM11,2)) -> 0 | BO11: {=IF($BJ11="","",IF(TRIM(INDEX('Part 2'!$F$3:$AS$3,1,ROW()-1))=TRIM($BJ11),INDEX('Part 2'!$F$33:$AS$33,1,ROW()-1),"CHECK"))} -> 110 | BP11: HONDA ACCORD | BR11: HCC SONATA | BS11: BC | BT11: 0 | BU11: =IF(TRIM('Part 2'!$BC$3&" "&'Part 2'!$BC$4)=TRIM($BR11),'Part 2'!$BC$243,"CHECK") -> 0 | BV11: =IF(OR($BR11="",$BU11="CHECK"),"",ROUND($BT11-$BU11,2)) -> 0 | BW11: =IF(TRIM('Part 2'!$BC$3&" "&'Part 2'!$BC$4)=TRIM($BR11),'Part 2'!$BC$33,"CHECK") -> 0 | BY11: PLATE HUB HS-11 | BZ11: SD-1004 | CA11: 120 | CB11: {=IF($BY11="","",IF(TRIM(INDEX('Part 2'!$BJ$3:$CZ$3,1,ROW()-1))=TRIM($BZ11),INDEX('Part 2'!$BJ$243:$CZ$243,1,ROW()-1),"CHECK"))} -> 120 | CC11: =IF(OR($BY11="",$CB11="CHECK"),"",ROUND($CA11-$CB11,2)) -> 0 | CD11: {=IF($BY11="","",IF(TRIM(INDEX('Part 2'!$BJ$3:$CZ$3,1,ROW()-1))=TRIM($BZ11),INDEX('Part 2'!$BJ$33:$CZ$33,1,ROW()-1),"CHECK"))} -> 120
A12: DÉCOR | B12: PC-86273 | C12: 50 | D12: {=IF($A12="","",IF(TRIM(INDEX('Part 1'!$F$3:$CZ$3,1,ROW()-1))=TRIM($A12),INDEX('Part 1'!$F$386:$CZ$386,1,ROW()-1),"CHECK"))} -> 50 | E12: =IF(OR($A12="",$D12="CHECK",$D12=""),"",$C12-$D12) -> 0 | F12: {=IF($A12="","",IF(TRIM(INDEX('Part 1'!$F$3:$CZ$3,1,ROW()-1))=TRIM($A12),INDEX('Part 1'!$F$38:$CZ$38,1,ROW()-1),"CHECK"))} -> 50 | J12: Esteem R-134a | K12: PC-036R-134 | L12: 138 | M12: {=IF($J12="","",IF(TRIM(INDEX('Part 1'!$CS$3:$EQ$3,1,ROW()-1))=TRIM($J12),INDEX('Part 1'!$CS$386:$EQ$386,1,ROW()-1),"CHECK"))} -> 138 | N12: =IF(OR($J12="",$M12="CHECK",$M12=""),"",$L12-$M12) -> 0 | O12: {=IF($J12="","",IF(TRIM(INDEX('Part 1'!$CS$3:$EQ$3,1,ROW()-1))=TRIM($J12),INDEX('Part 1'!$CS$38:$EQ$38,1,ROW()-1),"CHECK"))} -> 138 | Q12: Lancer | R12: PC-8017 | S12: 300 | T12: {=IF($Q12="","",IF(TRIM(INDEX('Part 1'!$GD$3:$HB$3,1,ROW()-1))=TRIM($Q12),INDEX('Part 1'!$GD$386:$HB$386,1,ROW()-1),"CHECK"))} -> 300 | U12: =IF(OR($Q12="",$T12="CHECK",$T12=""),"",$S12-$T12) -> 0 | V12: {=IF($Q12="","",IF(TRIM(INDEX('Part 1'!$GD$3:$HB$3,1,ROW()-1))=TRIM($Q12),INDEX('Part 1'!$GD$38:$HB$38,1,ROW()-1),"CHECK"))} -> 500 | X12: OPEL-BIG | Y12: PC-1091 | Z12: 25 | AA12: {=IF($X12="","",IF(TRIM(INDEX('Part 1'!$FG$3:$GC$3,1,ROW()-1))=TRIM($X12),INDEX('Part 1'!$FG$386:$GC$386,1,ROW()-1),"CHECK"))} -> 25 | AB12: =IF(OR($X12="",$AA12="CHECK",$AA12=""),"",$Z12-$AA12) -> 0 | AC12: {=IF($X12="","",IF(TRIM(INDEX('Part 1'!$FG$3:$GC$3,1,ROW()-1))=TRIM($X12),INDEX('Part 1'!$FG$38:$GC$38,1,ROW()-1),"CHECK"))} -> 100 | AE12: 405 | AG12: 50 | AH12: {=IF($AE12="","",IF(TRIM(INDEX('Part 1'!$ER$3:$FF$3,1,ROW()-1))=TRIM($AE12),INDEX('Part 1'!$ER$386:$FF$386,1,ROW()-1),"CHECK"))} -> 50 | AI12: =IF(OR($AE12="",$AH12="CHECK",$AH12=""),"",ROUND($AG12-$AH12,2)) -> 0 | AJ12: {=IF($AE12="","",IF(TRIM(INDEX('Part 1'!$ER$3:$FF$3,1,ROW()-1))=TRIM($AE12),INDEX('Part 1'!$ER$38:$FF$38,1,ROW()-1),"CHECK"))} -> 50 | AK12: 405 | AM12: OPEL ASTRA | AN12: PC-7210 | AO12: 100 | AP12: {=IF($AM12="","",IF(TRIM(INDEX('Part 1'!$HC$3:$HT$3,1,ROW()-1))=TRIM($AM12),INDEX('Part 1'!$HC$386:$HT$386,1,ROW()-1),"CHECK"))} -> 100 | AQ12: =IF(OR($AM12="",$AP12="CHECK",$AP12=""),"",ROUND($AO12-$AP12,2)) -> 0 | AR12: {=IF($AM12="","",IF(TRIM(INDEX('Part 1'!$HC$3:$HT$3,1,ROW()-1))=TRIM($AM12),INDEX('Part 1'!$HC$38:$HT$38,1,ROW()-1),"CHECK"))} -> 400 | BB12: INNOVA / WR | BC12: FK-1082B | BD12: 0 | BE12: {=IF($BB12="","",IF(TRIM(INDEX('Part 1'!$ID$3:$IP$3,1,ROW()-1))=TRIM($BB12),INDEX('Part 1'!$ID$386:$IP$386,1,ROW()-1),"CHECK"))} -> 0 | BF12: =IF(OR($BB12="",$BE12="CHECK",$BE12=""),"",ROUND($BD12-$BE12,2)) -> 0 | BG12: {=IF($BB12="","",IF(TRIM(INDEX('Part 1'!$ID$3:$IP$3,1,ROW()-1))=TRIM($BB12),INDEX('Part 1'!$ID$38:$IP$38,1,ROW()-1),"CHECK"))} -> 200 | BH12: INNOVA / WR | BJ12: HONDA CIVIC | BK12: PC-E523 | BL12: 394 | BM12: {=IF($BJ12="","",IF(TRIM(INDEX('Part 2'!$F$3:$AS$3,1,ROW()-1))=TRIM($BJ12),INDEX('Part 2'!$F$243:$AS$243,1,ROW()-1),"CHECK"))} -> 410 | BN12: =IF(OR($BJ12="",$BM12="CHECK",$BM12=""),"",ROUND($BL12-$BM12,2)) -> -16 | BO12: {=IF($BJ12="","",IF(TRIM(INDEX('Part 2'!$F$3:$AS$3,1,ROW()-1))=TRIM($BJ12),INDEX('Part 2'!$F$33:$AS$33,1,ROW()-1),"CHECK"))} -> 435 | BP12: HONDA CIVIC | BR12: HCC ELANTRA-2006 | BS12: BD | BT12: 0 | BU12: =IF(TRIM('Part 2'!$BD$3&" "&'Part 2'!$BD$4)=TRIM($BR12),'Part 2'!$BD$243,"CHECK") -> 0 | BV12: =IF(OR($BR12="",$BU12="CHECK"),"",ROUND($BT12-$BU12,2)) -> 0 | BW12: =IF(TRIM('Part 2'!$BD$3&" "&'Part 2'!$BD$4)=TRIM($BR12),'Part 2'!$BD$33,"CHECK") -> 0 | BY12: MAGNATIC COIL HS-11 | BZ12: SD-1004A | CA12: 150 | CB12: {=IF($BY12="","",IF(TRIM(INDEX('Part 2'!$BJ$3:$CZ$3,1,ROW()-1))=TRIM($BZ12),INDEX('Part 2'!$BJ$243:$CZ$243,1,ROW()-1),"CHECK"))} -> 150 | CC12: =IF(OR($BY12="",$CB12="CHECK"),"",ROUND($CA12-$CB12,2)) -> 0 | CD12: {=IF($BY12="","",IF(TRIM(INDEX('Part 2'!$BJ$3:$CZ$3,1,ROW()-1))=TRIM($BZ12),INDEX('Part 2'!$BJ$33:$CZ$33,1,ROW()-1),"CHECK"))} -> 150
A13: ELANTRA | B13: PC-86066 | C13: 50 | D13: {=IF($A13="","",IF(TRIM(INDEX('Part 1'!$F$3:$CZ$3,1,ROW()-1))=TRIM($A13),INDEX('Part 1'!$F$386:$CZ$386,1,ROW()-1),"CHECK"))} -> 45 | E13: =IF(OR($A13="",$D13="CHECK",$D13=""),"",$C13-$D13) -> 5 | F13: {=IF($A13="","",IF(TRIM(INDEX('Part 1'!$F$3:$CZ$3,1,ROW()-1))=TRIM($A13),INDEX('Part 1'!$F$38:$CZ$38,1,ROW()-1),"CHECK"))} -> 100 | J13: ESTILO | K13: PC-408 | L13: 0 | M13: {=IF($J13="","",IF(TRIM(INDEX('Part 1'!$CS$3:$EQ$3,1,ROW()-1))=TRIM($J13),INDEX('Part 1'!$CS$386:$EQ$386,1,ROW()-1),"CHECK"))} -> 0 | N13: =IF(OR($J13="",$M13="CHECK",$M13=""),"",$L13-$M13) -> 0 | O13: {=IF($J13="","",IF(TRIM(INDEX('Part 1'!$CS$3:$EQ$3,1,ROW()-1))=TRIM($J13),INDEX('Part 1'!$CS$38:$EQ$38,1,ROW()-1),"CHECK"))} -> 0 | Q13: Maruti 'F'Ring | R13: PC-8047 | S13: 275 | T13: {=IF($Q13="","",IF(TRIM(INDEX('Part 1'!$GD$3:$HB$3,1,ROW()-1))=TRIM($Q13),INDEX('Part 1'!$GD$386:$HB$386,1,ROW()-1),"CHECK"))} -> 275 | U13: =IF(OR($Q13="",$T13="CHECK",$T13=""),"",$S13-$T13) -> 0 | V13: {=IF($Q13="","",IF(TRIM(INDEX('Part 1'!$GD$3:$HB$3,1,ROW()-1))=TRIM($Q13),INDEX('Part 1'!$GD$38:$HB$38,1,ROW()-1),"CHECK"))} -> 500 | X13: OPEL-SMALL-2pin | Y13: PC-1087 | Z13: 0 | AA13: {=IF($X13="","",IF(TRIM(INDEX('Part 1'!$FG$3:$GC$3,1,ROW()-1))=TRIM($X13),INDEX('Part 1'!$FG$386:$GC$386,1,ROW()-1),"CHECK"))} -> 0 | AB13: =IF(OR($X13="",$AA13="CHECK",$AA13=""),"",$Z13-$AA13) -> 0 | AC13: {=IF($X13="","",IF(TRIM(INDEX('Part 1'!$FG$3:$GC$3,1,ROW()-1))=TRIM($X13),INDEX('Part 1'!$FG$38:$GC$38,1,ROW()-1),"CHECK"))} -> 300 | AE13: 404 | AG13: 987.9999 | AH13: {=IF($AE13="","",IF(TRIM(INDEX('Part 1'!$ER$3:$FF$3,1,ROW()-1))=TRIM($AE13),INDEX('Part 1'!$ER$386:$FF$386,1,ROW()-1),"CHECK"))} -> 1000 | AI13: =IF(OR($AE13="",$AH13="CHECK",$AH13=""),"",ROUND($AG13-$AH13,2)) -> -12 | AJ13: {=IF($AE13="","",IF(TRIM(INDEX('Part 1'!$ER$3:$FF$3,1,ROW()-1))=TRIM($AE13),INDEX('Part 1'!$ER$38:$FF$38,1,ROW()-1),"CHECK"))} -> 1000 | AK13: 404 | AM13: O-RINGS | AN13: PC-7085A | AO13: 1700 | AP13: {=IF($AM13="","",IF(TRIM(INDEX('Part 1'!$HC$3:$HT$3,1,ROW()-1))=TRIM($AM13),INDEX('Part 1'!$HC$386:$HT$386,1,ROW()-1),"CHECK"))} -> 1700 | AQ13: =IF(OR($AM13="",$AP13="CHECK",$AP13=""),"",ROUND($AO13-$AP13,2)) -> 0 | AR13: {=IF($AM13="","",IF(TRIM(INDEX('Part 1'!$HC$3:$HT$3,1,ROW()-1))=TRIM($AM13),INDEX('Part 1'!$HC$38:$HT$38,1,ROW()-1),"CHECK"))} -> 3000 | BB13: ORIFICE TUBE | BC13: oringe-PC-8006 | BD13: 250 | BE13: {=IF($BB13="","",IF(TRIM(INDEX('Part 1'!$ID$3:$IP$3,1,ROW()-1))=TRIM($BB13),INDEX('Part 1'!$ID$386:$IP$386,1,ROW()-1),"CHECK"))} -> 250 | BF13: =IF(OR($BB13="",$BE13="CHECK",$BE13=""),"",ROUND($BD13-$BE13,2)) -> 0 | BG13: {=IF($BB13="","",IF(TRIM(INDEX('Part 1'!$ID$3:$IP$3,1,ROW()-1))=TRIM($BB13),INDEX('Part 1'!$ID$38:$IP$38,1,ROW()-1),"CHECK"))} -> 0 | BH13: ORIFICE TUBE (ORANGE) | BJ13: CRV | BK13: PC-E509 | BL13: 0 | BM13: {=IF($BJ13="","",IF(TRIM(INDEX('Part 2'!$F$3:$AS$3,1,ROW()-1))=TRIM($BJ13),INDEX('Part 2'!$F$243:$AS$243,1,ROW()-1),"CHECK"))} -> 24 | BN13: =IF(OR($BJ13="",$BM13="CHECK",$BM13=""),"",ROUND($BL13-$BM13,2)) -> -24 | BO13: {=IF($BJ13="","",IF(TRIM(INDEX('Part 2'!$F$3:$AS$3,1,ROW()-1))=TRIM($BJ13),INDEX('Part 2'!$F$33:$AS$33,1,ROW()-1),"CHECK"))} -> 0 | BP13: CRV | BR13: HCC ELANTRA-2000 | BS13: BE | BT13: 0 | BU13: =IF(TRIM('Part 2'!$BE$3&" "&'Part 2'!$BE$4)=TRIM($BR13),'Part 2'!$BE$243,"CHECK") -> 0 | BV13: =IF(OR($BR13="",$BU13="CHECK"),"",ROUND($BT13-$BU13,2)) -> 0 | BW13: =IF(TRIM('Part 2'!$BE$3&" "&'Part 2'!$BE$4)=TRIM($BR13),'Part 2'!$BE$33,"CHECK") -> 0 | BY13: PULLEY PULL HS-11 | BZ13: SD-1004B | CA13: 108 | CB13: {=IF($BY13="","",IF(TRIM(INDEX('Part 2'!$BJ$3:$CZ$3,1,ROW()-1))=TRIM($BZ13),INDEX('Part 2'!$BJ$243:$CZ$243,1,ROW()-1),"CHECK"))} -> 108 | CC13: =IF(OR($BY13="",$CB13="CHECK"),"",ROUND($CA13-$CB13,2)) -> 0 | CD13: {=IF($BY13="","",IF(TRIM(INDEX('Part 2'!$BJ$3:$CZ$3,1,ROW()-1))=TRIM($BZ13),INDEX('Part 2'!$BJ$33:$CZ$33,1,ROW()-1),"CHECK"))} -> 108
A14: ENDEAVOUR | B14: PC-86277 | C14: 50 | D14: {=IF($A14="","",IF(TRIM(INDEX('Part 1'!$F$3:$CZ$3,1,ROW()-1))=TRIM($A14),INDEX('Part 1'!$F$386:$CZ$386,1,ROW()-1),"CHECK"))} -> 50 | E14: =IF(OR($A14="",$D14="CHECK",$D14=""),"",$C14-$D14) -> 0 | F14: {=IF($A14="","",IF(TRIM(INDEX('Part 1'!$F$3:$CZ$3,1,ROW()-1))=TRIM($A14),INDEX('Part 1'!$F$38:$CZ$38,1,ROW()-1),"CHECK"))} -> 50 | J14: FIESTA | K14: PC-205 | L14: 360 | M14: {=IF($J14="","",IF(TRIM(INDEX('Part 1'!$CS$3:$EQ$3,1,ROW()-1))=TRIM($J14),INDEX('Part 1'!$CS$386:$EQ$386,1,ROW()-1),"CHECK"))} -> 360 | N14: =IF(OR($J14="",$M14="CHECK",$M14=""),"",$L14-$M14) -> 0 | O14: {=IF($J14="","",IF(TRIM(INDEX('Part 1'!$CS$3:$EQ$3,1,ROW()-1))=TRIM($J14),INDEX('Part 1'!$CS$38:$EQ$38,1,ROW()-1),"CHECK"))} -> 366 | Q14: Maruti 'O'Ring | R14: PC-8051 | S14: 1000 | T14: {=IF($Q14="","",IF(TRIM(INDEX('Part 1'!$GD$3:$HB$3,1,ROW()-1))=TRIM($Q14),INDEX('Part 1'!$GD$386:$HB$386,1,ROW()-1),"CHECK"))} -> 1000 | U14: =IF(OR($Q14="",$T14="CHECK",$T14=""),"",$S14-$T14) -> 0 | V14: {=IF($Q14="","",IF(TRIM(INDEX('Part 1'!$GD$3:$HB$3,1,ROW()-1))=TRIM($Q14),INDEX('Part 1'!$GD$38:$HB$38,1,ROW()-1),"CHECK"))} -> 1000 | X14: PALIO | Y14: PC-1100 | Z14: 150 | AA14: {=IF($X14="","",IF(TRIM(INDEX('Part 1'!$FG$3:$GC$3,1,ROW()-1))=TRIM($X14),INDEX('Part 1'!$FG$386:$GC$386,1,ROW()-1),"CHECK"))} -> 50 | AB14: =IF(OR($X14="",$AA14="CHECK",$AA14=""),"",$Z14-$AA14) -> 100 | AC14: {=IF($X14="","",IF(TRIM(INDEX('Part 1'!$FG$3:$GC$3,1,ROW()-1))=TRIM($X14),INDEX('Part 1'!$FG$38:$GC$38,1,ROW()-1),"CHECK"))} -> 200 | AE14: CONCORD WHEEL | AG14: 358 | AH14: {=IF($AE14="","",IF(TRIM(INDEX('Part 1'!$ER$3:$FF$3,1,ROW()-1))=TRIM($AE14),INDEX('Part 1'!$ER$386:$FF$386,1,ROW()-1),"CHECK"))} -> 358 | AI14: =IF(OR($AE14="",$AH14="CHECK",$AH14=""),"",ROUND($AG14-$AH14,2)) -> 0 | AJ14: {=IF($AE14="","",IF(TRIM(INDEX('Part 1'!$ER$3:$FF$3,1,ROW()-1))=TRIM($AE14),INDEX('Part 1'!$ER$38:$FF$38,1,ROW()-1),"CHECK"))} -> 300 | AK14: CONCORD WHEEL | AM14: Santro Large-matiz/ZEN DELPHI | AN14: PC-7058A | AO14: 150 | AP14: {=IF($AM14="","",IF(TRIM(INDEX('Part 1'!$HC$3:$HT$3,1,ROW()-1))=TRIM($AM14),INDEX('Part 1'!$HC$386:$HT$386,1,ROW()-1),"CHECK"))} -> 150 | AQ14: =IF(OR($AM14="",$AP14="CHECK",$AP14=""),"",ROUND($AO14-$AP14,2)) -> 0 | AR14: {=IF($AM14="","",IF(TRIM(INDEX('Part 1'!$HC$3:$HT$3,1,ROW()-1))=TRIM($AM14),INDEX('Part 1'!$HC$38:$HT$38,1,ROW()-1),"CHECK"))} -> 3000 | BB14: ORIFICE TUBE | BC14: white - PC-8002 | BD14: 0 | BE14: {=IF($BB14="","",IF(TRIM(INDEX('Part 1'!$ID$3:$IP$3,1,ROW()-1))=TRIM($BB14),INDEX('Part 1'!$ID$386:$IP$386,1,ROW()-1),"CHECK"))} -> 0 | BF14: =IF(OR($BB14="",$BE14="CHECK",$BE14=""),"",ROUND($BD14-$BE14,2)) -> 0 | BG14: {=IF($BB14="","",IF(TRIM(INDEX('Part 1'!$ID$3:$IP$3,1,ROW()-1))=TRIM($BB14),INDEX('Part 1'!$ID$38:$IP$38,1,ROW()-1),"CHECK"))} -> 0 | BH14: ORIFICE TUBE (WHITE) | BJ14: IKON | BK14: PC-E022 | BL14: 375 | BM14: {=IF($BJ14="","",IF(TRIM(INDEX('Part 2'!$F$3:$AS$3,1,ROW()-1))=TRIM($BJ14),INDEX('Part 2'!$F$243:$AS$243,1,ROW()-1),"CHECK"))} -> 375 | BN14: =IF(OR($BJ14="",$BM14="CHECK",$BM14=""),"",ROUND($BL14-$BM14,2)) -> 0 | BO14: {=IF($BJ14="","",IF(TRIM(INDEX('Part 2'!$F$3:$AS$3,1,ROW()-1))=TRIM($BJ14),INDEX('Part 2'!$F$33:$AS$33,1,ROW()-1),"CHECK"))} -> 465 | BP14: IKON | BR14: HOSE 8MM-LID | BS14: BF | BT14: 133 | BU14: =IF(TRIM('Part 2'!$BF$3&" "&'Part 2'!$BF$4)=TRIM($BR14),'Part 2'!$BF$243,"CHECK") -> 145 | BV14: =IF(OR($BR14="",$BU14="CHECK"),"",ROUND($BT14-$BU14,2)) -> -12 | BW14: =IF(TRIM('Part 2'!$BF$3&" "&'Part 2'!$BF$4)=TRIM($BR14),'Part 2'!$BF$33,"CHECK") -> 165 | BY14: MAGNETIC COIL MC-A HS-XING | BZ14: SD-1004C | CA14: 150 | CB14: {=IF($BY14="","",IF(TRIM(INDEX('Part 2'!$BJ$3:$CZ$3,1,ROW()-1))=TRIM($BZ14),INDEX('Part 2'!$BJ$243:$CZ$243,1,ROW()-1),"CHECK"))} -> 150 | CC14: =IF(OR($BY14="",$CB14="CHECK"),"",ROUND($CA14-$CB14,2)) -> 0 | CD14: {=IF($BY14="","",IF(TRIM(INDEX('Part 2'!$BJ$3:$CZ$3,1,ROW()-1))=TRIM($BZ14),INDEX('Part 2'!$BJ$33:$CZ$33,1,ROW()-1),"CHECK"))} -> 150
